Workbook

Sheet 1&2号构型
A1: 系统章节 | B1: 设备名称 | C1: 设备编号 | D1: LIN号 | E1: 长*高*宽 mm | F1: 设备布置区域 | G1: 构型分类 | H1: 总体布置调整需求 | I1: 安装方式 下拉选择，【选择托架需填写sheet3托架信息表！！】 | J1: 电搭接方式 | K1: 电搭接类型 | L1: 重量(kg) 托架重量分开填到sheet2 | M1: 是否有EICD | N1: 是否是电设备 | O1: 是否为一级用电设备 | P1: 供电余度 | Q1: 供电电压 | R1: 用电功率 | S1: 备注 | T1: 设备清单批注
A2: EATA23 通信系统 | B2: ELT发射器 | C2: 2321E01001G900 | D2: 2301U3101 | F2: 客舱-顶部 | G2: 2 | K2: =VLOOKUP(B2,电搭接情况统计!$B$2:$H$423,7,0) -> C类 | M2: 有 | N2: 是 | O2: 是
A3: EATA23 通信系统 | B3: ELT天线 | C3: 2321E01003G900 | D3: 2301A3901 | F3: 客舱-外部 | G3: 2 | K3: =VLOOKUP(B3,电搭接情况统计!$B$2:$H$423,7,0) -> A类 | M3: 有 | N3: 是 | O3: 否
A4: EATA23 通信系统 | B4: 音频管理单元1 | C4: 2350E01001G900 | D4: 2302U2501 | F4: 驾驶舱-左设备架 | G4: 2 | I4: =VLOOKUP($B4,设备架接口信息!$A$1:$G$69,4,0) -> 2MCU托架安装，A类锁紧器 | J4: =VLOOKUP($B4,设备架接口信息!$A$1:$G$69,5,0) -> 面搭接 | K4: =VLOOKUP(B4,电搭接情况统计!$B$2:$H$423,7,0) -> C类 | L4: =VLOOKUP($B4,设备架接口信息!$A$1:$G$69,6,0) -> 2.671105 | M4: 有 | N4: 是 | O4: 是 | S4: 重量含托架
A5: EATA23 通信系统 | B5: 音频管理单元2 | C5: 2350E01001G900 | D5: 2302U2603 | F5: 驾驶舱-右设备架 | G5: 2 | I5: =VLOOKUP($B5,设备架接口信息!$A$1:$G$69,4,0) -> 2MCU托架安装，A类锁紧器 | J5: =VLOOKUP($B5,设备架接口信息!$A$1:$G$69,5,0) -> 面搭接 | K5: =VLOOKUP(B5,电搭接情况统计!$B$2:$H$423,7,0) -> C类 | L5: =VLOOKUP($B5,设备架接口信息!$A$1:$G$69,6,0) -> 2.687105 | M5: 有 | N5: 是 | O5: 是 | S5: 重量含托架
A6: EATA23 通信系统 | B6: 音频插孔面板1 | C6: 2350E02001G900 | D6: 2302D2401 | F6: 驾驶舱-控制面板 | G6: 2 | K6: =VLOOKUP(B6,电搭接情况统计!$B$2:$H$423,7,0) -> C类 | M6: 有 | N6: 是 | O6: 是
A7: EATA23 通信系统 | B7: 音频插孔面板2 | C7: 2350E02001G900 | D7: 2302D2403 | F7: 驾驶舱-控制面板 | G7: 2 | K7: =VLOOKUP(B7,电搭接情况统计!$B$2:$H$423,7,0) -> C类 | M7: 有 | N7: 是 | O7: 是
A8: EATA23 通信系统 | B8: 悬臂式耳机1 | C8: 2350E02003G900 | D8: 2302R2101 | F8: 驾驶舱-顶部 | G8: 2 | M8: 无 | N8: 否 | O8: 否
A9: EATA23 通信系统 | B9: 悬臂式耳机2 | C9: 2350E02003G900 | D9: 2302R2103 | F9: 驾驶舱-顶部 | G9: 2 | M9: 无 | N9: 否 | O9: 否
A10: EATA23 通信系统 | B10: 手持话筒1 | C10: 2350E02005G900 | D10: 2302D2101 | F10: 驾驶舱-顶部 | G10: 2 | K10: =VLOOKUP(B10,电搭接情况统计!$B$2:$H$423,7,0) -> C类 | M10: 无 | N10: 否 | O10: 否
A11: EATA23 通信系统 | B11: 手持话筒2 | C11: 2350E02005G900 | D11: 2302D2103 | F11: 驾驶舱-顶部 | G11: 2 | K11: =VLOOKUP(B11,电搭接情况统计!$B$2:$H$423,7,0) -> C类 | M11: 无 | N11: 否 | O11: 否
A12: EATA23 通信系统 | B12: 扬声器1 | C12: 2350E02007G900 | D12: 2302E2101 | F12: 驾驶舱-顶部 | G12: 2 | K12: =VLOOKUP(B12,电搭接情况统计!$B$2:$H$423,7,0) -> C类 | M12: 有 | N12: 是 | O12: 否
A13: EATA23 通信系统 | B13: 扬声器2 | C13: 2350E02007G900 | D13: 2302E2103 | F13: 驾驶舱-顶部 | G13: 2 | K13: =VLOOKUP(B13,电搭接情况统计!$B$2:$H$423,7,0) -> C类 | M13: 有 | N13: 是 | O13: 否
A14: EATA23 通信系统 | B14: 后缘型静电放电器1 | C14: 2362E01001G900 | D14: 2315G6201 | F14: 机翼-机翼外段 | G14: 1 | H14: 建议更改连接形式 | K14: =VLOOKUP(B14,电搭接情况统计!$B$2:$H$423,7,0) -> 静电放电器复材底座 | M14: 无 | N14: 否 | O14: 否
A15: EATA23 通信系统 | B15: 后缘型静电放电器2 | C15: 2362E01001G900 | D15: 2315G6203 | F15: 机翼-机翼外段 | G15: 1 | H15: 建议更改连接形式 | K15: =VLOOKUP(B15,电搭接情况统计!$B$2:$H$423,7,0) -> 静电放电器复材底座 | M15: 无 | N15: 否 | O15: 否
A16: EATA23 通信系统 | B16: 后缘型静电放电器3 | C16: 2362E01001G900 | D16: 2315G6205 | F16: 机翼-机翼外段 | G16: 1 | H16: 建议更改连接形式 | K16: =VLOOKUP(B16,电搭接情况统计!$B$2:$H$423,7,0) -> 静电放电器复材底座 | M16: 无 | N16: 否 | O16: 否
A17: EATA23 通信系统 | B17: 后缘型静电放电器4 | C17: 2362E01001G900 | D17: 2315G6207 | F17: 机翼-机翼外段 | G17: 1 | H17: 建议更改连接形式 | K17: =VLOOKUP(B17,电搭接情况统计!$B$2:$H$423,7,0) -> 静电放电器复材底座 | M17: 无 | N17: 否 | O17: 否
A18: EATA23 通信系统 | B18: 后缘型静电放电器5 | C18: 2362E01001G900 | D18: 2315G6209 | F18: 机翼-机翼外段 | G18: 1 | H18: 建议更改连接形式 | K18: =VLOOKUP(B18,电搭接情况统计!$B$2:$H$423,7,0) -> 静电放电器复材底座 | M18: 无 | N18: 否 | O18: 否
A19: EATA23 通信系统 | B19: 后缘型静电放电器6 | C19: 2362E01001G900 | D19: 2315G6211 | F19: 机翼-机翼外段 | G19: 1 | H19: 建议更改连接形式 | K19: =VLOOKUP(B19,电搭接情况统计!$B$2:$H$423,7,0) -> 静电放电器复材底座 | M19: 无 | N19: 否 | O19: 否
A20: EATA23 通信系统 | B20: 后缘型静电放电器7 | C20: 2362E01001G900 | D20: 2315G8301 | F20: 尾段-水平尾翼 | G20: 1 | H20: 建议更改连接形式 | K20: =VLOOKUP(B20,电搭接情况统计!$B$2:$H$423,7,0) -> 静电放电器复材底座 | M20: 无 | N20: 否 | O20: 否
A21: EATA23 通信系统 | B21: 后缘型静电放电器8 | C21: 2362E01001G900 | D21: 2315G8303 | F21: 尾段-水平尾翼 | G21: 1 | H21: 建议更改连接形式 | K21: =VLOOKUP(B21,电搭接情况统计!$B$2:$H$423,7,0) -> 静电放电器复材底座 | M21: 无 | N21: 否 | O21: 否
A22: EATA23 通信系统 | B22: 后缘型静电放电器9 | C22: 2362E01001G900 | D22: 2315G8305 | F22: 尾段-水平尾翼 | G22: 1 | H22: 建议更改连接形式 | K22: =VLOOKUP(B22,电搭接情况统计!$B$2:$H$423,7,0) -> 静电放电器复材底座 | M22: 无 | N22: 否 | O22: 否
A23: EATA23 通信系统 | B23: 后缘型静电放电器10 | C23: 2362E01001G900 | D23: 2315G8307 | F23: 尾段-水平尾翼 | G23: 1 | H23: 建议更改连接形式 | K23: =VLOOKUP(B23,电搭接情况统计!$B$2:$H$423,7,0) -> 静电放电器复材底座 | M23: 无 | N23: 否 | O23: 否
A24: EATA23 通信系统 | B24: 后缘型静电放电器11 | C24: 2362E01001G900 | D24: 2315G8309 | F24: 尾段-水平尾翼 | G24: 1 | H24: 建议更改连接形式 | K24: =VLOOKUP(B24,电搭接情况统计!$B$2:$H$423,7,0) -> 静电放电器复材底座 | M24: 无 | N24: 否 | O24: 否
A25: EATA23 通信系统 | B25: 后缘型静电放电器12 | C25: 2362E01001G900 | D25: 2315G8311 | F25: 尾段-水平尾翼 | G25: 1 | H25: 建议更改连接形式 | K25: =VLOOKUP(B25,电搭接情况统计!$B$2:$H$423,7,0) -> 静电放电器复材底座 | M25: 无 | N25: 否 | O25: 否
... A28: EATA23 通信系统 | B28: 后缘型静电放电器15 | C28: 2362E01001G900 | D28: 2315G8205 | F28: 尾段-垂直尾翼 | G28: 1 | H28: 建议更改连接形式 | K28: =VLOOKUP(B28,电搭接情况统计!$B$2:$H$423,7,0) -> 静电放电器复材底座 | M28: 无 | N28: 否 | O28: 否
A29: EATA23 通信系统 | B29: 5G ATG机载CPE | C29: 2393E01001G900 | D29: 2301U3601 | F29: 客舱-后设备舱左设备架 | G29: 2 | I29: =VLOOKUP($B29,设备架接口信息!$A$1:$G$69,4,0) -> 4MCU托架安装，C类锁紧器，托架下方安装风扇 | J29: =VLOOKUP($B29,设备架接口信息!$A$1:$G$69,5,0) -> 面搭接 | K29: =VLOOKUP(B29,电搭接情况统计!$B$2:$H$423,7,0) -> R类 | L29: =VLOOKUP($B29,设备架接口信息!$A$1:$G$69,6,0) -> 10.081134 | M29: 有 | N29: 是 | O29: 否 | S29: 重量含托架
A30: EATA23 通信系统 | B30: 功率放大器 | C30: 2393E01001U900 | D30: 2301U3201 | F30: 客舱-后设备舱左设备架 | G30: 2 | H30: 需改为标准ARINC600机箱 | I30: =VLOOKUP($B30,设备架接口信息!$A$1:$G$69,4,0) -> 六角螺栓安装 | J30: =VLOOKUP($B30,设备架接口信息!$A$1:$G$69,5,0) -> 线搭接 | K30: =VLOOKUP(B30,电搭接情况统计!$B$2:$H$423,7,0) -> R类 | L30: =VLOOKUP($B30,设备架接口信息!$A$1:$G$69,6,0) -> 3.869881 | M30: 有 | N30: 是 | O30: 否
A31: EATA23 通信系统 | B31: 5G ATG全向天线 | C31: 2393E01003U900 | D31: 2301A4901 | F31: 下机身前段-外部 | G31: 2 | K31: =VLOOKUP(B31,电搭接情况统计!$B$2:$H$423,7,0) -> A类 | M31: 有 | N31: 是 | O31: 否
A32: EATA23 通信系统 | B32: 电源转换模块 | C32: 2393E01005U900 | D32: 2301T3201 | F32: 客舱-后设备舱盘箱 | G32: 2 | H32: 需改为标准ARINC600机箱 | I32: =VLOOKUP($B32,设备架接口信息!$A$1:$G$69,4,0) -> 四角螺栓安装 | J32: =VLOOKUP($B32,设备架接口信息!$A$1:$G$69,5,0) -> 线搭接 | K32: =VLOOKUP(B32,电搭接情况统计!$B$2:$H$423,7,0) -> C类 | L32: =VLOOKUP($B32,设备架接口信息!$A$1:$G$69,6,0) -> 6.386789 | M32: 有 | N32: 是 | O32: 是
A33: EATA24 电源系统 | B33: E 270V电池（含BMS） | C33: 2431E01001G900 | D33: 2401G4101 | F33: 下机身前段-前设备舱 | G33: 1 | K33: =VLOOKUP(B33,电搭接情况统计!$B$2:$H$423,7,0) -> 双线制 R H S类，壳体搭接； | L33: 98 | M33: 有 | N33: 是 | O33: 是 | S33: 【20260309】提供新重量
A34: EATA24 电源系统 | B34: LR 270V电池（含BMS） | C34: 2431E01003G900 | D34: 2401G5201 | F34: 下机身后段-中设备舱 | G34: 1 | K34: =VLOOKUP(B34,电搭接情况统计!$B$2:$H$423,7,0) -> 双线制 R H S类，壳体搭接； | L34: 192.4 | M34: 有 | N34: 是 | O34: 是 | S34: 【20260309】提供新重量
A35: EATA24 电源系统 | B35: 应急28V电池（含BMS） | C35: 2432E01001G900 | D35: 2401G4103 | F35: 下机身前段-前设备舱 | G35: 1 | K35: =VLOOKUP(B35,电搭接情况统计!$B$2:$H$423,7,0) -> #N/A | L35: 18.8 | M35: 有 | N35: 是 | O35: 是 | S35: 【20260309】提供新重量
A36: EATA24 电源系统 | B36: 机身外部充电接口 | T36: 新增替换原有面板和插座
A37: EATA24 电源系统 | B37: 左配电盘箱 | C37: 2461E01001G900 | D37: 2401U3401 | E37: 390*460*200 | F37: 客舱-后设备舱盘箱 | G37: 1 | H37: 改成单面出线、缩小体积重量 | I37: 两侧出线，六个安装孔，方案未冻结 | J37: =VLOOKUP($B37,设备架接口信息!$A$1:$G$69,5,0) -> 线搭接 | K37: =VLOOKUP(B37,电搭接情况统计!$B$2:$H$423,7,0) -> C 类 R H S类，壳体搭接； | L37: =VLOOKUP($B37,设备架接口信息!$A$1:$G$69,6,0) -> 18 | M37: 有 | N37: 是 | O37: 是 | S37: 安装方式调整
A38: EATA24 电源系统 | B38: 右配电盘箱 | C38: 2461E01003G900 | D38: 2401U3403 | E38: 390*460*200 | F38: 客舱-后设备舱盘箱 | G38: 1 | H38: 改成单面出线、缩小体积重量 | I38: 两侧出线，六个安装孔，方案未冻结 | J38: =VLOOKUP($B38,设备架接口信息!$A$1:$G$69,5,0) -> 线搭接 | K38: =VLOOKUP(B38,电搭接情况统计!$B$2:$H$423,7,0) -> C 类 R H S类，壳体搭接； | L38: =VLOOKUP($B38,设备架接口信息!$A$1:$G$69,6,0) -> 18 | M38: 有 | N38: 是 | O38: 是 | S38: 安装方式调整
A39: EATA24 电源系统 | B39: 应急配电盘箱 | C39: 2461E01005G900 | D39: 2401U2601 | E39: 320*650*170 | F39: 驾驶舱-右设备架 | G39: 1 | H39: 改成单面出线、缩小体积重量 | I39: 两侧出线，六个安装孔，方案未冻结 | J39: =VLOOKUP($B39,设备架接口信息!$A$1:$G$69,5,0) -> 线搭接 | K39: =VLOOKUP(B39,电搭接情况统计!$B$2:$H$423,7,0) -> C 类 R H S类，壳体搭接； | L39: =VLOOKUP($B39,设备架接口信息!$A$1:$G$69,6,0) -> 18 | M39: 有 | N39: 是 | O39: 是 | S39: 安装方式调整
A40: EATA24 电源系统 | B40: 远程配电装置 RPDU1 | C40: 2462E01001G900 | D40: 2404U4101 | F40: 驾驶舱-右设备架 | G40: 1 | H40: 缩小设备尺寸，降低设备宽度 | I40: =VLOOKUP($B40,设备架接口信息!$A$1:$G$69,4,0) -> 四角螺栓安装 | J40: =VLOOKUP($B40,设备架接口信息!$A$1:$G$69,5,0) -> 线搭接 | K40: =VLOOKUP(B40,电搭接情况统计!$B$2:$H$423,7,0) -> C 类 R H S类，壳体搭接； | L40: 7.6 | M40: 有 | N40: 是 | O40: 是 | S40: 位置调整 【20260309】提供新重量
A41: EATA24 电源系统 | B41: 远程配电装置 RPDU2 | C41: 2462E01003G900 | D41: 2404U4103 | F41: 驾驶舱-左设备架 | G41: 1 | H41: 缩小设备尺寸，降低设备宽度 | I41: =VLOOKUP($B41,设备架接口信息!$A$1:$G$69,4,0) -> 四角螺栓安装 | J41: =VLOOKUP($B41,设备架接口信息!$A$1:$G$69,5,0) -> 线搭接 | K41: =VLOOKUP(B41,电搭接情况统计!$B$2:$H$423,7,0) -> C 类 R H S类，壳体搭接； | L41: 7.6 | M41: 有 | N41: 是 | O41: 是 | S41: 位置调整 【20260309】提供新重量
A42: EATA24 电源系统 | B42: 远程配电装置 RPDU3 | C42: 2462E01005G900 | D42: 2404U3405 | F42: 客舱-后设备舱左设备架 | G42: 1 | H42: 缩小设备尺寸，降低设备宽度 | I42: =VLOOKUP($B42,设备架接口信息!$A$1:$G$69,4,0) -> 四角螺栓安装 | J42: =VLOOKUP($B42,设备架接口信息!$A$1:$G$69,5,0) -> 线搭接 | K42: =VLOOKUP(B42,电搭接情况统计!$B$2:$H$423,7,0) -> C 类 R H S类，壳体搭接； | L42: 7.6 | M42: 有 | N42: 是 | O42: 是 | S42: 位置调整 【20260309】提供新重量
...

Sheet X号构型
A1: 系统章节 | B1: 设备名称 | C1: 设备编号 | D1: LIN号 | E1: 长*高*宽 mm | F1: 设备布置区域 | G1: 构型分类 | H1: 是否使用 0号机设备 | I1: 总体布置调整需求 | J1: 安装方式 下拉选择，【选择托架需填写sheet2托架信息表！！】 | K1: 电搭接方式 | L1: 电搭接类型 | M1: 重量(kg) 托架重量分开填到sheet2 | N1: 是否有EICD | O1: 是否是电设备 | P1: 供电余度 | Q1: 供电电压 | R1: 用电功率 | S1: 备注
A2: EATA11 标牌与标识 | B2: TBD | F2: TBD | G2: 3 | H2: 是 | T2: 可以先删除这行，后续系统反馈后，如有再加
A3: EATA21 空调系统 | B3: 气源系统控制器 | C3: TBD | D3: TBD | F3: TBD | G3: 3 | H3: 是 | L3: =VLOOKUP(B3,电搭接情况统计!$B$2:$H$423,7,0) -> #N/A | N3: 是
A4: EATA21 空调系统 | B4: 气源冲压进气道及作动器（含风门） | C4: TBD | D4: TBD | F4: TBD | G4: 3 | H4: 是 | L4: =VLOOKUP(B4,电搭接情况统计!$B$2:$H$423,7,0) -> #N/A | N4: 是
A5: EATA21 空调系统 | B5: 冲压进气道-气源压缩机连接管 | C5: TBD | D5: TBD | F5: TBD | G5: 3 | H5: 是 | L5: =VLOOKUP(B5,电搭接情况统计!$B$2:$H$423,7,0) -> #N/A | N5: 是
A6: EATA21 空调系统 | B6: 进口过滤器 | C6: TBD | D6: TBD | F6: TBD | G6: 3 | H6: 是 | L6: =VLOOKUP(B6,电搭接情况统计!$B$2:$H$423,7,0) -> #N/A | N6: 是
A7: EATA21 空调系统 | B7: 气源压缩机 | C7: TBD | D7: TBD | F7: TBD | G7: 3 | H7: 是 | L7: =VLOOKUP(B7,电搭接情况统计!$B$2:$H$423,7,0) -> #N/A | N7: 是
A8: EATA21 空调系统 | B8: 气源压缩机电机 | C8: TBD | D8: TBD | F8: TBD | G8: 3 | H8: 是 | L8: =VLOOKUP(B8,电搭接情况统计!$B$2:$H$423,7,0) -> #N/A | N8: 是
A9: EATA21 空调系统 | B9: 气源压缩机出口单向活门 | C9: TBD | D9: TBD | F9: TBD | G9: 3 | H9: 是 | L9: =VLOOKUP(B9,电搭接情况统计!$B$2:$H$423,7,0) -> #N/A | N9: 是
A10: EATA21 空调系统 | B10: 气源压缩机出口流量传感器 | C10: TBD | D10: TBD | F10: TBD | G10: 3 | H10: 是 | L10: =VLOOKUP(B10,电搭接情况统计!$B$2:$H$423,7,0) -> #N/A | N10: 是 | T10: ZHT是否还有压力传感器？
A11: EATA21 空调系统 | B11: 气源热泵连接管 | C11: TBD | D11: TBD | F11: TBD | G11: 3 | H11: 是 | N11: 否 | T11: ZHT是否还有混合腔？
A12: EATA21 空调系统 | B12: 热泵蒸发制冷系统控制器 | C12: TBD | D12: TBD | F12: TBD | G12: 3 | H12: 是 | N12: 否 | T12: ZHT是否还有混合腔？
A13: EATA21 空调系统 | B13: 舱内换热器 | C13: TBD | D13: TBD | F13: TBD | G13: 3 | H13: 是 | N13: 否 | T13: ZHT是否还有混合腔？
A14: EATA21 空调系统 | B14: 制冷压缩机 | C14: TBD | D14: TBD | F14: TBD | G14: 3 | H14: 是 | N14: 否 | T14: ZHT是否还有混合腔？
A15: EATA21 空调系统 | B15: 四通换向阀 | C15: TBD | D15: TBD | F15: TBD | G15: 3 | H15: 是 | N15: 否
A16: EATA21 空调系统 | B16: 气液分离器 | C16: TBD | D16: TBD | F16: TBD | G16: 3 | H16: 是 | L16: =VLOOKUP(B16,电搭接情况统计!$B$2:$H$423,7,0) -> #N/A | N16: 是
A17: EATA21 空调系统 | B17: 双向电子膨胀阀 | C17: TBD | D17: TBD | F17: TBD | G17: 3 | H17: 是 | N17: 否
A18: EATA21 空调系统 | B18: 泄压阀 | C18: TBD | D18: TBD | F18: TBD | G18: 3 | H18: 是 | N18: 否
A19: EATA21 空调系统 | B19: 舱外换热器 | C19: TBD | D19: TBD | F19: TBD | G19: 3 | H19: 是 | N19: 否
A20: EATA21 空调系统 | B20: 热沉冲压进气道及作动器（含风门） | C20: TBD | D20: TBD | F20: TBD | G20: 3 | H20: 是 | N20: 否
A21: EATA21 空调系统 | B21: 热泵导热介质管路（含冷凝水管路） | C21: TBD | D21: TBD | F21: TBD | G21: 3 | H21: 是 | L21: =VLOOKUP(B21,电搭接情况统计!$B$2:$H$423,7,0) -> #N/A | N21: 否
A22: EATA21 空调系统 | B22: 冷却风扇 | C22: TBD | D22: TBD | F22: TBD | G22: 3 | H22: 是 | L22: =VLOOKUP(B22,电搭接情况统计!$B$2:$H$423,7,0) -> #N/A | N22: 是
A23: EATA21 空调系统 | B23: 热泵排气活门 | C23: TBD | D23: TBD | F23: TBD | G23: 3 | H23: 是 | N23: 否
A24: EATA21 空调系统 | B24: 制冷压缩机进口温度传感器TS1 | C24: TBD | D24: TBD | F24: TBD | G24: 3 | H24: 是 | N24: 是
A25: EATA21 空调系统 | B25: 制冷压缩机进口压力传感器PS1 | C25: TBD | D25: TBD | F25: TBD | G25: 3 | H25: 是 | N25: 是
A26: EATA21 空调系统 | B26: 制冷压缩机出口温度传感器TS2 | C26: TBD | D26: TBD | F26: TBD | G26: 3 | H26: 是 | N26: 是
A27: EATA21 空调系统 | B27: 制冷压缩机出口压力传感器PS2 | C27: TBD | D27: TBD | F27: TBD | G27: 3 | H27: 是 | J27: =VLOOKUP($B27,设备架接口信息!$A$1:$G$69,4,0) -> #N/A | K27: =VLOOKUP($B27,设备架接口信息!$A$1:$G$69,5,0) -> #N/A | M27: =VLOOKUP($B27,设备架接口信息!$A$1:$G$69,6,0) -> #N/A | N27: 是 | S27: 重量为估算值
A28: EATA21 空调系统 | B28: 舱内换热器温度传感器TS3 | C28: TBD | D28: TBD | F28: TBD | G28: 3 | H28: 是 | J28: =VLOOKUP($B28,设备架接口信息!$A$1:$G$69,4,0) -> #N/A | K28: =VLOOKUP($B28,设备架接口信息!$A$1:$G$69,5,0) -> #N/A | M28: =VLOOKUP($B28,设备架接口信息!$A$1:$G$69,6,0) -> #N/A | N28: 是 | S28: 重量为估算值
A29: EATA21 空调系统 | B29: 舱内换热器压力传感器PS3 | C29: TBD | D29: TBD | F29: TBD | G29: 3 | H29: 是 | N29: 否
A30: EATA21 空调系统 | B30: 舱外换热器温度传感器TS4 | C30: TBD | D30: TBD | F30: TBD | G30: 3 | H30: 是 | N30: 是
A31: EATA21 空调系统 | B31: 舱外换热器压力传感器PS4 | C31: TBD | D31: TBD | F31: TBD | G31: 3 | H31: 是 | N31: 是
A32: EATA21 空调系统 | B32: 通风系统控制器 | C32: TBD | D32: TBD | F32: TBD | G32: 3 | H32: 是 | N32: 是
A33: EATA21 空调系统 | B33: 再循环风扇 | C33: TBD | D33: TBD | F33: TBD | G33: 3 | H33: 是 | N33: 是
A34: EATA21 空调系统 | B34: 再循环回风管路 | C34: TBD | D34: TBD | F34: TBD | G34: 3 | H34: 是 | N34: 是
A35: EATA21 空调系统 | B35: 热泵通风连接管 | C35: TBD | D35: TBD | F35: TBD | G35: 3 | H35: 是 | N35: 是
A36: EATA21 空调系统 | B36: 应急冲压进气道及作动器（含风门） | C36: 2153E01001G900 | D36: 2101M8101 | F36: TBD | G36: 3 | H36: 是 | N36: 是
A37: EATA21 空调系统 | B37: 应急冲压风扇（带单向活门） | C37: 2153E01003G900 | D37: 2101M8103 | F37: TBD | G37: 3 | H37: 是 | N37: 是
A38: EATA21 空调系统 | B38: 单向活门EMR | C38: TBD | D38: TBD | F38: TBD | G38: 3 | H38: 是 | N38: 是
A39: EATA21 空调系统 | B39: 单向活门CA | C39: TBD | D39: TBD | F39: TBD | G39: 3 | H39: 是 | N39: 是
A40: EATA21 空调系统 | B40: 单向活门F | C40: TBD | D40: TBD | F40: TBD | G40: 3 | H40: 是 | N40: 否
...

Sheet 托架信息
A1: 设备托架名称 | B1: 设备托架编号 | C1: 托架LIN号 | D1: 托架长*高*宽 | E1: 设备布置区域 | F1: 托架重量 | G1: 构型分类 （同设备） | H1: 锁紧器 下拉选择 | I1: 特殊需求 | J1: 是否158提供 | K1: 对应设备
A2: =K2&"-"&L2 -> 空调系统综合控制器1-托架 | E2: =VLOOKUP(K2,'1&2号构型'!B:F,5,0) -> #N/A | G2: =VLOOKUP(K2,'1&2号构型'!B:G,7,0) -> #N/A | H2: A类锁紧器 | K2: 空调系统综合控制器1 | L2: 托架
A3: =K3&"-"&L3 -> 空调系统综合控制器2-托架 | E3: =VLOOKUP(K3,'1&2号构型'!B:F,5,0) -> #N/A | G3: =VLOOKUP(K3,'1&2号构型'!B:G,7,0) -> #N/A | H3: A类锁紧器 | K3: 空调系统综合控制器2 | L3: 托架
A4: =K4&"-"&L4 -> 显控计算机1-托架 | E4: =VLOOKUP(K4,'1&2号构型'!B:F,5,0) -> 驾驶舱-右设备架 | G4: =VLOOKUP(K4,'1&2号构型'!B:G,7,0) -> #REF! | H4: C类锁紧器 | I4: 托架底部需散热风道 | J4: 设备提供 | K4: 显控计算机1 | L4: 托架
A5: =K5&"-"&L5 -> 交通监视处理机-托架 | E5: =VLOOKUP(K5,'1&2号构型'!B:F,5,0) -> 驾驶舱-左设备架 | G5: =VLOOKUP(K5,'1&2号构型'!B:G,7,0) -> #REF! | H5: A类锁紧器 | J5: 设备提供 | K5: 交通监视处理机 | L5: 托架
A6: =K6&"-"&L6 -> 音频管理单元1-托架 | E6: =VLOOKUP(K6,'1&2号构型'!B:F,5,0) -> 驾驶舱-左设备架 | G6: =VLOOKUP(K6,'1&2号构型'!B:G,7,0) -> #REF! | H6: A类锁紧器 | J6: 设备提供 | K6: 音频管理单元1 | L6: 托架
A7: =K7&"-"&L7 -> 备份飞控计算机-托架 | E7: =VLOOKUP(K7,'1&2号构型'!B:F,5,0) -> 驾驶舱-左设备架 | G7: =VLOOKUP(K7,'1&2号构型'!B:G,7,0) -> #REF! | H7: A类锁紧器 | J7: 设备提供 | K7: 备份飞控计算机 | L7: 托架
A8: =K8&"-"&L8 -> 数据接口单元3-托架 | E8: =VLOOKUP(K8,'1&2号构型'!B:F,5,0) -> 驾驶舱-左设备架 | G8: =VLOOKUP(K8,'1&2号构型'!B:G,7,0) -> #REF! | H8: A类锁紧器 | J8: 158提供 | K8: 数据接口单元3 | L8: 托架
A9: =K9&"-"&L9 -> 数据接口单元2-托架 | E9: =VLOOKUP(K9,'1&2号构型'!B:F,5,0) -> 驾驶舱-右设备架 | G9: =VLOOKUP(K9,'1&2号构型'!B:G,7,0) -> #REF! | H9: A类锁紧器 | J9: 158提供 | K9: 数据接口单元2 | L9: 托架
A10: =K10&"-"&L10 -> 主飞控计算机3-托架 | E10: =VLOOKUP(K10,'1&2号构型'!B:F,5,0) -> 驾驶舱-右设备架 | G10: =VLOOKUP(K10,'1&2号构型'!B:G,7,0) -> #REF! | H10: A类锁紧器 | J10: 158提供 | K10: 主飞控计算机3 | L10: 托架
A11: =K11&"-"&L11 -> 显控计算机2-托架 | E11: =VLOOKUP(K11,'1&2号构型'!B:F,5,0) -> 驾驶舱-左设备架 | G11: =VLOOKUP(K11,'1&2号构型'!B:G,7,0) -> #REF! | H11: C类锁紧器 | I11: 托架底部需散热风道 | J11: 设备提供 | K11: 显控计算机2 | L11: 托架
A12: =K12&"-"&L12 -> 音频管理单元2-托架 | E12: =VLOOKUP(K12,'1&2号构型'!B:F,5,0) -> 驾驶舱-右设备架 | G12: =VLOOKUP(K12,'1&2号构型'!B:G,7,0) -> #REF! | H12: A类锁紧器 | J12: 设备提供 | K12: 音频管理单元2 | L12: 托架
A13: =K13&"-"&L13 -> 数据接口单元1-托架 | E13: =VLOOKUP(K13,'1&2号构型'!B:F,5,0) -> 驾驶舱-右设备架 | G13: =VLOOKUP(K13,'1&2号构型'!B:G,7,0) -> #REF! | H13: A类锁紧器 | J13: 158提供 | K13: 数据接口单元1 | L13: 托架
A14: =K14&"-"&L14 -> 主飞控计算机2-托架 | E14: =VLOOKUP(K14,'1&2号构型'!B:F,5,0) -> 客舱-后设备舱左设备架 | G14: =VLOOKUP(K14,'1&2号构型'!B:G,7,0) -> #REF! | H14: A类锁紧器 | J14: 158提供 | K14: 主飞控计算机2 | L14: 托架
A15: =K15&"-"&L15 -> 飞机数据网络交换机1-托架 | E15: =VLOOKUP(K15,'1&2号构型'!B:F,5,0) -> 驾驶舱-左设备架 | G15: =VLOOKUP(K15,'1&2号构型'!B:G,7,0) -> #REF! | H15: A类锁紧器 | J15: 158提供 | K15: 飞机数据网络交换机1 | L15: 托架
A16: =K16&"-"&L16 -> 甚高频通信及无线电导航集成设备2-托架 | E16: =VLOOKUP(K16,'1&2号构型'!B:F,5,0) -> 客舱-后设备舱左设备架 | G16: =VLOOKUP(K16,'1&2号构型'!B:G,7,0) -> #REF! | J16: 设备提供 | K16: 甚高频通信及无线电导航集成设备2 | L16: 托架
A17: =K17&"-"&L17 -> 数据接口单元4-托架 | E17: =VLOOKUP(K17,'1&2号构型'!B:F,5,0) -> 客舱-后设备舱左设备架 | G17: =VLOOKUP(K17,'1&2号构型'!B:G,7,0) -> #REF! | H17: A类锁紧器 | J17: 158提供 | K17: 数据接口单元4 | L17: 托架
A18: =K18&"-"&L18 -> 通用信息处理计算机-托架 | E18: =VLOOKUP(K18,'1&2号构型'!B:F,5,0) -> 客舱-后设备舱左设备架 | G18: =VLOOKUP(K18,'1&2号构型'!B:G,7,0) -> #REF! | H18: A类锁紧器 | J18: 158提供 | K18: 通用信息处理计算机 | L18: 托架
A19: =K19&"-"&L19 -> 北斗卫星导航接收机-托架 | E19: =VLOOKUP(K19,'1&2号构型'!B:F,5,0) -> #N/A | G19: =VLOOKUP(K19,'1&2号构型'!B:G,7,0) -> #N/A | H19: A类锁紧器 | J19: 158提供 | K19: 北斗卫星导航接收机 | L19: 托架
A20: =K20&"-"&L20 -> 数据接口单元5-托架 | E20: =VLOOKUP(K20,'1&2号构型'!B:F,5,0) -> 客舱-后设备舱左设备架 | G20: =VLOOKUP(K20,'1&2号构型'!B:G,7,0) -> #REF! | H20: A类锁紧器 | J20: 158提供 | K20: 数据接口单元5 | L20: 托架
A21: =K21&"-"&L21 -> 5G ATG机载CPE-托架 | E21: =VLOOKUP(K21,'1&2号构型'!B:F,5,0) -> 客舱-后设备舱左设备架 | G21: =VLOOKUP(K21,'1&2号构型'!B:G,7,0) -> #REF! | H21: C类锁紧器 | I21: 托架底部有散热风扇 | J21: 设备提供 | K21: 5G ATG机载CPE | L21: 托架
A22: =K22&"-"&L22 -> 主飞控计算机1-托架 | E22: =VLOOKUP(K22,'1&2号构型'!B:F,5,0) -> 客舱-后设备舱右设备架 | G22: =VLOOKUP(K22,'1&2号构型'!B:G,7,0) -> #REF! | H22: A类锁紧器 | J22: 158提供 | K22: 主飞控计算机1 | L22: 托架
A23: =K23&"-"&L23 -> 飞机数据网络交换机2-托架 | E23: =VLOOKUP(K23,'1&2号构型'!B:F,5,0) -> 驾驶舱-右设备架 | G23: =VLOOKUP(K23,'1&2号构型'!B:G,7,0) -> #REF! | H23: A类锁紧器 | J23: 158提供 | K23: 飞机数据网络交换机2 | L23: 托架
A24: =K24&"-"&L24 -> 数据接口单元6-托架 | E24: =VLOOKUP(K24,'1&2号构型'!B:F,5,0) -> 客舱-后设备舱右设备架 | G24: =VLOOKUP(K24,'1&2号构型'!B:G,7,0) -> #REF! | H24: A类锁紧器 | J24: 158提供 | K24: 数据接口单元6 | L24: 托架
A25: =K25&"-"&L25 -> 甚高频通信及无线电导航集成设备1-托架 | E25: =VLOOKUP(K25,'1&2号构型'!B:F,5,0) -> 客舱-后设备舱右设备架 | G25: =VLOOKUP(K25,'1&2号构型'!B:G,7,0) -> #REF! | J25: 设备提供 | K25: 甚高频通信及无线电导航集成设备1 | L25: 托架
A26: =K26&"-"&L26 -> 结构健康监测设备-托架 | E26: =VLOOKUP(K26,'1&2号构型'!B:F,5,0) -> #N/A | G26: =VLOOKUP(K26,'1&2号构型'!B:G,7,0) -> #N/A | H26: A类锁紧器 | J26: 158提供 | K26: 结构健康监测设备 | L26: 托架
A27: =K27&"-"&L27 -> 防除冰控制器1-托架 | E27: =VLOOKUP(K27,'1&2号构型'!B:F,5,0) -> #N/A | G27: =VLOOKUP(K27,'1&2号构型'!B:G,7,0) -> #N/A | K27: 防除冰控制器1 | L27: 托架
A28: =K28&"-"&L28 -> 防除冰控制器2-托架 | E28: =VLOOKUP(K28,'1&2号构型'!B:F,5,0) -> #N/A | G28: =VLOOKUP(K28,'1&2号构型'!B:G,7,0) -> #N/A | K28: 防除冰控制器2 | L28: 托架
A29: =K29&"-"&L29 -> 风挡加热控制器1-托架 | E29: =VLOOKUP(K29,'1&2号构型'!B:F,5,0) -> 下机身前段-前设备舱 | G29: =VLOOKUP(K29,'1&2号构型'!B:G,7,0) -> #REF! | K29: 风挡加热控制器1 | L29: 托架
A30: =K30&"-"&L30 -> 风挡加热控制器2-托架 | E30: =VLOOKUP(K30,'1&2号构型'!B:F,5,0) -> 下机身前段-前设备舱 | G30: =VLOOKUP(K30,'1&2号构型'!B:G,7,0) -> #REF! | K30: 风挡加热控制器2 | L30: 托架
A31: =K31&"-"&L31 -> 驾驶舱灯具调光控制盒-托架 | E31: =VLOOKUP(K31,'1&2号构型'!B:F,5,0) -> 设备架 | G31: =VLOOKUP(K31,'1&2号构型'!B:G,7,0) -> #REF! | K31: 驾驶舱灯具调光控制盒 | L31: 托架
A32: =K32&"-"&L32 -> 客舱一般照明控制器-托架 | E32: =VLOOKUP(K32,'1&2号构型'!B:F,5,0) -> #N/A | G32: =VLOOKUP(K32,'1&2号构型'!B:G,7,0) -> #N/A | K32: 客舱一般照明控制器 | L32: 托架
L33: 托架
L34: 托架
L35: 托架
L36: 托架
L37: 托架
L38: 托架
L39: 托架

Sheet 设备架接口信息
A1: 设备名称 | B1: 布置位置 | C1: 左前设备架设备清单 | D1: 安装方式 | E1: 电搭接方式 | F1: 重量(kg) | G1: 备注
A2: 显控计算机1 | B2: 驾驶舱-左设备架 | C2: 3102U2201 | D2: 非标托架，C类锁紧器 | E2: 线搭接 | F2: 6.665 | G2: 含托架
A3: 惯性基准系统2 | B3: 驾驶舱-左设备架 | C3: 3401U2507 | D3: 六角螺栓安装 | E3: 线搭接 | F3: 5.4398 | G3: 含托架
A4: 惯性基准系统1 | B4: 驾驶舱-左设备架 | C4: 3401U2505 | D4: 六角螺栓安装 | E4: 线搭接 | F4: 5.335745 | G4: 含托架
A5: 交通监视处理机 | B5: 驾驶舱-左设备架 | C5: 3401U2503 | D5: 4MCU托架安装，A类锁紧器 | E5: 面搭接 | F5: 9.5 | G5: 不含托架，估算值
A6: 音频管理单元1 | B6: 驾驶舱-左设备架 | C6: 2302U2501 | D6: 2MCU托架安装，A类锁紧器 | E6: 面搭接 | F6: 2.671105 | G6: 含托架
A7: 驾驶舱机组无线通信单元 | B7: 驾驶舱-左设备架 | C7: 4601U2507 | D7: 四角螺栓安装 | E7: 面搭接 | F7: 1.2849
A8: 备份飞控计算机 | B8: 驾驶舱-左设备架 | C8: 2701U2505 | D8: 3MCU托架安装，A类锁紧器 | E8: 线搭接 | F8: 6.177486 | G8: 含托架
A9: 刹车控制监视单元 | B9: 驾驶舱-左设备架 | C9: 3201U2505 | D9: 3MCU托架安装，A类锁紧器 | E9: 面搭接 | F9: 4.06 | G9: 含托架
A10: 数据接口单元3 | B10: 驾驶舱-左设备架 | C10: 4206U2501 | D10: 3MCU托架安装，A类锁紧器 | E10: 面搭接 | F10: 3 | G10: 不含托架
A11: 收放控制单元2 | B11: 驾驶舱-左设备架 | C11: 3201U3503 | D11: 2MCU托架安装，A类锁紧器 | E11: 面搭接 | F11: 6 | G11: 含托架
A12: 登机门控制面板 | B12: 驾驶舱-左设备架 | C12: 5233E02001G900 | D12: 四角螺栓安装 | E12: 线搭接 | F12: 1.3
A13: 舱门控制系统控制器 | B13: 驾驶舱-左设备架 | C13: 5231E01000G900 | D13: 四角螺栓安装 | E13: 线搭接 | F13: 2
A14: 备份放继电器1 | B14: 驾驶舱-左设备架 | C14: 3201K2501 | D14: 三角螺栓安装 | E14: 面搭接 | F14: 0.15
A15: 备份放继电器2 | B15: 驾驶舱-左设备架 | C15: 3202K2501 | D15: 三角螺栓安装 | E15: 面搭接 | F15: 0.15
A16: 备份放继电器3 | B16: 驾驶舱-左设备架 | C16: 3202K2503 | D16: 三角螺栓安装 | E16: 面搭接 | F16: 0.15
A17: 大气数据计算机1 | B17: 驾驶舱-左设备架 | C17: 3403U2501 | D17: 四角螺栓安装 | E17: 面搭接 | F17: 0.790714
A18: 大气数据计算机2 | B18: 驾驶舱-左设备架 | C18: 3403U2503 | D18: 四角螺栓安装 | E18: 面搭接 | F18: 0.788214
A19: 远程配电装置 RPDU1 | B19: 驾驶舱-右设备架 | C19: 2404U4101 | D19: 四角螺栓安装 | E19: 线搭接 | F19: 7.3
A20: 远程配电装置 RPDU2 | B20: 驾驶舱-右设备架 | C20: 2404U4103 | D20: 四角螺栓安装 | E20: 线搭接 | F20: 7.3
A21: E270/28V DCDC | B21: 驾驶舱-右设备架 | C21: 2401T2601 | D21: 四角螺栓安装 | E21: 线搭接 | F21: 6.5
A22: 应急配电盘箱 | B22: 驾驶舱-右设备架 | C22: 2461E01005G900 | D22: / | E22: 线搭接 | F22: 18
A23: 飞控数据记录器1 | B23: 驾驶舱-右设备架 | C23: 2702U3201 | D23: 四角螺栓安装 | E23: 线搭接 | F23: 2.116
A24: 数据接口单元2 | B24: 驾驶舱-右设备架 | C24: 4206U2603 | D24: 3MCU托架安装，A类锁紧器 | E24: 面搭接 | F24: 3 | G24: 不含托架
A25: 主飞控计算机3 | B25: 驾驶舱-右设备架 | C25: 2703U2603 | D25: 3MCU托架安装，A类锁紧器 | E25: 面搭接 | F25: 5.057831 | G25: 含托架
A26: 显控计算机2 | B26: 驾驶舱-右设备架 | C26: 3102U2203 | D26: 非标托架，C类锁紧器 | E26: 面搭接 | F26: 6.665 | G26: 含托架
A27: 音频管理单元2 | B27: 驾驶舱-右设备架 | C27: 2302U2603 | D27: 2MCU托架安装，A类锁紧器 | E27: 面搭接 | F27: 2.687105 | G27: 含托架
A28: 数据接口单元1 | B28: 驾驶舱-右设备架 | C28: 4206U2601 | D28: 3MCU托架安装，A类锁紧器 | E28: 面搭接 | F28: 3 | G28: 不含托架
A29: 视觉辅助计算机 | B29: 驾驶舱-右设备架 | C29: 9001U2601 | D29: 四角螺栓安装 | E29: 面搭接 | F29: 2.41
A30: 大气数据计算机3 | B30: 驾驶舱-右设备架 | C30: 3403U2601 | D30: 四角螺栓安装 | E30: 面搭接 | F30: 0.787614
A31: 主飞控计算机2 | B31: 客舱-后设备舱左设备架 | C31: 2703U3501 | D31: 3MCU托架安装，A类锁紧器 | E31: 面搭接 | F31: 5.006831 | G31: 含托架
A32: 飞机数据网络交换机1 | B32: 客舱-后设备舱左设备架 | C32: 4202U3503 | D32: 4MCU托架安装，A类锁紧器 | E32: 面搭接 | F32: 3.8 | G32: 不含托架
A33: 甚高频通信及无线电导航集成设备2 | B33: 客舱-后设备舱左设备架 | C33: 3401U3501 | D33: 非标托架，无锁紧器，参照数模 | E33: 线搭接 | F33: 6.045385 | G33: 含托架
A34: 数据接口单元4 | B34: 客舱-后设备舱左设备架 | C34: 4206U3501 | D34: 3MCU托架安装，A类锁紧器 | E34: 面搭接 | F34: 3 | G34: 不含托架
A35: 收放控制单元1 | B35: 客舱-后设备舱左设备架 | C35: 3201U2501 | D35: 2MCU托架安装，A类锁紧器 | E35: 面搭接 | F35: 6 | G35: 含托架
A36: 通用信息处理计算机 | B36: 客舱-后设备舱左设备架 | C36: 4601U3503 | D36: 4MCU托架安装，A类锁紧器 | E36: 面搭接 | F36: 6.220516 | G36: 估算值
A37: GNSS射频功分器2 | B37: 客舱-后设备舱左设备架 | C37: 3401U3505 | D37: 四角螺栓安装 | E37: 面搭接 | F37: 0.289152
A38: LOC/GS功分器2 | B38: 客舱-后设备舱左设备架 | C38: 3402U3503 | D38: 两角螺栓安装 | E38: 面搭接 | F38: 0.079261
A39: 北斗卫星导航接收机 | B39: 客舱-后设备舱左设备架 | C39: 3401U3503 | D39: 2MCU托架安装，A类锁紧器 | E39: 面搭接 | F39: 2.589624 | G39: 含托架
A40: 数据接口单元5 | B40: 客舱-后设备舱左设备架 | C40: 4206U3503 | D40: 3MCU托架安装，A类锁紧器 | E40: 面搭接 | F40: 3 | G40: 不含托架
...

Sheet 电搭接情况统计
A1: 系统名称 | B1: 设备名称 | C1: 设备安装图 | D1: 设备编号 | E1: 设备布置 区域 | F1: 是否首飞上机 | G1: 电搭接形式 （面搭接/线搭接） 例：面搭接 | H1: 电搭接类型 （可参考sheet2） 例：A类 | I1: 电搭接 阻值要求 单位mΩ | J1: 搭接位置 （提供搭接的结构零件号-不是G200组件或坐标） 例：5325E0XXXXG700或坐标） | K1: 是否已在PACE 图纸中体现 | L1: 设备负责人
A2: ATA24 电源系统 | B2: LR 270V电池（含BMS） | C2: 2430E01000G200 | D2: 2431E01003G900 | E2: 下机身后段-中设备舱 | F2: 1 | G2: 线搭接 | H2: 双线制 R H S类，壳体搭接； | I2: 2.5mΩ | J2: 5386E01113G700和5386E01113G700 | K2: 未体现 | M2: 搭接线长度：200mm，搭接线孔径：⌀4mm
A3: ATA24 电源系统 | B3: E 270V电池（含BMS） | C3: 2430E01000G200 | D3: 2431E01001G900 | E3: 下机身前段-前设备舱 | F3: 1 | G3: 线搭接 | H3: 双线制 R H S类，壳体搭接； | I3: 2.5mΩ | J3: 5386E01467G700 | K3: 未体现 | M3: 搭接线长度：200mm，搭接线孔径：⌀4mm
A4: ATA24 电源系统 | B4: 应急28电池（含BMS） | C4: 2430E01000G200 | D4: 2432E01001G900 | E4: 下机身前段-前设备舱 | F4: 1 | G4: 线搭接 | H4: 双线制 R H S类，壳体搭接； | I4: 2.5mΩ | J4: 5386E01471G700 | K4: 未体现 | M4: 搭接线长度：450mm，搭接线孔径：⌀4mm
A5: ATA24 电源系统 | B5: 左配电盘箱 | C5: 2460E01000G200 | D5: 2461E01001G900 | E5: 客舱-后设备舱盘箱 | F5: 1 | G5: 线搭接 | H5: C 类 R H S类，壳体搭接； | I5: 2.5mΩ | J5: 5325E03121G700 | K5: 是 | M5: 搭接线长度：200mm，搭接线孔径：⌀4mm
A6: ATA24 电源系统 | B6: 右配电盘箱 | C6: 2460E01000G200 | D6: 2461E01003G900 | E6: 客舱-后设备舱盘箱 | F6: 1 | G6: 线搭接 | H6: C 类 R H S类，壳体搭接； | I6: 2.5mΩ | J6: 5325E03122G700 | K6: 是 | M6: 搭接线长度：200mm，搭接线孔径：⌀4mm
A7: ATA24 电源系统 | B7: 应急配电盘箱 | C7: 2460E01000G200 | D7: 2461E01005G900 | E7: 驾驶舱-右设备架 | F7: 1 | G7: 线搭接 | H7: C 类 R H S类，壳体搭接； | I7: 2.5mΩ | J7: 5325E02209G700 | K7: 是 | M7: 搭接线长度：200mm，搭接线孔径：⌀4mm
A8: ATA24 电源系统 | B8: L270/28V DCDC | C8: 2460E01000G200 | D8: 2463E01003G900 | E8: 客舱-后设备舱盘箱 | F8: 1 | G8: 线搭接 | H8: 双线制 R H S类，壳体搭接； | I8: 2.5mΩ | J8: 5325E03123G700 | K8: 是 | M8: 搭接线长度：200mm，搭接线孔径：⌀4mm
A9: ATA24 电源系统 | B9: R270/28V DCDC | C9: 2460E01000G200 | D9: 2463E01003G900 | E9: 客舱-后设备舱盘箱 | F9: 1 | G9: 线搭接 | H9: 双线制 R H S类，壳体搭接； | I9: 2.5mΩ | J9: 5325E03124G700 | K9: 是 | M9: 搭接线长度：200mm，搭接线孔径：⌀4mm
A10: ATA24 电源系统 | B10: E270/28V DCDC | C10: 2460E01000G200 | D10: 2463E01005G900 | E10: 驾驶舱-右设备架 | F10: 1 | G10: 线搭接 | H10: 双线制 R H S类，壳体搭接； | I10: 2.5mΩ | J10: 5325E02233G700 | K10: 是 | M10: 搭接线长度：200mm，搭接线孔径：⌀4mm
A11: ATA24 电源系统 | B11: 远程配电装置 RPDU1 | C11: 2460E01000G200 | D11: 2462E01001G900 | E11: 下机身前段-前设备舱 | F11: 1 | G11: 线搭接 | H11: C 类 R H S类，壳体搭接； | I11: 2.5mΩ | J11: 5386E01429G700 | K11: 是 | M11: 搭接线长度：200mm，搭接线孔径：⌀4mm
A12: ATA24 电源系统 | B12: 远程配电装置 RPDU2 | C12: 2460E01000G200 | D12: 2462E01001G900 | E12: 下机身前段-前设备舱 | F12: 1 | G12: 线搭接 | H12: C 类 R H S类，壳体搭接； | I12: 2.5mΩ | J12: 5386E01429G700 | K12: 是 | M12: 搭接线长度：200mm，搭接线孔径：⌀4mm
A13: ATA24 电源系统 | B13: 远程配电装置 RPDU3 | C13: 2460E01000G200 | D13: 2462E01001G900 | E13: 客舱-后设备舱盘箱 | F13: 1 | G13: 线搭接 | H13: C 类 R H S类，壳体搭接； | I13: 2.5mΩ | J13: 5325E03113G700 | K13: 是 | M13: 搭接线长度：200mm，搭接线孔径：⌀4mm
... A16: ATA24 电源系统 | B16: 高压PDU2 | C16: 非总装团队工作 | D16: 2464E01001G900 | E16: 机翼-机翼外段 | F16: 1 | G16: 线搭接 | H16: C 类 R H S类，壳体搭接； | I16: 2.5mΩ | J16: 5714E03037G700 | K16: 是 | M16: 搭接线长度：200mm，搭接线孔径：⌀4mm
A17: ATA24 电源系统 | B17: 外电源插座 | C17: 非总装团队工作 | D17: 2442E01001G900 | E17: 下机身前段-前设备舱 | F17: 1 | G17: 无需求 | H17: 无需求 | I17: 无 | J17: 无 | K17: 未体现
A18: ATA24 电源系统 | B18: 充电面板 | C18: 非总装团队工作 | D18: 2442E01003G900 | E18: 下机身前段-前设备舱 | F18: 1 | G18: 无需求 | H18: 无需求 | I18: 无 | J18: 无 | K18: 未体现
A19: ATA86 电推进系统 | B19: 电驱系统1 | C19: 8611E01001G200 | D19: 8611E01001G900 | E19: 短舱-1号短舱（机翼内侧） | F19: 1 | G19: 线搭接 | H19: C类，28V负极在ERN回流； L类，壳体搭接； | I19: 2.5mΩ | K19: 已签协调单+打孔
A20: ATA86 电推进系统 | B20: 电驱系统2 | C20: 8611E01001G200 | D20: 8611E01001G900 | E20: 短舱-2号短舱 | F20: 1 | G20: 线搭接 | H20: C类，28V负极在机身部分通过ERN回流； R类、H类、S类，壳体搭接 | I20: 2.5mΩ | K20: 已签协调单+打孔
A21: ATA86 电推进系统 | B21: 电驱系统3 | C21: 8611E01001G200 | D21: 8611E01001G900 | E21: 短舱-3号短舱 | F21: 1 | G21: 线搭接 | H21: C类，28V负极在机身部分通过ERN回流； R类、H类、S类，壳体搭接 | I21: 2.5mΩ | K21: 已签协调单+打孔
A22: ATA86 电推进系统 | B22: 电驱系统4 | C22: 8611E01001G200 | D22: 8611E01001G900 | E22: 短舱-4号短舱 | F22: 1 | G22: 线搭接 | H22: C类，28V负极在机身部分通过ERN回流； R类、H类、S类，壳体搭接 | I22: 2.5mΩ | K22: 已签协调单+打孔
A23: ATA86 电推进系统 | B23: 电驱系统5 | C23: 8611E01001G200 | D23: 8611E01001G900 | E23: 短舱-5号短舱（机翼外侧） | F23: 1 | G23: 线搭接 | H23: C类，28V负极在机身部分通过ERN回流； R类、H类、S类，壳体搭接 | I23: 2.5mΩ | K23: 已签协调单+打孔
A24: ATA86 电推进系统 | B24: 电驱系统6 | C24: 8611E01001G200 | D24: 8611E01001G900 | E24: 短舱-1号短舱（机翼内侧） | F24: 1 | G24: 线搭接 | H24: C类，28V负极在机身部分通过ERN回流； R类、H类、S类，壳体搭接 | I24: 2.5mΩ | K24: 已签协调单+打孔
A25: ATA86 电推进系统 | B25: 电驱系统7 | C25: 8611E01001G200 | D25: 8611E01001G900 | E25: 短舱-2号短舱 | F25: 1 | G25: 线搭接 | H25: C类，28V负极在机身部分通过ERN回流； R类、H类、S类，壳体搭接 | I25: 2.5mΩ | K25: 已签协调单+打孔
A26: ATA86 电推进系统 | B26: 电驱系统8 | C26: 8611E01001G200 | D26: 8611E01001G900 | E26: 短舱-3号短舱 | F26: 1 | G26: 线搭接 | H26: C类，28V负极在机身部分通过ERN回流； R类、H类、S类，壳体搭接 | I26: 2.5mΩ | K26: 已签协调单+打孔
A27: ATA86 电推进系统 | B27: 电驱系统9 | C27: 8611E01001G200 | D27: 8611E01001G900 | E27: 短舱-4号短舱 | F27: 1 | G27: 线搭接 | H27: C类，28V负极在机身部分通过ERN回流； R类、H类、S类，壳体搭接 | I27: 2.5mΩ | K27: 已签协调单+打孔
A28: ATA86 电推进系统 | B28: 电驱系统10 | C28: 8611E01001G200 | D28: 8611E01001G900 | E28: 短舱-5号短舱（机翼外侧） | F28: 1 | G28: 线搭接 | H28: C类，28V负极在机身部分通过ERN回流； R类、H类、S类，壳体搭接 | I28: 2.5mΩ | K28: 已签协调单+打孔
A29: ATA86 电推进系统 | B29: 构型B动力电池（含BMS与继电器开关）1 | C29: 8621E01000G200 | D29: 8621E01001G900 | E29: 下机身前段-1号动力电池舱 | F29: 1 | G29: 面搭接 | H29: 双线制 R H S类，壳体搭接； | I29: 2.5mΩ | K29: 未体现
A30: ATA86 电推进系统 | B30: 构型B动力电池（含BMS与继电器开关）2 | C30: 8621E01000G200 | D30: 8621E01001G900 | E30: 下机身前段-2号动力电池舱 | F30: 1 | G30: 面搭接 | H30: 双线制 R H S类，壳体搭接； | I30: 2.5mΩ | K30: 未体现
... A45: ATA87 通用机载测试系统 | B45: 采集机箱2 | C45: 图号未确定 | D45: 8712E01111T900 | E45: 客舱-地板上 | F45: 1 | G45: 线搭接 | H45: S类，壳体搭接 | I45: ≤2.5mΩ | K45: 是
A46: ATA87 通用机载测试系统 | B46: 机载数据交换机 | C46: 图号未确定 | D46: 8711E00511T900 | E46: 客舱-地板上 | F46: 1 | G46: 无需接地 | H46: NA | I46: NA | J46: NA
A47: ATA87 通用机载测试系统 | B47: 通用记录器 | C47: 图号未确定 | D47: 8713E00411T900 | E47: 客舱-地板上 | F47: 1 | G47: 线搭接 | H47: S类，壳体搭接 | I47: ≤2.5mΩ | K47: 是
A48: ATA87 通用机载测试系统 | B48: 直流稳压器 | C48: 图号未确定 | D48: 8781E00113T900 | E48: 客舱-地板上 | F48: 1 | G48: 无需接地 | H48: NA | I48: NA | J48: NA
A49: ATA87 通用机载测试系统 | B49: 蓄电池组 | C49: 图号未确定 | D49: 8781E00312T900 | E49: 客舱-地板上 | F49: 1 | G49: 线搭接 | H49: C类，28V负极在机身部分通过ERN回流； | I49: ≤2.5mΩ | K49: 是
A50: ATA87 通用机载测试系统 | B50: 机载GNSS天线 | C50: 图号未确定 | D50: 8711E00121T900 | E50: 客舱-地板上 | F50: 1 | G50: 无需接地 | H50: NA | I50: NA | J50: NA
A51: ATA34 导航系统 | B51: VHF天线1 | C51: 3451E02000G200 | D51: 3451E02001G900 | E51: 客舱-外部 | F51: 1 | G51: 面搭接 | H51: A类 | I51: 10mΩ | J51: 图纸中参考结构安装面 | K51: 是
A52: ATA34 导航系统 | B52: VHF天线2 | C52: 3451E02000G200 | D52: 3451E02001G900 | E52: 下机身前段-外部 | F52: 0 | G52: 面搭接 | H52: A类 | I52: 10mΩ | J52: 图纸中参考结构安装面 | K52: 是
A53: ATA34 导航系统 | B53: VHF天线3 | C53: 3451E02000G200 | D53: 3451E02001G900 | E53: 客舱-外部 | F53: 1 | G53: 面搭接 | H53: A类 | I53: 10mΩ | J53: 图纸中参考结构安装面 | K53: 是
A54: ATA23 通信系统 | B54: 5G ATG机载CPE | C54: 2393E01000G200 | D54: 2393E01001G900 | E54: 客舱-后设备舱右设备架 | F54: 0 | G54: 面搭接 | H54: R类 | I54: 2.5mΩ | J54: 图纸中参考结构安装面 | K54: 是
A55: ATA23 通信系统 | B55: 功率放大器 | C55: 2393E01000U200 | D55: 2393E01001U900 | E55: 客舱-地板上 | F55: 0 | G55: 线搭接 | H55: R类 | I55: 2.5mΩ | K55: 否 | M55: 搭接线长度：200mm，搭接线孔径：⌀5.6mm
A56: ATA23 通信系统 | B56: 5G ATG全向天线 | C56: 2393E01000U200 | D56: 2393E01003U900 | E56: 下机身前段-外部 | F56: 0 | G56: 面搭接 | H56: A类 | I56: 2.5mΩ | J56: 图纸中参考结构安装面 | K56: 是
...

Sheet 注意事项&统计
A1: 筛选【请勿】对所有人可见
A2: 显示不全请先【取消】筛选
A3: 标绿色设备为原先0号机首飞构型
A4: 安装方式下拉选择，选择托架需填写sheet3托架信息表
A6: 系统章节 | B6: 统计 | C6: 和原全构型对比 | E6: 系统章节 | F6: 统计 | G6: 和原全构型对比 | I6: 系统章节 | J6: 统计
A7: EATA11 标牌与标识 | B7: =COUNTIFS('1&2号构型'!A:A,A7) -> 0 | C7: =B7-J7 -> -1 | E7: EATA11 标牌与标识 | F7: =COUNTIFS(X号构型!A:A,A7) -> 1 | G7: =F7-J7 -> 0 | I7: EATA11 标牌与标识 | J7: 1
A8: EATA21 空调系统 | B8: =COUNTIFS('1&2号构型'!A:A,A8) -> 0 | C8: =B8-J8 -> -54 | E8: EATA21 空调系统 | F8: =COUNTIFS(X号构型!A:A,A8) -> 58 | G8: =F8-J8 -> 4 | I8: EATA21 空调系统 | J8: 54
A9: EATA23 通信系统 | B9: =COUNTIFS('1&2号构型'!A:A,A9) -> 31 | C9: =B9-J9 -> 0 | E9: EATA23 通信系统 | F9: =COUNTIFS(X号构型!A:A,A9) -> 29 | G9: =F9-J9 -> -2 | I9: EATA23 通信系统 | J9: 31
A10: EATA24 电源系统 | B10: =COUNTIFS('1&2号构型'!A:A,A10) -> 14 | C10: =B10-J10 -> -1 | E10: EATA24 电源系统 | F10: =COUNTIFS(X号构型!A:A,A10) -> 15 | G10: =F10-J10 -> 0 | I10: EATA24 电源系统 | J10: 15
A11: EATA25 设备/装饰 | B11: =COUNTIFS('1&2号构型'!A:A,A11) -> 23 | C11: =B11-J11 -> 0 | E11: EATA25 设备/装饰 | F11: =COUNTIFS(X号构型!A:A,A11) -> 23 | G11: =F11-J11 -> 0 | I11: EATA25 设备/装饰 | J11: 23
A12: EATA26 防火 | B12: =COUNTIFS('1&2号构型'!A:A,A12) -> 10 | C12: =B12-J12 -> -1 | E12: EATA26 防火 | F12: =COUNTIFS(X号构型!A:A,A12) -> 12 | G12: =F12-J12 -> 1 | I12: EATA26 防火 | J12: 11
A13: EATA27 飞行控制系统 | B13: =COUNTIFS('1&2号构型'!A:A,A13) -> 40 | C13: =B13-J13 -> 0 | E13: EATA27 飞行控制系统 | F13: =COUNTIFS(X号构型!A:A,A13) -> 38 | G13: =F13-J13 -> -2 | I13: EATA27 飞行控制系统 | J13: 40
A14: EATA30 防除冰和除雨 | B14: =COUNTIFS('1&2号构型'!A:A,A14) -> 14 | C14: =B14-J14 -> -4 | E14: EATA30 防除冰和除雨 | F14: =COUNTIFS(X号构型!A:A,A14) -> 15 | G14: =F14-J14 -> -3 | I14: EATA30 防除冰和除雨 | J14: 18
A15: EATA31 指示记录系统 | B15: =COUNTIFS('1&2号构型'!A:A,A15) -> 6 | C15: =B15-J15 -> 0 | E15: EATA31 指示记录系统 | F15: =COUNTIFS(X号构型!A:A,A15) -> 6 | G15: =F15-J15 -> 0 | I15: EATA31 指示记录系统 | J15: 6
A16: EATA32 起落架系统 | B16: =COUNTIFS('1&2号构型'!A:A,A16) -> 98 | C16: =B16-J16 -> 0 | E16: EATA32 起落架系统 | F16: =COUNTIFS(X号构型!A:A,A16) -> 98 | G16: =F16-J16 -> 0 | I16: EATA32 起落架系统 | J16: 98
A17: EATA33 照明系统 | B17: =COUNTIFS('1&2号构型'!A:A,A17) -> 33 | C17: =B17-J17 -> -58 | E17: EATA33 照明系统 | F17: =COUNTIFS(X号构型!A:A,A17) -> 85 | G17: =F17-J17 -> -6 | I17: EATA33 照明系统 | J17: 91
A18: EATA34 导航系统 | B18: =COUNTIFS('1&2号构型'!A:A,A18) -> 59 | C18: =B18-J18 -> -3 | E18: EATA34 导航系统 | F18: =COUNTIFS(X号构型!A:A,A18) -> 56 | G18: =F18-J18 -> -6 | I18: EATA34 导航系统 | J18: 62
... A29: EATA92 地面网联系统 | B29: =COUNTIFS('1&2号构型'!A:A,A29) -> 6 | C29: =B29-J29 -> 0 | E29: EATA92 地面网联系统 | F29: =COUNTIFS(X号构型!A:A,A29) -> 0 | G29: =F29-J29 -> -6 | I29: EATA92 地面网联系统 | J29: 6
A31: 1+2号总数 | B31: =SUM(B7:B29) -> 439 | E31: X号总数 | F31: =SUM(F7:F29) -> 558 | I31: 原全构型数量仅作对比用 | J31: 607
A32: 0331讨论后更改 | E32: 0330讨论后更改
E33: 0401收集意见
E34: 0403系统反馈
E35: 0410系统反馈
E36: 0415-EICD反馈

Sheet 已删除设备
A1: 系统章节 | B1: 设备名称 | C1: 设备编号 | D1: LIN号
A2: EATA21 空调系统 | B2: 通风系统上机件控制器A | C2: 2180E01001U900 | D2: 2102U3505
A3: EATA21 空调系统 | B3: 通风系统上机件控制器B | C3: 2180E01001U900 | D3: 2102U3503
A4: EATA24 电源系统 | B4: 高压PDU1 | C4: 2464E01001G900 | D4: 2402U6201
A5: EATA24 电源系统 | B5: 高压PDU2 | C5: 2464E01001G900 | D5: 2402U6203
A6: EATA25 设备/装饰 | B6: 电源加装件 | C6: 2519E05001U900 | D6: 2501S4901
A7: EATA33 照明系统 | B7: 外部照明控制盒
A8: EATA34 导航系统 | B8: 应答机 | C8: 3454E01001U900 | D8: 3401U2503
A9: EATA34 导航系统 | B9: 应答机上天线 | C9: 3454E01003U900 | D9: 3402A3905
A10: EATA34 导航系统 | B10: 应答机下天线 | C10: 3454E01003U900 | D10: 3402A4901
A12: 列在该sheet中的设备都已从清单删除
A14: 1/2号构型 | B14: 标识标牌TBD | C14: 可以先删除这行，后续系统反馈后，如有再加 | E14: X号构型 | F14: 功率放大器 | G14: 确认删除
A15: 1/2号构型 | B15: 外电源插座 | C15: 考虑和充电面板合并 | E15: X号构型 | F15: 电源转换模块 | G15: 确认删除
A16: 1/2号构型 | B16: 充电面板 | C16: 考虑和充电面板合并 | E16: X号构型 | F16: 飞控数据记录器1 | G16: 确认删除
A17: 1/2号构型 | B17: 盥洗室烟雾探测器 | C17: 盥洗室未上 | E17: X号构型 | F17: 飞控数据记录器2 | G17: 确认删除
A18: 1/2号构型 | B18: 盥洗室灭火瓶 | C18: 盥洗室未上 | E18: X号构型 | F18: 风挡清洗罐 | G18: 确认删除
A19: 1/2号构型 | B19: 风挡清洗罐 | C19: 确认删除 | E19: X号构型 | F19: 喷嘴1 | G19: ZHT建议删除，结构不需要设计喷嘴开孔
A20: 1/2号构型 | B20: 喷嘴1 | C20: ZHT建议删除 | E20: X号构型 | F20: 喷嘴2 | G20: ZHT建议删除，结构不需要设计喷嘴开孔
A21: 1/2号构型 | B21: 主风挡玻璃及其加热模块组件 | C21: 已与汲总确认，删除本设备 | E21: X号构型 | F21: 标准空速管 | G21: 确认删除
A22: 1/2号构型 | B22: 标准空速管 | C22: 考虑删除 | E22: X号构型 | F22: 标准大气校准数据计算机 | G22: 确认删除
A23: 1/2号构型 | B23: 标准大气校准数据计算机 | C23: 考虑删除 | E23: X号构型 | F23: GNSS射频功分器1 | G23: 确认删除，原先保留1，按系统反馈保留2
A24: 1/2号构型 | B24: 北斗卫星导航接收机 | C24: 建议删除（需与系统讨论后确认） | E24: X号构型 | F24: RTK机载接收机1 | G24: 确认删除
A25: 1/2号构型 | B25: 结构健康监测设备 | C25: 建议删除（需与系统讨论后确认） | E25: X号构型 | F25: RTK机载接收机2 | G25: 确认删除
... A44: 1/2号构型 | B44: 驾驶舱机组无线通信单元 | C44: 建议删除（需与系统讨论后确认） | E44: X号构型 | F44: 结构健康监测光纤传感器16 | G44: 确认删除
E45: X号构型 | F45: 视频服务单元2 | G45: 视频服务单元1和2合并
E46: X号构型 | F46: 驾驶舱摄像头 | G46: 建议删除
E47: X号构型 | F47: U波段数据链收发组合 | G47: 确认删除
E48: X号构型 | F48: 数据链机腹全向天线 | G48: 确认删除
E49: X号构型 | F49: 数据链机背全向天线 | G49: 确认删除
E50: X号构型 | F50: C波段数据链收发组合 | G50: 确认删除
E51: X号构型 | F51: C波段数据链定向天线 | G51: 确认删除
E52: X号构型 | F52: 空地数据管理计算机 | G52: 确认删除
E53: X号构型 | F53: 构型A动力电池冷却系统 | G53: 0403-X机改B构型电池
E54: X号构型 | F54: 左白光防撞灯 | G54: 0410反馈删除
E55: X号构型 | F55: 右白光防撞灯 | G55: 0410反馈删除
E56: X号构型 | F56: TAWS | G56: 0415反馈删除
... E60: X号构型 | F60: 右探冰灯 | G60: 0415反馈删除

Sheet 校验
A1: 段名称 | B1: 节-段名称 | C1: 节段编号 | F1: 设备名称 | G1: LIN号位置校验 | H1: LIN号位数校验 | I1: DM号ATA校验 | J1: DM号位数校验 | K1: DM号层级
A2: 雷达舱 | B2: 机头-雷达舱 | C2: 11 | F2: ='1&2号构型'!#REF! -> #REF! | G2: =VLOOKUP('1&2号构型'!#REF!,B:C,2,0)=VALUE(MID('1&2号构型'!#REF!,6,2)) -> #REF! | H2: =IF(LEN('1&2号构型'!#REF!)=9,"TRUE","FALSE") -> #REF! | I2: =VALUE(MID('1&2号构型'!#REF!,1,2))=VALUE(MID('1&2号构型'!#REF!,5,2)) -> #REF! | J2: =IF(LEN('1&2号构型'!#REF!)=14,"TRUE","FALSE") -> #REF! | K2: =RIGHT('1&2号构型'!#REF!,4) -> #REF!
A3: 前起落架舱 | B3: 机头-前起落架舱 | C3: 12 | F3: ='1&2号构型'!#REF! -> #REF! | G3: =VLOOKUP('1&2号构型'!#REF!,B:C,2,0)=VALUE(MID('1&2号构型'!#REF!,6,2)) -> #REF! | H3: =IF(LEN('1&2号构型'!#REF!)=9,"TRUE","FALSE") -> #REF! | I3: =VALUE(MID('1&2号构型'!#REF!,1,2))=VALUE(MID('1&2号构型'!#REF!,5,2)) -> #REF! | J3: =IF(LEN('1&2号构型'!#REF!)=14,"TRUE","FALSE") -> #REF! | K3: =RIGHT('1&2号构型'!#REF!,4) -> #REF!
A4: 前附件舱 | B4: 机头-前附件舱 | C4: 13 | F4: ='1&2号构型'!#REF! -> #REF! | G4: =VLOOKUP('1&2号构型'!#REF!,B:C,2,0)=VALUE(MID('1&2号构型'!#REF!,6,2)) -> #REF! | H4: =IF(LEN('1&2号构型'!#REF!)=9,"TRUE","FALSE") -> #REF! | I4: =VALUE(MID('1&2号构型'!#REF!,1,2))=VALUE(MID('1&2号构型'!#REF!,5,2)) -> #REF! | J4: =IF(LEN('1&2号构型'!#REF!)=14,"TRUE","FALSE") -> #REF! | K4: =RIGHT('1&2号构型'!#REF!,4) -> #REF!
A5: 外部 | B5: 机头-外部 | C5: 19 | F5: ='1&2号构型'!#REF! -> #REF! | G5: =VLOOKUP('1&2号构型'!#REF!,B:C,2,0)=VALUE(MID('1&2号构型'!#REF!,6,2)) -> #REF! | H5: =IF(LEN('1&2号构型'!#REF!)=9,"TRUE","FALSE") -> #REF! | I5: =VALUE(MID('1&2号构型'!#REF!,1,2))=VALUE(MID('1&2号构型'!#REF!,5,2)) -> #REF! | J5: =IF(LEN('1&2号构型'!#REF!)=14,"TRUE","FALSE") -> #REF! | K5: =RIGHT('1&2号构型'!#REF!,4) -> #REF!
A6: 顶部 | B6: 驾驶舱-顶部 | C6: 21 | F6: ='1&2号构型'!#REF! -> #REF! | G6: =VLOOKUP('1&2号构型'!#REF!,B:C,2,0)=VALUE(MID('1&2号构型'!#REF!,6,2)) -> #REF! | H6: =IF(LEN('1&2号构型'!#REF!)=9,"TRUE","FALSE") -> #REF! | I6: =VALUE(MID('1&2号构型'!#REF!,1,2))=VALUE(MID('1&2号构型'!#REF!,5,2)) -> #REF! | J6: =IF(LEN('1&2号构型'!#REF!)=14,"TRUE","FALSE") -> #REF! | K6: =RIGHT('1&2号构型'!#REF!,4) -> #REF!
A7: 地板上 | B7: 驾驶舱-地板上 | C7: 22 | F7: ='1&2号构型'!#REF! -> #REF! | G7: =VLOOKUP('1&2号构型'!#REF!,B:C,2,0)=VALUE(MID('1&2号构型'!#REF!,6,2)) -> #REF! | H7: =IF(LEN('1&2号构型'!#REF!)=9,"TRUE","FALSE") -> #REF! | I7: =VALUE(MID('1&2号构型'!#REF!,1,2))=VALUE(MID('1&2号构型'!#REF!,5,2)) -> #REF! | J7: =IF(LEN('1&2号构型'!#REF!)=14,"TRUE","FALSE") -> #REF! | K7: =RIGHT('1&2号构型'!#REF!,4) -> #REF!
A8: 地板下 | B8: 驾驶舱-地板下 | C8: 23 | F8: ='1&2号构型'!#REF! -> #REF! | G8: =VLOOKUP('1&2号构型'!#REF!,B:C,2,0)=VALUE(MID('1&2号构型'!#REF!,6,2)) -> #REF! | H8: =IF(LEN('1&2号构型'!#REF!)=9,"TRUE","FALSE") -> #REF! | I8: =VALUE(MID('1&2号构型'!#REF!,1,2))=VALUE(MID('1&2号构型'!#REF!,5,2)) -> #REF! | J8: =IF(LEN('1&2号构型'!#REF!)=14,"TRUE","FALSE") -> #REF! | K8: =RIGHT('1&2号构型'!#REF!,4) -> #REF!
A9: 控制面板 | B9: 驾驶舱-控制面板 | C9: 24 | F9: ='1&2号构型'!#REF! -> #REF! | G9: =VLOOKUP('1&2号构型'!#REF!,B:C,2,0)=VALUE(MID('1&2号构型'!#REF!,6,2)) -> #REF! | H9: =IF(LEN('1&2号构型'!#REF!)=9,"TRUE","FALSE") -> #REF! | I9: =VALUE(MID('1&2号构型'!#REF!,1,2))=VALUE(MID('1&2号构型'!#REF!,5,2)) -> #REF! | J9: =IF(LEN('1&2号构型'!#REF!)=14,"TRUE","FALSE") -> #REF! | K9: =RIGHT('1&2号构型'!#REF!,4) -> #REF!
A10: 左设备架 | B10: 驾驶舱-左设备架 | C10: 25 | F10: ='1&2号构型'!#REF! -> #REF! | G10: =VLOOKUP('1&2号构型'!#REF!,B:C,2,0)=VALUE(MID('1&2号构型'!#REF!,6,2)) -> #REF! | H10: =IF(LEN('1&2号构型'!#REF!)=9,"TRUE","FALSE") -> #REF! | I10: =VALUE(MID('1&2号构型'!#REF!,1,2))=VALUE(MID('1&2号构型'!#REF!,5,2)) -> #REF! | J10: =IF(LEN('1&2号构型'!#REF!)=14,"TRUE","FALSE") -> #REF! | K10: =RIGHT('1&2号构型'!#REF!,4) -> #REF!
A11: 右设备架 | B11: 驾驶舱-右设备架 | C11: 26 | F11: ='1&2号构型'!#REF! -> #REF! | G11: =VLOOKUP('1&2号构型'!#REF!,B:C,2,0)=VALUE(MID('1&2号构型'!#REF!,6,2)) -> #REF! | H11: =IF(LEN('1&2号构型'!#REF!)=9,"TRUE","FALSE") -> #REF! | I11: =VALUE(MID('1&2号构型'!#REF!,1,2))=VALUE(MID('1&2号构型'!#REF!,5,2)) -> #REF! | J11: =IF(LEN('1&2号构型'!#REF!)=14,"TRUE","FALSE") -> #REF! | K11: =RIGHT('1&2号构型'!#REF!,4) -> #REF!
A12: 外部 | B12: 驾驶舱-外部 | C12: 29 | F12: ='1&2号构型'!#REF! -> #REF! | G12: =VLOOKUP('1&2号构型'!#REF!,B:C,2,0)=VALUE(MID('1&2号构型'!#REF!,6,2)) -> #REF! | H12: =IF(LEN('1&2号构型'!#REF!)=9,"TRUE","FALSE") -> #REF! | I12: =VALUE(MID('1&2号构型'!#REF!,1,2))=VALUE(MID('1&2号构型'!#REF!,5,2)) -> #REF! | J12: =IF(LEN('1&2号构型'!#REF!)=14,"TRUE","FALSE") -> #REF! | K12: =RIGHT('1&2号构型'!#REF!,4) -> #REF!
A13: 顶部 | B13: 客舱-顶部 | C13: 31 | F13: ='1&2号构型'!#REF! -> #REF! | G13: =VLOOKUP('1&2号构型'!#REF!,B:C,2,0)=VALUE(MID('1&2号构型'!#REF!,6,2)) -> #REF! | H13: =IF(LEN('1&2号构型'!#REF!)=9,"TRUE","FALSE") -> #REF! | I13: =VALUE(MID('1&2号构型'!#REF!,1,2))=VALUE(MID('1&2号构型'!#REF!,5,2)) -> #REF! | J13: =IF(LEN('1&2号构型'!#REF!)=14,"TRUE","FALSE") -> #REF! | K13: =RIGHT('1&2号构型'!#REF!,4) -> #REF!
... A46: 外部 | B46: 尾段-外部 | C46: 89 | F46: ='1&2号构型'!#REF! -> #REF! | G46: =VLOOKUP('1&2号构型'!#REF!,B:C,2,0)=VALUE(MID('1&2号构型'!#REF!,6,2)) -> #REF! | H46: =IF(LEN('1&2号构型'!#REF!)=9,"TRUE","FALSE") -> #REF! | I46: =VALUE(MID('1&2号构型'!#REF!,1,2))=VALUE(MID('1&2号构型'!#REF!,5,2)) -> #REF! | J46: =IF(LEN('1&2号构型'!#REF!)=14,"TRUE","FALSE") -> #REF! | K46: =RIGHT('1&2号构型'!#REF!,4) -> #REF!
F47: ='1&2号构型'!#REF! -> #REF! | G47: =VLOOKUP('1&2号构型'!#REF!,B:C,2,0)=VALUE(MID('1&2号构型'!#REF!,6,2)) -> #REF! | H47: =IF(LEN('1&2号构型'!#REF!)=9,"TRUE","FALSE") -> #REF! | I47: =VALUE(MID('1&2号构型'!#REF!,1,2))=VALUE(MID('1&2号构型'!#REF!,5,2)) -> #REF! | J47: =IF(LEN('1&2号构型'!#REF!)=14,"TRUE","FALSE") -> #REF! | K47: =RIGHT('1&2号构型'!#REF!,4) -> #REF!
F48: ='1&2号构型'!#REF! -> #REF! | G48: =VLOOKUP('1&2号构型'!#REF!,B:C,2,0)=VALUE(MID('1&2号构型'!#REF!,6,2)) -> #REF! | H48: =IF(LEN('1&2号构型'!#REF!)=9,"TRUE","FALSE") -> #REF! | I48: =VALUE(MID('1&2号构型'!#REF!,1,2))=VALUE(MID('1&2号构型'!#REF!,5,2)) -> #REF! | J48: =IF(LEN('1&2号构型'!#REF!)=14,"TRUE","FALSE") -> #REF! | K48: =RIGHT('1&2号构型'!#REF!,4) -> #REF!
F49: ='1&2号构型'!#REF! -> #REF! | G49: =VLOOKUP('1&2号构型'!#REF!,B:C,2,0)=VALUE(MID('1&2号构型'!#REF!,6,2)) -> #REF! | H49: =IF(LEN('1&2号构型'!#REF!)=9,"TRUE","FALSE") -> #REF! | I49: =VALUE(MID('1&2号构型'!#REF!,1,2))=VALUE(MID('1&2号构型'!#REF!,5,2)) -> #REF! | J49: =IF(LEN('1&2号构型'!#REF!)=14,"TRUE","FALSE") -> #REF! | K49: =RIGHT('1&2号构型'!#REF!,4) -> #REF!
F50: ='1&2号构型'!#REF! -> #REF! | G50: =VLOOKUP('1&2号构型'!#REF!,B:C,2,0)=VALUE(MID('1&2号构型'!#REF!,6,2)) -> #REF! | H50: =IF(LEN('1&2号构型'!#REF!)=9,"TRUE","FALSE") -> #REF! | I50: =VALUE(MID('1&2号构型'!#REF!,1,2))=VALUE(MID('1&2号构型'!#REF!,5,2)) -> #REF! | J50: =IF(LEN('1&2号构型'!#REF!)=14,"TRUE","FALSE") -> #REF! | K50: =RIGHT('1&2号构型'!#REF!,4) -> #REF!
F51: ='1&2号构型'!#REF! -> #REF! | G51: =VLOOKUP('1&2号构型'!#REF!,B:C,2,0)=VALUE(MID('1&2号构型'!#REF!,6,2)) -> #REF! | H51: =IF(LEN('1&2号构型'!#REF!)=9,"TRUE","FALSE") -> #REF! | I51: =VALUE(MID('1&2号构型'!#REF!,1,2))=VALUE(MID('1&2号构型'!#REF!,5,2)) -> #REF! | J51: =IF(LEN('1&2号构型'!#REF!)=14,"TRUE","FALSE") -> #REF! | K51: =RIGHT('1&2号构型'!#REF!,4) -> #REF!
F52: ='1&2号构型'!#REF! -> #REF! | G52: =VLOOKUP('1&2号构型'!#REF!,B:C,2,0)=VALUE(MID('1&2号构型'!#REF!,6,2)) -> #REF! | H52: =IF(LEN('1&2号构型'!#REF!)=9,"TRUE","FALSE") -> #REF! | I52: =VALUE(MID('1&2号构型'!#REF!,1,2))=VALUE(MID('1&2号构型'!#REF!,5,2)) -> #REF! | J52: =IF(LEN('1&2号构型'!#REF!)=14,"TRUE","FALSE") -> #REF! | K52: =RIGHT('1&2号构型'!#REF!,4) -> #REF!
F53: ='1&2号构型'!#REF! -> #REF! | G53: =VLOOKUP('1&2号构型'!#REF!,B:C,2,0)=VALUE(MID('1&2号构型'!#REF!,6,2)) -> #REF! | H53: =IF(LEN('1&2号构型'!#REF!)=9,"TRUE","FALSE") -> #REF! | I53: =VALUE(MID('1&2号构型'!#REF!,1,2))=VALUE(MID('1&2号构型'!#REF!,5,2)) -> #REF! | J53: =IF(LEN('1&2号构型'!#REF!)=14,"TRUE","FALSE") -> #REF! | K53: =RIGHT('1&2号构型'!#REF!,4) -> #REF!
F54: ='1&2号构型'!#REF! -> #REF! | G54: =VLOOKUP('1&2号构型'!#REF!,B:C,2,0)=VALUE(MID('1&2号构型'!#REF!,6,2)) -> #REF! | H54: =IF(LEN('1&2号构型'!#REF!)=9,"TRUE","FALSE") -> #REF! | I54: =VALUE(MID('1&2号构型'!#REF!,1,2))=VALUE(MID('1&2号构型'!#REF!,5,2)) -> #REF! | J54: =IF(LEN('1&2号构型'!#REF!)=14,"TRUE","FALSE") -> #REF! | K54: =RIGHT('1&2号构型'!#REF!,4) -> #REF!
F55: ='1&2号构型'!#REF! -> #REF! | G55: =VLOOKUP('1&2号构型'!#REF!,B:C,2,0)=VALUE(MID('1&2号构型'!#REF!,6,2)) -> #REF! | H55: =IF(LEN('1&2号构型'!#REF!)=9,"TRUE","FALSE") -> #REF! | I55: =VALUE(MID('1&2号构型'!#REF!,1,2))=VALUE(MID('1&2号构型'!#REF!,5,2)) -> #REF! | J55: =IF(LEN('1&2号构型'!#REF!)=14,"TRUE","FALSE") -> #REF! | K55: =RIGHT('1&2号构型'!#REF!,4) -> #REF!
F56: ='1&2号构型'!#REF! -> #REF! | G56: =VLOOKUP('1&2号构型'!#REF!,B:C,2,0)=VALUE(MID('1&2号构型'!#REF!,6,2)) -> #REF! | H56: =IF(LEN('1&2号构型'!#REF!)=9,"TRUE","FALSE") -> #REF! | I56: =VALUE(MID('1&2号构型'!#REF!,1,2))=VALUE(MID('1&2号构型'!#REF!,5,2)) -> #REF! | J56: =IF(LEN('1&2号构型'!#REF!)=14,"TRUE","FALSE") -> #REF! | K56: =RIGHT('1&2号构型'!#REF!,4) -> #REF!
F57: ='1&2号构型'!B2 -> ELT发射器 | G57: =VLOOKUP('1&2号构型'!F2,B:C,2,0)=VALUE(MID('1&2号构型'!D2,6,2)) -> TRUE | H57: =IF(LEN('1&2号构型'!D2)=9,"TRUE","FALSE") -> TRUE | I57: =VALUE(MID('1&2号构型'!C2,1,2))=VALUE(MID('1&2号构型'!A2,5,2)) -> TRUE | J57: =IF(LEN('1&2号构型'!C2)=14,"TRUE","FALSE") -> TRUE | K57: =RIGHT('1&2号构型'!C2,4) -> G900
F58: ='1&2号构型'!B3 -> ELT天线 | G58: =VLOOKUP('1&2号构型'!F3,B:C,2,0)=VALUE(MID('1&2号构型'!D3,6,2)) -> TRUE | H58: =IF(LEN('1&2号构型'!D3)=9,"TRUE","FALSE") -> TRUE | I58: =VALUE(MID('1&2号构型'!C3,1,2))=VALUE(MID('1&2号构型'!A3,5,2)) -> TRUE | J58: =IF(LEN('1&2号构型'!C3)=14,"TRUE","FALSE") -> TRUE | K58: =RIGHT('1&2号构型'!C3,4) -> G900
F59: ='1&2号构型'!B4 -> 音频管理单元1 | G59: =VLOOKUP('1&2号构型'!F4,B:C,2,0)=VALUE(MID('1&2号构型'!D4,6,2)) -> TRUE | H59: =IF(LEN('1&2号构型'!D4)=9,"TRUE","FALSE") -> TRUE | I59: =VALUE(MID('1&2号构型'!C4,1,2))=VALUE(MID('1&2号构型'!A4,5,2)) -> TRUE | J59: =IF(LEN('1&2号构型'!C4)=14,"TRUE","FALSE") -> TRUE | K59: =RIGHT('1&2号构型'!C4,4) -> G900
F60: ='1&2号构型'!B5 -> 音频管理单元2 | G60: =VLOOKUP('1&2号构型'!F5,B:C,2,0)=VALUE(MID('1&2号构型'!D5,6,2)) -> TRUE | H60: =IF(LEN('1&2号构型'!D5)=9,"TRUE","FALSE") -> TRUE | I60: =VALUE(MID('1&2号构型'!C5,1,2))=VALUE(MID('1&2号构型'!A5,5,2)) -> TRUE | J60: =IF(LEN('1&2号构型'!C5)=14,"TRUE","FALSE") -> TRUE | K60: =RIGHT('1&2号构型'!C5,4) -> G900
F61: ='1&2号构型'!B6 -> 音频插孔面板1 | G61: =VLOOKUP('1&2号构型'!F6,B:C,2,0)=VALUE(MID('1&2号构型'!D6,6,2)) -> TRUE | H61: =IF(LEN('1&2号构型'!D6)=9,"TRUE","FALSE") -> TRUE | I61: =VALUE(MID('1&2号构型'!C6,1,2))=VALUE(MID('1&2号构型'!A6,5,2)) -> TRUE | J61: =IF(LEN('1&2号构型'!C6)=14,"TRUE","FALSE") -> TRUE | K61: =RIGHT('1&2号构型'!C6,4) -> G900
F62: ='1&2号构型'!B7 -> 音频插孔面板2 | G62: =VLOOKUP('1&2号构型'!F7,B:C,2,0)=VALUE(MID('1&2号构型'!D7,6,2)) -> TRUE | H62: =IF(LEN('1&2号构型'!D7)=9,"TRUE","FALSE") -> TRUE | I62: =VALUE(MID('1&2号构型'!C7,1,2))=VALUE(MID('1&2号构型'!A7,5,2)) -> TRUE | J62: =IF(LEN('1&2号构型'!C7)=14,"TRUE","FALSE") -> TRUE | K62: =RIGHT('1&2号构型'!C7,4) -> G900
F63: ='1&2号构型'!B8 -> 悬臂式耳机1 | G63: =VLOOKUP('1&2号构型'!F8,B:C,2,0)=VALUE(MID('1&2号构型'!D8,6,2)) -> TRUE | H63: =IF(LEN('1&2号构型'!D8)=9,"TRUE","FALSE") -> TRUE | I63: =VALUE(MID('1&2号构型'!C8,1,2))=VALUE(MID('1&2号构型'!A8,5,2)) -> TRUE | J63: =IF(LEN('1&2号构型'!C8)=14,"TRUE","FALSE") -> TRUE | K63: =RIGHT('1&2号构型'!C8,4) -> G900
F64: ='1&2号构型'!B9 -> 悬臂式耳机2 | G64: =VLOOKUP('1&2号构型'!F9,B:C,2,0)=VALUE(MID('1&2号构型'!D9,6,2)) -> TRUE | H64: =IF(LEN('1&2号构型'!D9)=9,"TRUE","FALSE") -> TRUE | I64: =VALUE(MID('1&2号构型'!C9,1,2))=VALUE(MID('1&2号构型'!A9,5,2)) -> TRUE | J64: =IF(LEN('1&2号构型'!C9)=14,"TRUE","FALSE") -> TRUE | K64: =RIGHT('1&2号构型'!C9,4) -> G900
F65: ='1&2号构型'!B10 -> 手持话筒1 | G65: =VLOOKUP('1&2号构型'!F10,B:C,2,0)=VALUE(MID('1&2号构型'!D10,6,2)) -> TRUE | H65: =IF(LEN('1&2号构型'!D10)=9,"TRUE","FALSE") -> TRUE | I65: =VALUE(MID('1&2号构型'!C10,1,2))=VALUE(MID('1&2号构型'!A10,5,2)) -> TRUE | J65: =IF(LEN('1&2号构型'!C10)=14,"TRUE","FALSE") -> TRUE | K65: =RIGHT('1&2号构型'!C10,4) -> G900
F66: ='1&2号构型'!B11 -> 手持话筒2 | G66: =VLOOKUP('1&2号构型'!F11,B:C,2,0)=VALUE(MID('1&2号构型'!D11,6,2)) -> TRUE | H66: =IF(LEN('1&2号构型'!D11)=9,"TRUE","FALSE") -> TRUE | I66: =VALUE(MID('1&2号构型'!C11,1,2))=VALUE(MID('1&2号构型'!A11,5,2)) -> TRUE | J66: =IF(LEN('1&2号构型'!C11)=14,"TRUE","FALSE") -> TRUE | K66: =RIGHT('1&2号构型'!C11,4) -> G900
F67: ='1&2号构型'!B12 -> 扬声器1 | G67: =VLOOKUP('1&2号构型'!F12,B:C,2,0)=VALUE(MID('1&2号构型'!D12,6,2)) -> TRUE | H67: =IF(LEN('1&2号构型'!D12)=9,"TRUE","FALSE") -> TRUE | I67: =VALUE(MID('1&2号构型'!C12,1,2))=VALUE(MID('1&2号构型'!A12,5,2)) -> TRUE | J67: =IF(LEN('1&2号构型'!C12)=14,"TRUE","FALSE") -> TRUE | K67: =RIGHT('1&2号构型'!C12,4) -> G900
F68: ='1&2号构型'!B13 -> 扬声器2 | G68: =VLOOKUP('1&2号构型'!F13,B:C,2,0)=VALUE(MID('1&2号构型'!D13,6,2)) -> TRUE | H68: =IF(LEN('1&2号构型'!D13)=9,"TRUE","FALSE") -> TRUE | I68: =VALUE(MID('1&2号构型'!C13,1,2))=VALUE(MID('1&2号构型'!A13,5,2)) -> TRUE | J68: =IF(LEN('1&2号构型'!C13)=14,"TRUE","FALSE") -> TRUE | K68: =RIGHT('1&2号构型'!C13,4) -> G900
... F87: ='1&2号构型'!B32 -> 电源转换模块 | G87: =VLOOKUP('1&2号构型'!F32,B:C,2,0)=VALUE(MID('1&2号构型'!D32,6,2)) -> FALSE | H87: =IF(LEN('1&2号构型'!D32)=9,"TRUE","FALSE") -> TRUE | I87: =VALUE(MID('1&2号构型'!C32,1,2))=VALUE(MID('1&2号构型'!A32,5,2)) -> TRUE | J87: =IF(LEN('1&2号构型'!C32)=14,"TRUE","FALSE") -> TRUE | K87: =RIGHT('1&2号构型'!C32,4) -> U900
F88: ='1&2号构型'!#REF! -> #REF! | G88: =VLOOKUP('1&2号构型'!#REF!,B:C,2,0)=VALUE(MID('1&2号构型'!#REF!,6,2)) -> #REF! | H88: =IF(LEN('1&2号构型'!#REF!)=9,"TRUE","FALSE") -> #REF! | I88: =VALUE(MID('1&2号构型'!#REF!,1,2))=VALUE(MID('1&2号构型'!#REF!,5,2)) -> #REF! | J88: =IF(LEN('1&2号构型'!#REF!)=14,"TRUE","FALSE") -> #REF! | K88: =RIGHT('1&2号构型'!#REF!,4) -> #REF!
F89: ='1&2号构型'!B33 -> E 270V电池（含BMS） | G89: =VLOOKUP('1&2号构型'!F33,B:C,2,0)=VALUE(MID('1&2号构型'!D33,6,2)) -> TRUE | H89: =IF(LEN('1&2号构型'!D33)=9,"TRUE","FALSE") -> TRUE | I89: =VALUE(MID('1&2号构型'!C33,1,2))=VALUE(MID('1&2号构型'!A33,5,2)) -> TRUE | J89: =IF(LEN('1&2号构型'!C33)=14,"TRUE","FALSE") -> TRUE | K89: =RIGHT('1&2号构型'!C33,4) -> G900
F90: ='1&2号构型'!B34 -> LR 270V电池（含BMS） | G90: =VLOOKUP('1&2号构型'!F34,B:C,2,0)=VALUE(MID('1&2号构型'!D34,6,2)) -> TRUE | H90: =IF(LEN('1&2号构型'!D34)=9,"TRUE","FALSE") -> TRUE | I90: =VALUE(MID('1&2号构型'!C34,1,2))=VALUE(MID('1&2号构型'!A34,5,2)) -> TRUE | J90: =IF(LEN('1&2号构型'!C34)=14,"TRUE","FALSE") -> TRUE | K90: =RIGHT('1&2号构型'!C34,4) -> G900
...
