Workbook

Sheet 系统
A1: 序号 | B1: ATA | C1: 系统名称
A2: 1 | B2: ATA21 | C2: EATA21 空调系统
A3: 2 | B3: ATA23 | C3: EATA23 通信系统
A4: 3 | B4: ATA24 | C4: EATA24 电源系统
A5: 4 | B5: ATA25 | C5: EATA25 设备/装饰
A6: 5 | B6: ATA26 | C6: EATA26 防火
A7: 6 | B7: ATA27 | C7: EATA27 飞行控制系统
A8: 7 | B8: ATA30 | C8: EATA30 防除冰和除雨
A9: 8 | B9: ATA31 | C9: EATA31 指示记录系统
A10: 9 | B10: ATA32 | C10: EATA32 起落架系统
A11: 10 | B11: ATA33 | C11: EATA33 照明系统
A12: 11 | B12: ATA34 | C12: EATA34 导航系统
A13: 12 | B13: ATA35 | C13: EATA35 氧气
... A23: 22 | B23: ATA92 | C23: EATA92 地面网联系统

Sheet 1、2号机设备清单
A1: 序号 | B1: 系统章节 | C1: 设备名称 | D1: 设备编号 | E1: LIN号 | F1: 安装位置 | G1: 是否为用电设备 | H1: 是否为一级用电设备 | I1: 备注
A2: 1 | B2: EATA23 通信系统 | C2: ELT发射器 | D2: 2321E01001G900 | E2: 2301U3101 | F2: 客舱-顶部 | G2: 是 | H2: 是
A3: 2 | B3: EATA23 通信系统 | C3: ELT天线 | D3: 2321E01003G900 | E3: 2301A3901 | F3: 客舱-外部 | G3: 是 | H3: 否
A4: 3 | B4: EATA23 通信系统 | C4: 音频管理单元1 | D4: 2350E01001G900 | E4: 2302U2501 | F4: 驾驶舱-左设备架 | G4: 是 | H4: 是
A5: 4 | B5: EATA23 通信系统 | C5: 音频管理单元2 | D5: 2350E01001G900 | E5: 2302U2603 | F5: 驾驶舱-右设备架 | G5: 是 | H5: 是
A6: 5 | B6: EATA23 通信系统 | C6: 音频插孔面板1 | D6: 2350E02001G900 | E6: 2302D2401 | F6: 驾驶舱-控制面板 | G6: 是 | H6: 否
A7: 6 | B7: EATA23 通信系统 | C7: 音频插孔面板2 | D7: 2350E02001G900 | E7: 2302D2403 | F7: 驾驶舱-控制面板 | G7: 是 | H7: 否
A8: 7 | B8: EATA23 通信系统 | C8: 悬臂式耳机1 | D8: 2350E02003G900 | E8: 2302R2101 | F8: 驾驶舱-顶部 | G8: 否 | H8: 否
A9: 8 | B9: EATA23 通信系统 | C9: 悬臂式耳机2 | D9: 2350E02003G900 | E9: 2302R2103 | F9: 驾驶舱-顶部 | G9: 否 | H9: 否
A10: 9 | B10: EATA23 通信系统 | C10: 手持话筒1 | D10: 2350E02005G900 | E10: 2302D2101 | F10: 驾驶舱-顶部 | G10: 否 | H10: 否
A11: 10 | B11: EATA23 通信系统 | C11: 手持话筒2 | D11: 2350E02005G900 | E11: 2302D2103 | F11: 驾驶舱-顶部 | G11: 否 | H11: 否
A12: 11 | B12: EATA23 通信系统 | C12: 扬声器1 | D12: 2350E02007G900 | E12: 2302E2101 | F12: 驾驶舱-顶部 | G12: 是 | H12: 否
A13: 12 | B13: EATA23 通信系统 | C13: 扬声器2 | D13: 2350E02007G900 | E13: 2302E2103 | F13: 驾驶舱-顶部 | G13: 是 | H13: 否
... A91: 90 | B91: EATA27 飞行控制系统 | C91: 备份飞控计算机 | D91: 2791E01003G900 | E91: 2701U2505 | F91: 驾驶舱-左设备架 | G91: 是 | H91: 是
A92: 91 | B92: EATA27 飞行控制系统 | C92: 飞控数据记录器1 | D92: 2791E02001U900 | E92: 2702U2601 | F92: 驾驶舱-右设备架 | G92: 是 | H92: 是 | I92: 建议将两个飞控数据记录器用同一个电源引脚进行配电
A93: 92 | B93: EATA27 飞行控制系统 | C93: 飞控数据记录器2 | D93: 2791E02001U900 | E93: 2702U3203 | F93: 客舱-地板上 | G93: 是 | H93: 是 | I93: 建议将两个飞控数据记录器用同一个电源引脚进行配电
A94: 93 | B94: EATA27 飞行控制系统 | C94: 马达控制电子1 | D94: 2792E01001G900 | E94: 2704U3601 | F94: 客舱-后设备舱右设备架 | G94: 是 | H94: 是
A95: 94 | B95: EATA27 飞行控制系统 | C95: 马达控制电子2 | D95: 2792E01001G900 | E95: 2704U3603 | F95: 客舱-后设备舱右设备架 | G95: 是 | H95: 是
A96: 95 | B96: EATA27 飞行控制系统 | C96: 马达控制电子3 | D96: 2792E01001G900 | E96: 2704U3505 | F96: 客舱-后设备舱左设备架 | G96: 是 | H96: 是
A97: 96 | B97: EATA27 飞行控制系统 | C97: 马达控制电子4 | D97: 2792E01001G900 | E97: 2704U3507 | F97: 客舱-后设备舱左设备架 | G97: 是 | H97: 是
A98: 97 | B98: EATA27 飞行控制系统 | C98: 马达控制电子5 | D98: 2792E01003G900 | E98: 2702U3609 | F98: 客舱-后设备舱右设备架 | G98: 是 | H98: 是
A99: 98 | B99: EATA27 飞行控制系统 | C99: 马达控制电子6 | D99: 2792E01003G900 | E99: 2702U3511 | F99: 客舱-后设备舱左设备架 | G99: 是 | H99: 是
A100: 99 | B100: EATA27 飞行控制系统 | C100: 马达控制电子7 | D100: 2792E01005G900 | E100: 2702U6101 | F100: 机翼-中央翼盒 | G100: 是 | H100: 是
A101: 100 | B101: EATA27 飞行控制系统 | C101: 马达控制电子8 | D101: 2792E01005G900 | E101: 2702U6103 | F101: 机翼-中央翼盒 | G101: 是 | H101: 是
A102: 101 | B102: EATA27 飞行控制系统 | C102: 位置传感器6 | D102: 2793E01001G900 | E102: 2702U6211 | F102: 机翼-机翼外段 | G102: 是 | H102: 否
A103: 102 | B103: EATA27 飞行控制系统 | C103: 位置传感器1 | D103: 2793E01001G900 | E103: 2702U6201 | F103: 机翼-机翼外段 | G103: 是 | H103: 否
A104: 103 | B104: EATA27 飞行控制系统 | C104: 位置传感器3 | D104: 2793E01003G900 | E104: 2702U6205 | F104: 机翼-机翼外段 | G104: 是 | H104: 否
A105: 104 | B105: EATA27 飞行控制系统 | C105: 位置传感器4 | D105: 2793E01003G900 | E105: 2702U6207 | F105: 机翼-机翼外段 | G105: 是 | H105: 否
... A118: 117 | B118: EATA30 防除冰和除雨 | C118: 风挡雨刷片2 | D118: 3040E02006G900 | E118: 3002X1909 | F118: 机头-外部 | G118: 否 | H118: 否
A119: 118 | B119: EATA30 防除冰和除雨 | C119: 雨量传感器 | D119: 3040E02007G900 | E119: 3001X1901 | F119: 机头-外部 | G119: 是 | H119: 否 | I119: 功率太小，建议由系统自己为传感器供电
A120: 119 | B120: EATA30 防除冰和除雨 | C120: 风挡清洗罐 | D120: 3040E03001G900 | E120: 3001U1301 | F120: 机头-前附件舱 | G120: 否 | H120: 否
A121: 120 | B121: EATA30 防除冰和除雨 | C121: 喷嘴1 | D121: 3040E03003G900 | E121: 3002X1911 | F121: 机头-外部 | G121: 否 | H121: 否
A122: 121 | B122: EATA30 防除冰和除雨 | C122: 喷嘴2 | D122: 3040E03003G900 | E122: 3002X1913 | F122: 机头-外部 | G122: 否 | H122: 否
A123: 122 | B123: EATA30 防除冰和除雨 | C123: 结冰探测器1 | D123: 3080E01001G900 | E123: 3002U4101 | F123: 下机身前段-前设备舱 | G123: 是 | H123: 是
A124: 123 | B124: EATA30 防除冰和除雨 | C124: 结冰探测器2 | D124: 3080E01003G900 | E124: 3002U4103 | F124: 下机身前段-前设备舱 | G124: 是 | H124: 是
A125: 124 | B125: EATA30 防除冰和除雨 | C125: 结冰探测棒 | D125: 3080E01005G900 | E125: 3001U1901 | F125: 机头-外部 | G125: 是 | H125: 是
A126: 125 | B126: EATA30 防除冰和除雨 | C126: 左侧风挡玻璃及其加热模块组件 | D126: 5610E02001G200 | E126: 5602H2201 | F126: 驾驶舱-地板上 | G126: 是 | H126: 否
A127: 126 | B127: EATA30 防除冰和除雨 | C127: 右侧风挡玻璃及其加热模块组件 | D127: 5610E02002G200 | E127: 5602H2202 | F127: 驾驶舱-地板上 | G127: 是 | H127: 否
A128: 127 | B128: EATA31 指示记录系统 | C128: 区域麦克风（AMP） | D128: 3130E01001G900 | E128: 3101D2403 | F128: 驾驶舱-控制面板 | G128: 是 | H128: 是 | I128: 考虑不由电源系统直接供电，由信息系统计算机供电
A129: 128 | B129: EATA31 指示记录系统 | C129: 三轴加速度计（TAA） | D129: 3130E02001G900 | E129: 3101U6101 | F129: 机翼-中央翼盒 | G129: 是 | H129: 是 | I129: 考虑不由电源系统直接供电，由信息系统计算机供电
...

Sheet 负载电气特性
A1: 负载电气特性 | O1: 负载校核
A2: 序号 | B2: 负载ID | C2: 系统章节 | D2: 设备名称 | E2: 设备编号 | F2: LIN号 | G2: 正常工作电压等级（V） | H2: 正常工作电压范围（V） | I2: 是否需要软启动 | J2: 峰值功率（kW） | K2: 峰值功率时间（s） | L2: 供电路数 | M2: 有无供电非相似需求 | N2: 应急是否可卸载 | O2: 工作功率（kW） | P2: 实际功率（kW） | Q2: 功率余量 | R2: 实测电流(A) | S2: 峰值功率/工作功率
A3: 1 | B3: 2301U3101-28V | C3: EATA23 通信系统 | D3: ELT发射器 | E3: 2321E01001G900 | F3: 2301U3101 | G3: 28 | H3: 18-32V | I3: 否 | J3: 0.015 | K3: 0.55 | L3: 单通道供电 | M3: 无 | N3: 否 | O3: 0.00336 | P3: / | Q3: / | R3: / | S3: =J3/O3 -> 4.4642857
A4: 2 | B4: 2302U2501-28V | C4: EATA23 通信系统 | D4: 音频管理单元1 | E4: 2350E01001G900 | F4: 2302U2501 | G4: 28 | H4: 18-32V | I4: 否 | J4: 0.18 | K4: 0.12 | L4: 双通道供电 | M4: 无 | N4: 否 | O4: 0.032 | P4: / | Q4: / | R4: / | S4: =J4/O4 -> 5.625
A5: 3 | B5: 2302U2603-28V | C5: EATA23 通信系统 | D5: 音频管理单元2 | E5: 2350E01001G900 | F5: 2302U2603 | G5: 28 | H5: 18-32V | I5: 否 | J5: 0.18 | K5: 0.12 | L5: 双通道供电 | M5: 无 | N5: 否 | O5: 0.032 | P5: / | Q5: / | R5: / | S5: =J5/O5 -> 5.625
A6: 4 | B6: 2301T3401-28V | C6: EATA23 通信系统 | D6: 电源转换模块 | E6: 2393E01005U900 | F6: 2301T3401 | G6: 28 | H6: 18-32V | I6: 否 | J6: 0.8 | K6: 0.001 | L6: 双通道供电 | M6: 无 | N6: 否 | O6: 0.36 | P6: / | Q6: / | R6: / | S6: =J6/O6 -> 2.2222222
A7: 5 | B7: 2401G4101-28V | C7: EATA24 电源系统 | D7: E 270V电池（含BMS） | E7: 2431E01001G900 | F7: 2401G4101 | G7: 28 | H7: 18-32V | I7: 否 | J7: 0.25 | K7: 0.05 | L7: 双通道供电 | M7: 有 | N7: 否 | O7: 0.1 | P7: / | Q7: / | R7: / | S7: =J7/O7 -> 2.5
A8: 6 | B8: 2401G5201-28V-L | C8: EATA24 电源系统 | D8: LR 270V电池（含BMS） | E8: 2431E01003G900 | F8: 2401G5201 | G8: 28 | H8: 18-32V | I8: 否 | J8: 0.25 | K8: 0.05 | L8: 双通道供电 | M8: 有 | N8: 否 | O8: 0.1 | P8: / | Q8: / | R8: / | S8: =J8/O8 -> 2.5
A9: 7 | B9: 2401G5201-28V-R | C9: EATA24 电源系统 | D9: LR 270V电池（含BMS） | E9: 2431E01003G900 | F9: 2401G5201 | G9: 28 | H9: 18-32V | I9: 否 | J9: 0.25 | K9: 0.05 | L9: 双通道供电 | M9: 有 | N9: 否 | O9: 0.1 | P9: / | Q9: / | R9: / | S9: =J9/O9 -> 2.5
A10: 8 | B10: 2401G4103-28V | C10: EATA24 电源系统 | D10: 应急28V电池（含BMS） | E10: 2432E01001G900 | F10: 2401G4103 | G10: 28 | H10: 18-32V | I10: 否 | J10: 0.2 | K10: 0.05 | L10: 双通道供电 | M10: 有 | N10: 否 | O10: 0.1 | P10: / | Q10: / | R10: / | S10: =J10/O10 -> 2
A11: 9 | B11: 2401U3401-28V | C11: EATA24 电源系统 | D11: 左配电盘箱 | E11: 2461E01001G900 | F11: 2401U3401 | G11: 28 | H11: 18-32V | I11: 否 | J11: 0.06 | K11: 0.1 | L11: 双通道供电 | M11: 有 | N11: 否 | O11: 0.04 | P11: / | Q11: / | R11: / | S11: =J11/O11 -> 1.5
A12: 10 | B12: 2401U3403-28V | C12: EATA24 电源系统 | D12: 右配电盘箱 | E12: 2461E01003G900 | F12: 2401U3403 | G12: 28 | H12: 18-32V | I12: 否 | J12: 0.06 | K12: 0.1 | L12: 双通道供电 | M12: 有 | N12: 否 | O12: 0.04 | P12: / | Q12: / | R12: / | S12: =J12/O12 -> 1.5
A13: 11 | B13: 2401U2601-28V | C13: EATA24 电源系统 | D13: 应急配电盘箱 | E13: 2461E01005G900 | F13: 2401U2601 | G13: 28 | H13: 18-32V | I13: 否 | J13: 0.06 | K13: 0.1 | L13: 双通道供电 | M13: 有 | N13: 否 | O13: 0.04 | P13: / | Q13: / | R13: / | S13: =J13/O13 -> 1.5
A14: 12 | B14: 2404U2601-28V | C14: EATA24 电源系统 | D14: 远程配电装置 RPDU1 | E14: 2462E01001G900 | F14: 2404U2601 | G14: 28 | H14: 18-32V | I14: 否 | J14: 0.2 | K14: 10 | L14: 双通道供电 | M14: 有 | N14: 否 | O14: 0.1 | P14: / | Q14: / | R14: / | S14: =J14/O14 -> 2
... A19: 17 | B19: 2501U2403-28V | C19: EATA25 设备/装饰 | D19: 应急控制板 | E19: 2519E02001G900 | F19: 2501U2403 | G19: 28 | H19: 18-32V | I19: 否 | J19: 0.06 | K19: 0.05 | L19: 单通道供电 | M19: 无 | N19: 否 | O19: 0.005 | P19: / | Q19: / | R19: / | S19: =J19/O19 -> 12
A20: 18 | B20: 2501U2405-28V | C20: EATA25 设备/装饰 | D20: 电源控制板 | E20: 2519E03001G900 | F20: 2501U2405 | G20: 28 | H20: 18-32V | I20: 否 | J20: 0.06 | K20: 0.05 | L20: 单通道供电 | M20: 无 | N20: 否 | O20: 0.005 | P20: 0.00168 | Q20: =O20/P20 -> 2.9761905 | R20: 0.06 | S20: =J20/O20 -> 12
A21: 19 | B21: 2501U2407-28V | C21: EATA25 设备/装饰 | D21: 推力手柄 | E21: 2519E04001G900 | F21: 2501U2407 | G21: 28 | H21: 18-32V | I21: 否 | J21: 0.12 | K21: 0.05 | L21: 双通道供电 | M21: 无 | N21: 否 | O21: 0.028 | P21: / | Q21: / | R21: / | S21: =J21/O21 -> 4.2857143
A22: 20 | B22: 2703U3601-28V | C22: EATA27 飞行控制系统 | D22: 主飞控计算机1 | E22: 2791E01001G900 | F22: 2703U3601 | G22: 28 | H22: 18-32V | I22: 否 | J22: 0.382 | K22: 0.2 | L22: 双通道供电 | M22: 有 | N22: 否 | O22: 0.065 | P22: 0.04088 | Q22: =O22/P22 -> 1.5900196 | R22: 1.46 | S22: =J22/O22 -> 5.8769231
A23: 21 | B23: 2703U3501-28V | C23: EATA27 飞行控制系统 | D23: 主飞控计算机2 | E23: 2791E01001G900 | F23: 2703U3501 | G23: 28 | H23: 18-32V | I23: 否 | J23: 0.382 | K23: 0.2 | L23: 双通道供电 | M23: 有 | N23: 否 | O23: 0.065 | P23: 0.04116 | Q23: =O23/P23 -> 1.5792031 | R23: 1.47 | S23: =J23/O23 -> 5.8769231
A24: 22 | B24: 2703U2603-28V | C24: EATA27 飞行控制系统 | D24: 主飞控计算机3 | E24: 2791E01001G900 | F24: 2703U2603 | G24: 28 | H24: 18-32V | I24: 否 | J24: 0.382 | K24: 0.2 | L24: 双通道供电 | M24: 有 | N24: 否 | O24: 0.065 | P24: 0.04144 | Q24: =O24/P24 -> 1.5685328 | R24: 1.48 | S24: =J24/O24 -> 5.8769231
A25: 23 | B25: 2701U2505-28V | C25: EATA27 飞行控制系统 | D25: 备份飞控计算机 | E25: 2791E01003G900 | F25: 2701U2505 | G25: 28 | H25: 18-32V | I25: 否 | J25: 0.382 | K25: 0.2 | L25: 双通道供电 | M25: 有 | N25: 否 | O25: 0.06 | P25: / | Q25: / | R25: / | S25: =J25/O25 -> 6.3666667
A26: 24 | B26: 2702U2601-28V | C26: EATA27 飞行控制系统 | D26: 飞控数据记录器1 | E26: 2791E02001U900 | F26: 2702U2601 | G26: 28 | H26: 5-28V | I26: 否 | J26: 0.05 | K26: 3 | L26: 单通道供电 | M26: 无 | N26: 是 | O26: 0.025 | P26: 0.0154 | Q26: =O26/P26 -> 1.6233766 | R26: 0.55 | S26: =J26/O26 -> 2
A27: 25 | B27: 2702U3203-28V | C27: EATA27 飞行控制系统 | D27: 飞控数据记录器2 | E27: 2791E02001U900 | F27: 2702U3203 | G27: 28 | H27: 5-28V | I27: 否 | J27: 0.05 | K27: 3 | L27: 单通道供电 | M27: 无 | N27: 是 | O27: 0.025 | P27: 0.01512 | Q27: =O27/P27 -> 1.6534392 | R27: 0.54 | S27: =J27/O27 -> 2
A28: 26 | B28: 2704U3601-270V-功率 | C28: EATA27 飞行控制系统 | D28: 马达控制电子1 | E28: 2792E01001G900 | F28: 2704U3601 | G28: 270 | H28: 200-300V | I28: 是 | J28: 13.5 | K28: 60 | L28: 双通道供电 | M28: 有 | N28: 否 | O28: 2.5 | P28: / | Q28: / | R28: / | S28: =J28/O28 -> 5.4
A29: 27 | B29: 2704U3601-28V-控制 | C29: EATA27 飞行控制系统 | D29: 马达控制电子1 | E29: 2792E01001G900 | F29: 2704U3601 | G29: 28 | H29: 18-33V | I29: 否 | J29: 0.224 | K29: 0.05 | L29: 双通道供电 | M29: 有 | N29: 否 | O29: 0.03 | P29: 0.0084 | Q29: =O29/P29 -> 3.5714286 | R29: 0.3 | S29: =J29/O29 -> 7.4666667
A30: 28 | B30: 2704U3603-270V-功率 | C30: EATA27 飞行控制系统 | D30: 马达控制电子2 | E30: 2792E01001G900 | F30: 2704U3603 | G30: 270 | H30: 200-300V | I30: 是 | J30: 13.5 | K30: 60 | L30: 双通道供电 | M30: 有 | N30: 否 | O30: 2.5 | P30: / | Q30: / | R30: / | S30: =J30/O30 -> 5.4
A31: 29 | B31: 2704U3603-28V-控制 | C31: EATA27 飞行控制系统 | D31: 马达控制电子2 | E31: 2792E01001G900 | F31: 2704U3603 | G31: 28 | H31: 18-33V | I31: 否 | J31: 0.224 | K31: 0.05 | L31: 双通道供电 | M31: 有 | N31: 否 | O31: 0.03 | P31: 0.0084 | Q31: =O31/P31 -> 3.5714286 | R31: 0.3 | S31: =J31/O31 -> 7.4666667
A32: 30 | B32: 2704U3505-270V-功率 | C32: EATA27 飞行控制系统 | D32: 马达控制电子3 | E32: 2792E01001G900 | F32: 2704U3505 | G32: 270 | H32: 200-300V | I32: 是 | J32: 13.5 | K32: 60 | L32: 双通道供电 | M32: 有 | N32: 否 | O32: 2.5 | P32: / | Q32: / | R32: / | S32: =J32/O32 -> 5.4
A33: 31 | B33: 2704U3505-28V-控制 | C33: EATA27 飞行控制系统 | D33: 马达控制电子3 | E33: 2792E01001G900 | F33: 2704U3505 | G33: 28 | H33: 18-33V | I33: 否 | J33: 0.224 | K33: 0.05 | L33: 双通道供电 | M33: 有 | N33: 否 | O33: 0.03 | P33: 0.0084 | Q33: =O33/P33 -> 3.5714286 | R33: 0.3 | S33: =J33/O33 -> 7.4666667
A34: 32 | B34: 2704U3507-270V-功率 | C34: EATA27 飞行控制系统 | D34: 马达控制电子4 | E34: 2792E01001G900 | F34: 2704U3507 | G34: 270 | H34: 200-300V | I34: 是 | J34: 13.5 | K34: 60 | L34: 双通道供电 | M34: 有 | N34: 否 | O34: 2.5 | P34: / | Q34: / | R34: / | S34: =J34/O34 -> 5.4
A35: 33 | B35: 2704U3507-28V-控制 | C35: EATA27 飞行控制系统 | D35: 马达控制电子4 | E35: 2792E01001G900 | F35: 2704U3507 | G35: 28 | H35: 18-33V | I35: 否 | J35: 0.224 | K35: 0.05 | L35: 双通道供电 | M35: 有 | N35: 否 | O35: 0.03 | P35: 0.0084 | Q35: =O35/P35 -> 3.5714286 | R35: 0.3 | S35: =J35/O35 -> 7.4666667
A36: 34 | B36: 2702U3609-270V-功率 | C36: EATA27 飞行控制系统 | D36: 马达控制电子5 | E36: 2792E01003G900 | F36: 2702U3609 | G36: 270 | H36: 200-300V | I36: 是 | J36: 13.5 | K36: 60 | L36: 双通道供电 | M36: 有 | N36: 否 | O36: 1.65 | P36: / | Q36: / | R36: / | S36: =J36/O36 -> 8.1818182
A37: 35 | B37: 2702U3609-28V-控制 | C37: EATA27 飞行控制系统 | D37: 马达控制电子5 | E37: 2792E01003G900 | F37: 2702U3609 | G37: 28 | H37: 18-33V | I37: 否 | J37: 0.224 | K37: 0.05 | L37: 双通道供电 | M37: 有 | N37: 否 | O37: 0.03 | P37: 0.0084 | Q37: =O37/P37 -> 3.5714286 | R37: 0.3 | S37: =J37/O37 -> 7.4666667
A38: 36 | B38: 2702U3511-270V-功率 | C38: EATA27 飞行控制系统 | D38: 马达控制电子6 | E38: 2792E01003G900 | F38: 2702U3511 | G38: 270 | H38: 200-300V | I38: 是 | J38: 13.5 | K38: 60 | L38: 双通道供电 | M38: 有 | N38: 否 | O38: 1.65 | P38: / | Q38: / | R38: / | S38: =J38/O38 -> 8.1818182
A39: 37 | B39: 2702U3511-28V-控制 | C39: EATA27 飞行控制系统 | D39: 马达控制电子6 | E39: 2792E01003G900 | F39: 2702U3511 | G39: 28 | H39: 18-33V | I39: 否 | J39: 0.224 | K39: 0.05 | L39: 双通道供电 | M39: 有 | N39: 否 | O39: 0.03 | P39: 0.0084 | Q39: =O39/P39 -> 3.5714286 | R39: 0.3 | S39: =J39/O39 -> 7.4666667
A40: 38 | B40: 2702U6101-270V-功率 | C40: EATA27 飞行控制系统 | D40: 马达控制电子7 | E40: 2792E01005G900 | F40: 2702U6101 | G40: 28 | H40: 18-33V | I40: 否 | J40: 2.5 | K40: 60 | L40: 双通道供电 | M40: 有 | N40: 否 | O40: 0.5 | P40: / | Q40: / | R40: / | S40: =J40/O40 -> 5
A41: 39 | B41: 2702U6101-28V-控制 | C41: EATA27 飞行控制系统 | D41: 马达控制电子7 | E41: 2792E01005G900 | F41: 2702U6101 | G41: 28 | H41: 18-33V | I41: 否 | J41: 0.3 | K41: 0.05 | L41: 双通道供电 | M41: 有 | N41: 否 | O41: 0.112 | P41: 0.0252 | Q41: =O41/P41 -> 4.4444444 | R41: 0.9 | S41: =J41/O41 -> 2.6785714
A42: 40 | B42: 2702U6103-270V-功率 | C42: EATA27 飞行控制系统 | D42: 马达控制电子8 | E42: 2792E01005G900 | F42: 2702U6103 | G42: 28 | H42: 18-33V | I42: 否 | J42: 2.5 | K42: 60 | L42: 双通道供电 | M42: 有 | N42: 否 | O42: 0.5 | P42: / | Q42: / | R42: / | S42: =J42/O42 -> 5
A43: 41 | B43: 2702U6103-28V-控制 | C43: EATA27 飞行控制系统 | D43: 马达控制电子8 | E43: 2792E01005G900 | F43: 2702U6103 | G43: 28 | H43: 18-33V | I43: 否 | J43: 0.3 | K43: 0.05 | L43: 双通道供电 | M43: 有 | N43: 否 | O43: 0.112 | P43: 0.0252 | Q43: =O43/P43 -> 4.4444444 | R43: 0.9 | S43: =J43/O43 -> 2.6785714
A44: 42 | B44: 2701D6101-28V | C44: EATA27 飞行控制系统 | D44: 直接模式速率传感器（DMRS） | E44: 2793E01009G900 | F44: 2701D6101 | G44: 28 | H44: 18-32V | I44: 否 | J44: 0.01 | K44: 0.05 | L44: 双通道供电 | M44: 无 | N44: 否 | O44: 0.005 | P44: / | Q44: / | R44: / | S44: =J44/O44 -> 2
...

Sheet 负载统计飞行阶段定义
A1: 运行阶段编号 | B1: 运行阶段 | C1: 原统计的运行阶段 | D1: 时间/min | E1: 阶段定义 | F1: 备注
F2: 舵面情况 | G2: 飞行速度TAS | H2: 飞行高度
A3: G0 | B3: 过站 | C3: OP00过站 | D3: 0 | E3: 外部电源车接入电网，支持地面服务；对飞机电池充电或换电 | F3: NA | G3: 0 | H3: 0
A4: G1 | B4: 地面运转-装载 | C4: OP01飞行计划 | D4: 0 | E4: 机组、乘客登上飞机起，同时行李开始装载至飞机准备放行。 | F4: NA | G4: 0 | H4: 0
C5: OP02航前准备 | F5: NA | G5: 0 | H5: 0
A6: G2 | B6: 推出/牵引和起动 | C6: 推出/牵引和起动 | D6: 1 | E6: 自飞机不依靠自身动力受牵引力作用从廊桥、机坪或停机位等机场活动区移动起，至飞机开始依靠自身动力移动前。 | F6: NA | G6: 0 | H6: 0
A7: G3 | B7: 滑出 | C7: OP04滑出 | D7: 3 | E7: 该阶段是起落架开始滚动并滑行至跑道，加速，持续到起落架不再被压缩。根据飞机起飞距离不同，所需时间也不同。 | F7: 襟翼0°到35°，其他舵面0° | G7: 0-10m/s | H7: 0
A8: G4 | B8: 起飞和爬升 | C8: OP05起飞 | D8: 6.77 | E8: 该阶段从起落架不被挤压到刚开始巡航水平结束，包括起飞、初始爬升、航路爬升等子阶段 | F8: 襟翼35°，升降舵-8° | G8: 0~47m/s | H8: ~10.7m
C9: OP06初始爬升 | F9: 襟翼35°到0°，舵面0° | G9: 50m/s~75m/s | H9: ~457m
C10: OP07航路爬升 | F10: 襟翼0°，舵面0° | G10: 75m/s-90m/s | H10: ~4000m
A11: G5 | B11: 巡航 | C11: OP08巡航 | D11: 43.6 | E11: 该阶段的时间窗口是从爬升结束到开始下降的一段时间。 | F11: 襟翼0°，舵面0° | G11: 90m/s | H11: 4000m
A12: G6 | B12: 下降 | C12: OP09下降 | D12: 13.85 | E12: 该阶段是当飞机离开巡航高度，并且在距离地面15米处结束。 | F12: 襟翼0°，舵面0° | G12: 90m/s~75m/s | H12: ~457m
C13: OP10待机 | E13: NA | F13: NA | G13: NA | H13: NA
C14: OP11进近 | E14: 该阶段的时间窗口是从爬升结束到开始下降的一段时间。 | F14: 襟翼0°到35°，舵面0° | G14: 75m/s~50m/s | H14: ~15m
A15: G7 | B15: 着陆 | C15: OP12着陆 | D15: 0.5 | E15: 该阶段始于距离地面15米处，起落架展开，处于向下位置直到起落架全部接触地面，前后起落架完全稳定承受飞机重量。 | F15: 襟翼35°，升降舵-10° | G15: 50m/s~10m/s | H15: 0
A16: G8 | B16: 滑入 | C16: OP13滑入 | D16: 4 | E16: 是从着陆到推进电机关闭且飞机停靠至廊桥。 | F16: 襟翼35°到0度，其他舵面0° | G16: 0~10m/s | H16: 0

Sheet 负载工作模式
A1: 序号 | B1: 负载ID | C1: 系统章节 | D1: 设备名称 | E1: 设备编号 | F1: LIN号 | G1: 正常工作电压等级（V） | H1: 应急是否可卸载 | I1: 负载类型 | J1: 工作模式 | K1: 功率需求（kW） | L1: 飞行阶段 | U1: 正常功率计算辅助列 | AD1: 电量计算辅助列
L2: G0 过站 | M2: G1 地面运转-装载 | N2: G2 推出/牵引和起动 | O2: G3 滑出 | P2: G4 起飞和爬升 | Q2: G5 巡航 | R2: G6 下降 | S2: G7 着陆 | T2: G8 滑入 | U2: G0 过站 | V2: G1 地面运转-装载 | W2: G2 推出/牵引和起动 | X2: G3 滑出 | Y2: G4 起飞和爬升 | Z2: G5 巡航 | AA2: G6 下降 | AB2: G7 着陆 | AC2: G8 滑入 | AD2: G0 过站 | AE2: G1 地面运转-装载 | AF2: G2 推出/牵引和起动 | AG2: G3 滑出 | AH2: G4 起飞和爬升 | AI2: G5 巡航 | AJ2: G6 下降 | AK2: G7 着陆 | AL2: G8 滑入
A3: 1 | B3: 2301U3101-28V | C3: EATA23 通信系统 | D3: ELT发射器 | E3: 2321E01001G900 | F3: 2301U3101 | G3: =VLOOKUP(A3,负载电气特性!A:G,7,FALSE) -> 28 | H3: 否 | I3: 连续负载 | J3: 工作 | K3: 0.00336 | L3: 1 | M3: 1 | N3: 1 | O3: 1 | P3: 1 | Q3: 1 | R3: 1 | S3: 1 | T3: 1 | U3: =_xlfn.LET(_xlpm.maxVal,_xlfn.MAXIFS($K:$K,$A:$A,A3),IF(AND(_xlpm.maxVal=K3,L3<>0),_xlpm.maxVal,"")) -> 0.00336 | V3: =_xlfn.LET(_xlpm.maxVal,_xlfn.MAXIFS($K:$K,$A:$A,A3),IF(AND(_xlpm.maxVal=K3,M3<>0),_xlpm.maxVal,"")) -> 0.00336 | W3: =_xlfn.LET(_xlpm.maxVal,_xlfn.MAXIFS($K:$K,$A:$A,A3),IF(AND(_xlpm.maxVal=K3,N3<>0),_xlpm.maxVal,"")) -> 0.00336 | X3: =_xlfn.LET(_xlpm.maxVal,_xlfn.MAXIFS($K:$K,$A:$A,A3),IF(AND(_xlpm.maxVal=K3,O3<>0),_xlpm.maxVal,"")) -> 0.00336 | Y3: =_xlfn.LET(_xlpm.maxVal,_xlfn.MAXIFS($K:$K,$A:$A,A3),IF(AND(_xlpm.maxVal=K3,P3<>0),_xlpm.maxVal,"")) -> 0.00336 | Z3: =_xlfn.LET(_xlpm.maxVal,_xlfn.MAXIFS($K:$K,$A:$A,A3),IF(AND(_xlpm.maxVal=K3,Q3<>0),_xlpm.maxVal,"")) -> 0.00336 | AA3: =_xlfn.LET(_xlpm.maxVal,_xlfn.MAXIFS($K:$K,$A:$A,A3),IF(AND(_xlpm.maxVal=K3,R3<>0),_xlpm.maxVal,"")) -> 0.00336 | AB3: =_xlfn.LET(_xlpm.maxVal,_xlfn.MAXIFS($K:$K,$A:$A,A3),IF(AND(_xlpm.maxVal=K3,S3<>0),_xlpm.maxVal,"")) -> 0.00336 | AC3: =_xlfn.LET(_xlpm.maxVal,_xlfn.MAXIFS($K:$K,$A:$A,A3),IF(AND(_xlpm.maxVal=K3,T3<>0),_xlpm.maxVal,"")) -> 0.00336 | AD3: =$K3*L3*负载统计!$K$3/60 -> 0 | AE3: =$K3*L3*负载统计!$K$4/60 -> 0 | AF3: =$K3*N3*负载统计!$K$5/60 -> 5.6e-05 | AG3: =$K3*O3*负载统计!$K$6/60 -> 0.000168 | AH3: =$K3*P3*负载统计!$K$7/60 -> 0.00037912 | AI3: =$K3*Q3*负载统计!$K$8/60 -> 0.0024416 | AJ3: =$K3*R3*负载统计!$K$9/60 -> 0.0007756 | AK3: =$K3*S3*负载统计!$K$10/60 -> 2.8e-05 | AL3: =$K3*T3*负载统计!$K$11/60 -> 0.000224
A4: 1 | B4: 2301U3101-28V | C4: EATA23 通信系统 | D4: ELT发射器 | E4: 2321E01001G900 | F4: 2301U3101 | G4: =VLOOKUP(A4,负载电气特性!A:G,7,FALSE) -> 28 | H4: 否 | I4: 连续负载 | J4: 关闭 | K4: 0 | L4: 0 | M4: 0 | N4: 0 | O4: 0 | P4: 0 | Q4: 0 | R4: 0 | S4: 0 | T4: 0 | U4: =_xlfn.LET(_xlpm.maxVal,_xlfn.MAXIFS($K:$K,$A:$A,A4),IF(AND(_xlpm.maxVal=K4,L4<>0),_xlpm.maxVal,"")) | V4: =_xlfn.LET(_xlpm.maxVal,_xlfn.MAXIFS($K:$K,$A:$A,A4),IF(AND(_xlpm.maxVal=K4,M4<>0),_xlpm.maxVal,"")) | W4: =_xlfn.LET(_xlpm.maxVal,_xlfn.MAXIFS($K:$K,$A:$A,A4),IF(AND(_xlpm.maxVal=K4,N4<>0),_xlpm.maxVal,"")) | X4: =_xlfn.LET(_xlpm.maxVal,_xlfn.MAXIFS($K:$K,$A:$A,A4),IF(AND(_xlpm.maxVal=K4,O4<>0),_xlpm.maxVal,"")) | Y4: =_xlfn.LET(_xlpm.maxVal,_xlfn.MAXIFS($K:$K,$A:$A,A4),IF(AND(_xlpm.maxVal=K4,P4<>0),_xlpm.maxVal,"")) | Z4: =_xlfn.LET(_xlpm.maxVal,_xlfn.MAXIFS($K:$K,$A:$A,A4),IF(AND(_xlpm.maxVal=K4,Q4<>0),_xlpm.maxVal,"")) | AA4: =_xlfn.LET(_xlpm.maxVal,_xlfn.MAXIFS($K:$K,$A:$A,A4),IF(AND(_xlpm.maxVal=K4,R4<>0),_xlpm.maxVal,"")) | AB4: =_xlfn.LET(_xlpm.maxVal,_xlfn.MAXIFS($K:$K,$A:$A,A4),IF(AND(_xlpm.maxVal=K4,S4<>0),_xlpm.maxVal,"")) | AC4: =_xlfn.LET(_xlpm.maxVal,_xlfn.MAXIFS($K:$K,$A:$A,A4),IF(AND(_xlpm.maxVal=K4,T4<>0),_xlpm.maxVal,"")) | AD4: =$K4*L4*负载统计!$K$3/60 -> 0 | AE4: =$K4*L4*负载统计!$K$4/60 -> 0 | AF4: =$K4*N4*负载统计!$K$5/60 -> 0 | AG4: =$K4*O4*负载统计!$K$6/60 -> 0 | AH4: =$K4*P4*负载统计!$K$7/60 -> 0 | AI4: =$K4*Q4*负载统计!$K$8/60 -> 0 | AJ4: =$K4*R4*负载统计!$K$9/60 -> 0 | AK4: =$K4*S4*负载统计!$K$10/60 -> 0 | AL4: =$K4*T4*负载统计!$K$11/60 -> 0
A5: 2 | B5: 2302U2501-28V | C5: EATA23 通信系统 | D5: 音频管理单元1 | E5: 2350E01001G900 | F5: 2302U2501 | G5: =VLOOKUP(A5,负载电气特性!A:G,7,FALSE) -> 28 | H5: 否 | I5: 连续负载 | J5: 工作 | K5: 0.032 | L5: 1 | M5: 1 | N5: 1 | O5: 1 | P5: 1 | Q5: 1 | R5: 1 | S5: 1 | T5: 1 | U5: =_xlfn.LET(_xlpm.maxVal,_xlfn.MAXIFS($K:$K,$A:$A,A5),IF(AND(_xlpm.maxVal=K5,L5<>0),_xlpm.maxVal,"")) -> 0.032 | V5: =_xlfn.LET(_xlpm.maxVal,_xlfn.MAXIFS($K:$K,$A:$A,A5),IF(AND(_xlpm.maxVal=K5,M5<>0),_xlpm.maxVal,"")) -> 0.032 | W5: =_xlfn.LET(_xlpm.maxVal,_xlfn.MAXIFS($K:$K,$A:$A,A5),IF(AND(_xlpm.maxVal=K5,N5<>0),_xlpm.maxVal,"")) -> 0.032 | X5: =_xlfn.LET(_xlpm.maxVal,_xlfn.MAXIFS($K:$K,$A:$A,A5),IF(AND(_xlpm.maxVal=K5,O5<>0),_xlpm.maxVal,"")) -> 0.032 | Y5: =_xlfn.LET(_xlpm.maxVal,_xlfn.MAXIFS($K:$K,$A:$A,A5),IF(AND(_xlpm.maxVal=K5,P5<>0),_xlpm.maxVal,"")) -> 0.032 | Z5: =_xlfn.LET(_xlpm.maxVal,_xlfn.MAXIFS($K:$K,$A:$A,A5),IF(AND(_xlpm.maxVal=K5,Q5<>0),_xlpm.maxVal,"")) -> 0.032 | AA5: =_xlfn.LET(_xlpm.maxVal,_xlfn.MAXIFS($K:$K,$A:$A,A5),IF(AND(_xlpm.maxVal=K5,R5<>0),_xlpm.maxVal,"")) -> 0.032 | AB5: =_xlfn.LET(_xlpm.maxVal,_xlfn.MAXIFS($K:$K,$A:$A,A5),IF(AND(_xlpm.maxVal=K5,S5<>0),_xlpm.maxVal,"")) -> 0.032 | AC5: =_xlfn.LET(_xlpm.maxVal,_xlfn.MAXIFS($K:$K,$A:$A,A5),IF(AND(_xlpm.maxVal=K5,T5<>0),_xlpm.maxVal,"")) -> 0.032 | AD5: =$K5*L5*负载统计!$K$3/60 -> 0 | AE5: =$K5*L5*负载统计!$K$4/60 -> 0 | AF5: =$K5*N5*负载统计!$K$5/60 -> 0.00053333333 | AG5: =$K5*O5*负载统计!$K$6/60 -> 0.0016 | AH5: =$K5*P5*负载统计!$K$7/60 -> 0.0036106667 | AI5: =$K5*Q5*负载统计!$K$8/60 -> 0.023253333 | AJ5: =$K5*R5*负载统计!$K$9/60 -> 0.0073866667 | AK5: =$K5*S5*负载统计!$K$10/60 -> 0.00026666667 | AL5: =$K5*T5*负载统计!$K$11/60 -> 0.0021333333
A6: 2 | B6: 2302U2501-28V | C6: EATA23 通信系统 | D6: 音频管理单元1 | E6: 2350E01001G900 | F6: 2302U2501 | G6: =VLOOKUP(A6,负载电气特性!A:G,7,FALSE) -> 28 | H6: 否 | I6: 连续负载 | J6: 关闭 | K6: 0 | L6: 0 | M6: 0 | N6: 0 | O6: 0 | P6: 0 | Q6: 0 | R6: 0 | S6: 0 | T6: 0 | U6: =_xlfn.LET(_xlpm.maxVal,_xlfn.MAXIFS($K:$K,$A:$A,A6),IF(AND(_xlpm.maxVal=K6,L6<>0),_xlpm.maxVal,"")) | V6: =_xlfn.LET(_xlpm.maxVal,_xlfn.MAXIFS($K:$K,$A:$A,A6),IF(AND(_xlpm.maxVal=K6,M6<>0),_xlpm.maxVal,"")) | W6: =_xlfn.LET(_xlpm.maxVal,_xlfn.MAXIFS($K:$K,$A:$A,A6),IF(AND(_xlpm.maxVal=K6,N6<>0),_xlpm.maxVal,"")) | X6: =_xlfn.LET(_xlpm.maxVal,_xlfn.MAXIFS($K:$K,$A:$A,A6),IF(AND(_xlpm.maxVal=K6,O6<>0),_xlpm.maxVal,"")) | Y6: =_xlfn.LET(_xlpm.maxVal,_xlfn.MAXIFS($K:$K,$A:$A,A6),IF(AND(_xlpm.maxVal=K6,P6<>0),_xlpm.maxVal,"")) | Z6: =_xlfn.LET(_xlpm.maxVal,_xlfn.MAXIFS($K:$K,$A:$A,A6),IF(AND(_xlpm.maxVal=K6,Q6<>0),_xlpm.maxVal,"")) | AA6: =_xlfn.LET(_xlpm.maxVal,_xlfn.MAXIFS($K:$K,$A:$A,A6),IF(AND(_xlpm.maxVal=K6,R6<>0),_xlpm.maxVal,"")) | AB6: =_xlfn.LET(_xlpm.maxVal,_xlfn.MAXIFS($K:$K,$A:$A,A6),IF(AND(_xlpm.maxVal=K6,S6<>0),_xlpm.maxVal,"")) | AC6: =_xlfn.LET(_xlpm.maxVal,_xlfn.MAXIFS($K:$K,$A:$A,A6),IF(AND(_xlpm.maxVal=K6,T6<>0),_xlpm.maxVal,"")) | AD6: =$K6*L6*负载统计!$K$3/60 -> 0 | AE6: =$K6*L6*负载统计!$K$4/60 -> 0 | AF6: =$K6*N6*负载统计!$K$5/60 -> 0 | AG6: =$K6*O6*负载统计!$K$6/60 -> 0 | AH6: =$K6*P6*负载统计!$K$7/60 -> 0 | AI6: =$K6*Q6*负载统计!$K$8/60 -> 0 | AJ6: =$K6*R6*负载统计!$K$9/60 -> 0 | AK6: =$K6*S6*负载统计!$K$10/60 -> 0 | AL6: =$K6*T6*负载统计!$K$11/60 -> 0
A7: 3 | B7: 2302U2603-28V | C7: EATA23 通信系统 | D7: 音频管理单元2 | E7: 2350E01001G900 | F7: 2302U2603 | G7: =VLOOKUP(A7,负载电气特性!A:G,7,FALSE) -> 28 | H7: 否 | I7: 连续负载 | J7: 工作 | K7: 0.032 | L7: 1 | M7: 1 | N7: 1 | O7: 1 | P7: 1 | Q7: 1 | R7: 1 | S7: 1 | T7: 1 | U7: =_xlfn.LET(_xlpm.maxVal,_xlfn.MAXIFS($K:$K,$A:$A,A7),IF(AND(_xlpm.maxVal=K7,L7<>0),_xlpm.maxVal,"")) -> 0.032 | V7: =_xlfn.LET(_xlpm.maxVal,_xlfn.MAXIFS($K:$K,$A:$A,A7),IF(AND(_xlpm.maxVal=K7,M7<>0),_xlpm.maxVal,"")) -> 0.032 | W7: =_xlfn.LET(_xlpm.maxVal,_xlfn.MAXIFS($K:$K,$A:$A,A7),IF(AND(_xlpm.maxVal=K7,N7<>0),_xlpm.maxVal,"")) -> 0.032 | X7: =_xlfn.LET(_xlpm.maxVal,_xlfn.MAXIFS($K:$K,$A:$A,A7),IF(AND(_xlpm.maxVal=K7,O7<>0),_xlpm.maxVal,"")) -> 0.032 | Y7: =_xlfn.LET(_xlpm.maxVal,_xlfn.MAXIFS($K:$K,$A:$A,A7),IF(AND(_xlpm.maxVal=K7,P7<>0),_xlpm.maxVal,"")) -> 0.032 | Z7: =_xlfn.LET(_xlpm.maxVal,_xlfn.MAXIFS($K:$K,$A:$A,A7),IF(AND(_xlpm.maxVal=K7,Q7<>0),_xlpm.maxVal,"")) -> 0.032 | AA7: =_xlfn.LET(_xlpm.maxVal,_xlfn.MAXIFS($K:$K,$A:$A,A7),IF(AND(_xlpm.maxVal=K7,R7<>0),_xlpm.maxVal,"")) -> 0.032 | AB7: =_xlfn.LET(_xlpm.maxVal,_xlfn.MAXIFS($K:$K,$A:$A,A7),IF(AND(_xlpm.maxVal=K7,S7<>0),_xlpm.maxVal,"")) -> 0.032 | AC7: =_xlfn.LET(_xlpm.maxVal,_xlfn.MAXIFS($K:$K,$A:$A,A7),IF(AND(_xlpm.maxVal=K7,T7<>0),_xlpm.maxVal,"")) -> 0.032 | AD7: =$K7*L7*负载统计!$K$3/60 -> 0 | AE7: =$K7*L7*负载统计!$K$4/60 -> 0 | AF7: =$K7*N7*负载统计!$K$5/60 -> 0.00053333333 | AG7: =$K7*O7*负载统计!$K$6/60 -> 0.0016 | AH7: =$K7*P7*负载统计!$K$7/60 -> 0.0036106667 | AI7: =$K7*Q7*负载统计!$K$8/60 -> 0.023253333 | AJ7: =$K7*R7*负载统计!$K$9/60 -> 0.0073866667 | AK7: =$K7*S7*负载统计!$K$10/60 -> 0.00026666667 | AL7: =$K7*T7*负载统计!$K$11/60 -> 0.0021333333
A8: 3 | B8: 2302U2603-28V | C8: EATA23 通信系统 | D8: 音频管理单元2 | E8: 2350E01001G900 | F8: 2302U2603 | G8: =VLOOKUP(A8,负载电气特性!A:G,7,FALSE) -> 28 | H8: 否 | I8: 连续负载 | J8: 关闭 | K8: 0 | L8: 0 | M8: 0 | N8: 0 | O8: 0 | P8: 0 | Q8: 0 | R8: 0 | S8: 0 | T8: 0 | U8: =_xlfn.LET(_xlpm.maxVal,_xlfn.MAXIFS($K:$K,$A:$A,A8),IF(AND(_xlpm.maxVal=K8,L8<>0),_xlpm.maxVal,"")) | V8: =_xlfn.LET(_xlpm.maxVal,_xlfn.MAXIFS($K:$K,$A:$A,A8),IF(AND(_xlpm.maxVal=K8,M8<>0),_xlpm.maxVal,"")) | W8: =_xlfn.LET(_xlpm.maxVal,_xlfn.MAXIFS($K:$K,$A:$A,A8),IF(AND(_xlpm.maxVal=K8,N8<>0),_xlpm.maxVal,"")) | X8: =_xlfn.LET(_xlpm.maxVal,_xlfn.MAXIFS($K:$K,$A:$A,A8),IF(AND(_xlpm.maxVal=K8,O8<>0),_xlpm.maxVal,"")) | Y8: =_xlfn.LET(_xlpm.maxVal,_xlfn.MAXIFS($K:$K,$A:$A,A8),IF(AND(_xlpm.maxVal=K8,P8<>0),_xlpm.maxVal,"")) | Z8: =_xlfn.LET(_xlpm.maxVal,_xlfn.MAXIFS($K:$K,$A:$A,A8),IF(AND(_xlpm.maxVal=K8,Q8<>0),_xlpm.maxVal,"")) | AA8: =_xlfn.LET(_xlpm.maxVal,_xlfn.MAXIFS($K:$K,$A:$A,A8),IF(AND(_xlpm.maxVal=K8,R8<>0),_xlpm.maxVal,"")) | AB8: =_xlfn.LET(_xlpm.maxVal,_xlfn.MAXIFS($K:$K,$A:$A,A8),IF(AND(_xlpm.maxVal=K8,S8<>0),_xlpm.maxVal,"")) | AC8: =_xlfn.LET(_xlpm.maxVal,_xlfn.MAXIFS($K:$K,$A:$A,A8),IF(AND(_xlpm.maxVal=K8,T8<>0),_xlpm.maxVal,"")) | AD8: =$K8*L8*负载统计!$K$3/60 -> 0 | AE8: =$K8*L8*负载统计!$K$4/60 -> 0 | AF8: =$K8*N8*负载统计!$K$5/60 -> 0 | AG8: =$K8*O8*负载统计!$K$6/60 -> 0 | AH8: =$K8*P8*负载统计!$K$7/60 -> 0 | AI8: =$K8*Q8*负载统计!$K$8/60 -> 0 | AJ8: =$K8*R8*负载统计!$K$9/60 -> 0 | AK8: =$K8*S8*负载统计!$K$10/60 -> 0 | AL8: =$K8*T8*负载统计!$K$11/60 -> 0
A9: 4 | B9: 2301T3401-28V | C9: EATA23 通信系统 | D9: 电源转换模块 | E9: 2393E01005U900 | F9: 2301T3401 | G9: =VLOOKUP(A9,负载电气特性!A:G,7,FALSE) -> 28 | H9: 否 | I9: 连续负载 | J9: 工作 | K9: 0.36 | L9: 1 | M9: 1 | N9: 1 | O9: 1 | P9: 1 | Q9: 1 | R9: 1 | S9: 1 | T9: 1 | U9: =_xlfn.LET(_xlpm.maxVal,_xlfn.MAXIFS($K:$K,$A:$A,A9),IF(AND(_xlpm.maxVal=K9,L9<>0),_xlpm.maxVal,"")) -> 0.36 | V9: =_xlfn.LET(_xlpm.maxVal,_xlfn.MAXIFS($K:$K,$A:$A,A9),IF(AND(_xlpm.maxVal=K9,M9<>0),_xlpm.maxVal,"")) -> 0.36 | W9: =_xlfn.LET(_xlpm.maxVal,_xlfn.MAXIFS($K:$K,$A:$A,A9),IF(AND(_xlpm.maxVal=K9,N9<>0),_xlpm.maxVal,"")) -> 0.36 | X9: =_xlfn.LET(_xlpm.maxVal,_xlfn.MAXIFS($K:$K,$A:$A,A9),IF(AND(_xlpm.maxVal=K9,O9<>0),_xlpm.maxVal,"")) -> 0.36 | Y9: =_xlfn.LET(_xlpm.maxVal,_xlfn.MAXIFS($K:$K,$A:$A,A9),IF(AND(_xlpm.maxVal=K9,P9<>0),_xlpm.maxVal,"")) -> 0.36 | Z9: =_xlfn.LET(_xlpm.maxVal,_xlfn.MAXIFS($K:$K,$A:$A,A9),IF(AND(_xlpm.maxVal=K9,Q9<>0),_xlpm.maxVal,"")) -> 0.36 | AA9: =_xlfn.LET(_xlpm.maxVal,_xlfn.MAXIFS($K:$K,$A:$A,A9),IF(AND(_xlpm.maxVal=K9,R9<>0),_xlpm.maxVal,"")) -> 0.36 | AB9: =_xlfn.LET(_xlpm.maxVal,_xlfn.MAXIFS($K:$K,$A:$A,A9),IF(AND(_xlpm.maxVal=K9,S9<>0),_xlpm.maxVal,"")) -> 0.36 | AC9: =_xlfn.LET(_xlpm.maxVal,_xlfn.MAXIFS($K:$K,$A:$A,A9),IF(AND(_xlpm.maxVal=K9,T9<>0),_xlpm.maxVal,"")) -> 0.36 | AD9: =$K9*L9*负载统计!$K$3/60 -> 0 | AE9: =$K9*L9*负载统计!$K$4/60 -> 0 | AF9: =$K9*N9*负载统计!$K$5/60 -> 0.006 | AG9: =$K9*O9*负载统计!$K$6/60 -> 0.018 | AH9: =$K9*P9*负载统计!$K$7/60 -> 0.04062 | AI9: =$K9*Q9*负载统计!$K$8/60 -> 0.2616 | AJ9: =$K9*R9*负载统计!$K$9/60 -> 0.0831 | AK9: =$K9*S9*负载统计!$K$10/60 -> 0.003 | AL9: =$K9*T9*负载统计!$K$11/60 -> 0.024
A10: 4 | B10: 2301T3401-28V | C10: EATA23 通信系统 | D10: 电源转换模块 | E10: 2393E01005U900 | F10: 2301T3401 | G10: =VLOOKUP(A10,负载电气特性!A:G,7,FALSE) -> 28 | H10: 否 | I10: 连续负载 | J10: 关闭 | K10: 0 | L10: 0 | M10: 0 | N10: 0 | O10: 0 | P10: 0 | Q10: 0 | R10: 0 | S10: 0 | T10: 0 | U10: =_xlfn.LET(_xlpm.maxVal,_xlfn.MAXIFS($K:$K,$A:$A,A10),IF(AND(_xlpm.maxVal=K10,L10<>0),_xlpm.maxVal,"")) | V10: =_xlfn.LET(_xlpm.maxVal,_xlfn.MAXIFS($K:$K,$A:$A,A10),IF(AND(_xlpm.maxVal=K10,M10<>0),_xlpm.maxVal,"")) | W10: =_xlfn.LET(_xlpm.maxVal,_xlfn.MAXIFS($K:$K,$A:$A,A10),IF(AND(_xlpm.maxVal=K10,N10<>0),_xlpm.maxVal,"")) | X10: =_xlfn.LET(_xlpm.maxVal,_xlfn.MAXIFS($K:$K,$A:$A,A10),IF(AND(_xlpm.maxVal=K10,O10<>0),_xlpm.maxVal,"")) | Y10: =_xlfn.LET(_xlpm.maxVal,_xlfn.MAXIFS($K:$K,$A:$A,A10),IF(AND(_xlpm.maxVal=K10,P10<>0),_xlpm.maxVal,"")) | Z10: =_xlfn.LET(_xlpm.maxVal,_xlfn.MAXIFS($K:$K,$A:$A,A10),IF(AND(_xlpm.maxVal=K10,Q10<>0),_xlpm.maxVal,"")) | AA10: =_xlfn.LET(_xlpm.maxVal,_xlfn.MAXIFS($K:$K,$A:$A,A10),IF(AND(_xlpm.maxVal=K10,R10<>0),_xlpm.maxVal,"")) | AB10: =_xlfn.LET(_xlpm.maxVal,_xlfn.MAXIFS($K:$K,$A:$A,A10),IF(AND(_xlpm.maxVal=K10,S10<>0),_xlpm.maxVal,"")) | AC10: =_xlfn.LET(_xlpm.maxVal,_xlfn.MAXIFS($K:$K,$A:$A,A10),IF(AND(_xlpm.maxVal=K10,T10<>0),_xlpm.maxVal,"")) | AD10: =$K10*L10*负载统计!$K$3/60 -> 0 | AE10: =$K10*L10*负载统计!$K$4/60 -> 0 | AF10: =$K10*N10*负载统计!$K$5/60 -> 0 | AG10: =$K10*O10*负载统计!$K$6/60 -> 0 | AH10: =$K10*P10*负载统计!$K$7/60 -> 0 | AI10: =$K10*Q10*负载统计!$K$8/60 -> 0 | AJ10: =$K10*R10*负载统计!$K$9/60 -> 0 | AK10: =$K10*S10*负载统计!$K$10/60 -> 0 | AL10: =$K10*T10*负载统计!$K$11/60 -> 0
A11: 5 | B11: 2401G4101-28V | C11: EATA24 电源系统 | D11: E 270V电池（含BMS） | E11: 2431E01001G900 | F11: 2401G4101 | G11: =VLOOKUP(A11,负载电气特性!A:G,7,FALSE) -> 28 | H11: 否 | I11: 连续负载 | J11: 工作 | K11: 0.1 | L11: 1 | M11: 1 | N11: 1 | O11: 1 | P11: 1 | Q11: 1 | R11: 1 | S11: 1 | T11: 1 | U11: =_xlfn.LET(_xlpm.maxVal,_xlfn.MAXIFS($K:$K,$A:$A,A11),IF(AND(_xlpm.maxVal=K11,L11<>0),_xlpm.maxVal,"")) -> 0.1 | V11: =_xlfn.LET(_xlpm.maxVal,_xlfn.MAXIFS($K:$K,$A:$A,A11),IF(AND(_xlpm.maxVal=K11,M11<>0),_xlpm.maxVal,"")) -> 0.1 | W11: =_xlfn.LET(_xlpm.maxVal,_xlfn.MAXIFS($K:$K,$A:$A,A11),IF(AND(_xlpm.maxVal=K11,N11<>0),_xlpm.maxVal,"")) -> 0.1 | X11: =_xlfn.LET(_xlpm.maxVal,_xlfn.MAXIFS($K:$K,$A:$A,A11),IF(AND(_xlpm.maxVal=K11,O11<>0),_xlpm.maxVal,"")) -> 0.1 | Y11: =_xlfn.LET(_xlpm.maxVal,_xlfn.MAXIFS($K:$K,$A:$A,A11),IF(AND(_xlpm.maxVal=K11,P11<>0),_xlpm.maxVal,"")) -> 0.1 | Z11: =_xlfn.LET(_xlpm.maxVal,_xlfn.MAXIFS($K:$K,$A:$A,A11),IF(AND(_xlpm.maxVal=K11,Q11<>0),_xlpm.maxVal,"")) -> 0.1 | AA11: =_xlfn.LET(_xlpm.maxVal,_xlfn.MAXIFS($K:$K,$A:$A,A11),IF(AND(_xlpm.maxVal=K11,R11<>0),_xlpm.maxVal,"")) -> 0.1 | AB11: =_xlfn.LET(_xlpm.maxVal,_xlfn.MAXIFS($K:$K,$A:$A,A11),IF(AND(_xlpm.maxVal=K11,S11<>0),_xlpm.maxVal,"")) -> 0.1 | AC11: =_xlfn.LET(_xlpm.maxVal,_xlfn.MAXIFS($K:$K,$A:$A,A11),IF(AND(_xlpm.maxVal=K11,T11<>0),_xlpm.maxVal,"")) -> 0.1 | AD11: =$K11*L11*负载统计!$K$3/60 -> 0 | AE11: =$K11*L11*负载统计!$K$4/60 -> 0 | AF11: =$K11*N11*负载统计!$K$5/60 -> 0.0016666667 | AG11: =$K11*O11*负载统计!$K$6/60 -> 0.005 | AH11: =$K11*P11*负载统计!$K$7/60 -> 0.011283333 | AI11: =$K11*Q11*负载统计!$K$8/60 -> 0.072666667 | AJ11: =$K11*R11*负载统计!$K$9/60 -> 0.023083333 | AK11: =$K11*S11*负载统计!$K$10/60 -> 0.00083333333 | AL11: =$K11*T11*负载统计!$K$11/60 -> 0.0066666667
A12: 5 | B12: 2401G4101-28V | C12: EATA24 电源系统 | D12: E 270V电池（含BMS） | E12: 2431E01001G900 | F12: 2401G4101 | G12: =VLOOKUP(A12,负载电气特性!A:G,7,FALSE) -> 28 | H12: 否 | I12: 连续负载 | J12: 关闭 | K12: 0 | L12: 0 | M12: 0 | N12: 0 | O12: 0 | P12: 0 | Q12: 0 | R12: 0 | S12: 0 | T12: 0 | U12: =_xlfn.LET(_xlpm.maxVal,_xlfn.MAXIFS($K:$K,$A:$A,A12),IF(AND(_xlpm.maxVal=K12,L12<>0),_xlpm.maxVal,"")) | V12: =_xlfn.LET(_xlpm.maxVal,_xlfn.MAXIFS($K:$K,$A:$A,A12),IF(AND(_xlpm.maxVal=K12,M12<>0),_xlpm.maxVal,"")) | W12: =_xlfn.LET(_xlpm.maxVal,_xlfn.MAXIFS($K:$K,$A:$A,A12),IF(AND(_xlpm.maxVal=K12,N12<>0),_xlpm.maxVal,"")) | X12: =_xlfn.LET(_xlpm.maxVal,_xlfn.MAXIFS($K:$K,$A:$A,A12),IF(AND(_xlpm.maxVal=K12,O12<>0),_xlpm.maxVal,"")) | Y12: =_xlfn.LET(_xlpm.maxVal,_xlfn.MAXIFS($K:$K,$A:$A,A12),IF(AND(_xlpm.maxVal=K12,P12<>0),_xlpm.maxVal,"")) | Z12: =_xlfn.LET(_xlpm.maxVal,_xlfn.MAXIFS($K:$K,$A:$A,A12),IF(AND(_xlpm.maxVal=K12,Q12<>0),_xlpm.maxVal,"")) | AA12: =_xlfn.LET(_xlpm.maxVal,_xlfn.MAXIFS($K:$K,$A:$A,A12),IF(AND(_xlpm.maxVal=K12,R12<>0),_xlpm.maxVal,"")) | AB12: =_xlfn.LET(_xlpm.maxVal,_xlfn.MAXIFS($K:$K,$A:$A,A12),IF(AND(_xlpm.maxVal=K12,S12<>0),_xlpm.maxVal,"")) | AC12: =_xlfn.LET(_xlpm.maxVal,_xlfn.MAXIFS($K:$K,$A:$A,A12),IF(AND(_xlpm.maxVal=K12,T12<>0),_xlpm.maxVal,"")) | AD12: =$K12*L12*负载统计!$K$3/60 -> 0 | AE12: =$K12*L12*负载统计!$K$4/60 -> 0 | AF12: =$K12*N12*负载统计!$K$5/60 -> 0 | AG12: =$K12*O12*负载统计!$K$6/60 -> 0 | AH12: =$K12*P12*负载统计!$K$7/60 -> 0 | AI12: =$K12*Q12*负载统计!$K$8/60 -> 0 | AJ12: =$K12*R12*负载统计!$K$9/60 -> 0 | AK12: =$K12*S12*负载统计!$K$10/60 -> 0 | AL12: =$K12*T12*负载统计!$K$11/60 -> 0
A13: 6 | B13: 2401G5201-28V-L | C13: EATA24 电源系统 | D13: LR 270V电池（含BMS） | E13: 2431E01003G900 | F13: 2401G5201 | G13: =VLOOKUP(A13,负载电气特性!A:G,7,FALSE) -> 28 | H13: 否 | I13: 连续负载 | J13: 工作 | K13: 0.1 | L13: 1 | M13: 1 | N13: 1 | O13: 1 | P13: 1 | Q13: 1 | R13: 1 | S13: 1 | T13: 1 | U13: =_xlfn.LET(_xlpm.maxVal,_xlfn.MAXIFS($K:$K,$A:$A,A13),IF(AND(_xlpm.maxVal=K13,L13<>0),_xlpm.maxVal,"")) -> 0.1 | V13: =_xlfn.LET(_xlpm.maxVal,_xlfn.MAXIFS($K:$K,$A:$A,A13),IF(AND(_xlpm.maxVal=K13,M13<>0),_xlpm.maxVal,"")) -> 0.1 | W13: =_xlfn.LET(_xlpm.maxVal,_xlfn.MAXIFS($K:$K,$A:$A,A13),IF(AND(_xlpm.maxVal=K13,N13<>0),_xlpm.maxVal,"")) -> 0.1 | X13: =_xlfn.LET(_xlpm.maxVal,_xlfn.MAXIFS($K:$K,$A:$A,A13),IF(AND(_xlpm.maxVal=K13,O13<>0),_xlpm.maxVal,"")) -> 0.1 | Y13: =_xlfn.LET(_xlpm.maxVal,_xlfn.MAXIFS($K:$K,$A:$A,A13),IF(AND(_xlpm.maxVal=K13,P13<>0),_xlpm.maxVal,"")) -> 0.1 | Z13: =_xlfn.LET(_xlpm.maxVal,_xlfn.MAXIFS($K:$K,$A:$A,A13),IF(AND(_xlpm.maxVal=K13,Q13<>0),_xlpm.maxVal,"")) -> 0.1 | AA13: =_xlfn.LET(_xlpm.maxVal,_xlfn.MAXIFS($K:$K,$A:$A,A13),IF(AND(_xlpm.maxVal=K13,R13<>0),_xlpm.maxVal,"")) -> 0.1 | AB13: =_xlfn.LET(_xlpm.maxVal,_xlfn.MAXIFS($K:$K,$A:$A,A13),IF(AND(_xlpm.maxVal=K13,S13<>0),_xlpm.maxVal,"")) -> 0.1 | AC13: =_xlfn.LET(_xlpm.maxVal,_xlfn.MAXIFS($K:$K,$A:$A,A13),IF(AND(_xlpm.maxVal=K13,T13<>0),_xlpm.maxVal,"")) -> 0.1 | AD13: =$K13*L13*负载统计!$K$3/60 -> 0 | AE13: =$K13*L13*负载统计!$K$4/60 -> 0 | AF13: =$K13*N13*负载统计!$K$5/60 -> 0.0016666667 | AG13: =$K13*O13*负载统计!$K$6/60 -> 0.005 | AH13: =$K13*P13*负载统计!$K$7/60 -> 0.011283333 | AI13: =$K13*Q13*负载统计!$K$8/60 -> 0.072666667 | AJ13: =$K13*R13*负载统计!$K$9/60 -> 0.023083333 | AK13: =$K13*S13*负载统计!$K$10/60 -> 0.00083333333 | AL13: =$K13*T13*负载统计!$K$11/60 -> 0.0066666667
A14: 6 | B14: 2401G5201-28V-L | C14: EATA24 电源系统 | D14: LR 270V电池（含BMS） | E14: 2431E01003G900 | F14: 2401G5201 | G14: =VLOOKUP(A14,负载电气特性!A:G,7,FALSE) -> 28 | H14: 否 | I14: 连续负载 | J14: 关闭 | K14: 0 | L14: 0 | M14: 0 | N14: 0 | O14: 0 | P14: 0 | Q14: 0 | R14: 0 | S14: 0 | T14: 0 | U14: =_xlfn.LET(_xlpm.maxVal,_xlfn.MAXIFS($K:$K,$A:$A,A14),IF(AND(_xlpm.maxVal=K14,L14<>0),_xlpm.maxVal,"")) | V14: =_xlfn.LET(_xlpm.maxVal,_xlfn.MAXIFS($K:$K,$A:$A,A14),IF(AND(_xlpm.maxVal=K14,M14<>0),_xlpm.maxVal,"")) | W14: =_xlfn.LET(_xlpm.maxVal,_xlfn.MAXIFS($K:$K,$A:$A,A14),IF(AND(_xlpm.maxVal=K14,N14<>0),_xlpm.maxVal,"")) | X14: =_xlfn.LET(_xlpm.maxVal,_xlfn.MAXIFS($K:$K,$A:$A,A14),IF(AND(_xlpm.maxVal=K14,O14<>0),_xlpm.maxVal,"")) | Y14: =_xlfn.LET(_xlpm.maxVal,_xlfn.MAXIFS($K:$K,$A:$A,A14),IF(AND(_xlpm.maxVal=K14,P14<>0),_xlpm.maxVal,"")) | Z14: =_xlfn.LET(_xlpm.maxVal,_xlfn.MAXIFS($K:$K,$A:$A,A14),IF(AND(_xlpm.maxVal=K14,Q14<>0),_xlpm.maxVal,"")) | AA14: =_xlfn.LET(_xlpm.maxVal,_xlfn.MAXIFS($K:$K,$A:$A,A14),IF(AND(_xlpm.maxVal=K14,R14<>0),_xlpm.maxVal,"")) | AB14: =_xlfn.LET(_xlpm.maxVal,_xlfn.MAXIFS($K:$K,$A:$A,A14),IF(AND(_xlpm.maxVal=K14,S14<>0),_xlpm.maxVal,"")) | AC14: =_xlfn.LET(_xlpm.maxVal,_xlfn.MAXIFS($K:$K,$A:$A,A14),IF(AND(_xlpm.maxVal=K14,T14<>0),_xlpm.maxVal,"")) | AD14: =$K14*L14*负载统计!$K$3/60 -> 0 | AE14: =$K14*L14*负载统计!$K$4/60 -> 0 | AF14: =$K14*N14*负载统计!$K$5/60 -> 0 | AG14: =$K14*O14*负载统计!$K$6/60 -> 0 | AH14: =$K14*P14*负载统计!$K$7/60 -> 0 | AI14: =$K14*Q14*负载统计!$K$8/60 -> 0 | AJ14: =$K14*R14*负载统计!$K$9/60 -> 0 | AK14: =$K14*S14*负载统计!$K$10/60 -> 0 | AL14: =$K14*T14*负载统计!$K$11/60 -> 0
... A129: 58 | B129: 3201U6105-270V-功率 | C129: EATA32 起落架系统 | D129: 左主起EHM控制器 | E129: 3231E11100G900 | F129: 3201U6105 | G129: =VLOOKUP(A129,负载电气特性!A:G,7,FALSE) -> 270 | H129: 否 | I129: 脉冲负载 | J129: 工作 | K129: 1.35 | L129: 0 | M129: 0 | N129: 0 | O129: 0 | P129: 0.074 | Q129: 0 | R129: 0.036 | S129: 0 | T129: 0 | U129: =_xlfn.LET(_xlpm.maxVal,_xlfn.MAXIFS($K:$K,$A:$A,A129),IF(AND(_xlpm.maxVal=K129,L129<>0),_xlpm.maxVal,"")) | V129: =_xlfn.LET(_xlpm.maxVal,_xlfn.MAXIFS($K:$K,$A:$A,A129),IF(AND(_xlpm.maxVal=K129,M129<>0),_xlpm.maxVal,"")) | W129: =_xlfn.LET(_xlpm.maxVal,_xlfn.MAXIFS($K:$K,$A:$A,A129),IF(AND(_xlpm.maxVal=K129,N129<>0),_xlpm.maxVal,"")) | X129: =_xlfn.LET(_xlpm.maxVal,_xlfn.MAXIFS($K:$K,$A:$A,A129),IF(AND(_xlpm.maxVal=K129,O129<>0),_xlpm.maxVal,"")) | Y129: =_xlfn.LET(_xlpm.maxVal,_xlfn.MAXIFS($K:$K,$A:$A,A129),IF(AND(_xlpm.maxVal=K129,P129<>0),_xlpm.maxVal,"")) -> 1.35 | Z129: =_xlfn.LET(_xlpm.maxVal,_xlfn.MAXIFS($K:$K,$A:$A,A129),IF(AND(_xlpm.maxVal=K129,Q129<>0),_xlpm.maxVal,"")) | AA129: =_xlfn.LET(_xlpm.maxVal,_xlfn.MAXIFS($K:$K,$A:$A,A129),IF(AND(_xlpm.maxVal=K129,R129<>0),_xlpm.maxVal,"")) -> 1.35 | AB129: =_xlfn.LET(_xlpm.maxVal,_xlfn.MAXIFS($K:$K,$A:$A,A129),IF(AND(_xlpm.maxVal=K129,S129<>0),_xlpm.maxVal,"")) | AC129: =_xlfn.LET(_xlpm.maxVal,_xlfn.MAXIFS($K:$K,$A:$A,A129),IF(AND(_xlpm.maxVal=K129,T129<>0),_xlpm.maxVal,"")) | AD129: =$K129*L129*负载统计!$K$3/60 -> 0 | AE129: =$K129*L129*负载统计!$K$4/60 -> 0 | AF129: =$K129*N129*负载统计!$K$5/60 -> 0 | AG129: =$K129*O129*负载统计!$K$6/60 -> 0 | AH129: =$K129*P129*负载统计!$K$7/60 -> 0.01127205 | AI129: =$K129*Q129*负载统计!$K$8/60 -> 0 | AJ129: =$K129*R129*负载统计!$K$9/60 -> 0.0112185 | AK129: =$K129*S129*负载统计!$K$10/60 -> 0 | AL129: =$K129*T129*负载统计!$K$11/60 -> 0
A130: 58 | B130: 3201U6105-270V-功率 | C130: EATA32 起落架系统 | D130: 左主起EHM控制器 | E130: 3231E11100G900 | F130: 3201U6105 | G130: =VLOOKUP(A130,负载电气特性!A:G,7,FALSE) -> 270 | H130: 否 | I130: 脉冲负载 | J130: 关闭 | K130: 0 | L130: 1 | M130: 1 | N130: 1 | O130: 1 | P130: =1-P129 -> 0.926 | Q130: 1 | R130: =1-R129 -> 0.964 | S130: 1 | T130: 1 | U130: =_xlfn.LET(_xlpm.maxVal,_xlfn.MAXIFS($K:$K,$A:$A,A130),IF(AND(_xlpm.maxVal=K130,L130<>0),_xlpm.maxVal,"")) | V130: =_xlfn.LET(_xlpm.maxVal,_xlfn.MAXIFS($K:$K,$A:$A,A130),IF(AND(_xlpm.maxVal=K130,M130<>0),_xlpm.maxVal,"")) | W130: =_xlfn.LET(_xlpm.maxVal,_xlfn.MAXIFS($K:$K,$A:$A,A130),IF(AND(_xlpm.maxVal=K130,N130<>0),_xlpm.maxVal,"")) | X130: =_xlfn.LET(_xlpm.maxVal,_xlfn.MAXIFS($K:$K,$A:$A,A130),IF(AND(_xlpm.maxVal=K130,O130<>0),_xlpm.maxVal,"")) | Y130: =_xlfn.LET(_xlpm.maxVal,_xlfn.MAXIFS($K:$K,$A:$A,A130),IF(AND(_xlpm.maxVal=K130,P130<>0),_xlpm.maxVal,"")) | Z130: =_xlfn.LET(_xlpm.maxVal,_xlfn.MAXIFS($K:$K,$A:$A,A130),IF(AND(_xlpm.maxVal=K130,Q130<>0),_xlpm.maxVal,"")) | AA130: =_xlfn.LET(_xlpm.maxVal,_xlfn.MAXIFS($K:$K,$A:$A,A130),IF(AND(_xlpm.maxVal=K130,R130<>0),_xlpm.maxVal,"")) | AB130: =_xlfn.LET(_xlpm.maxVal,_xlfn.MAXIFS($K:$K,$A:$A,A130),IF(AND(_xlpm.maxVal=K130,S130<>0),_xlpm.maxVal,"")) | AC130: =_xlfn.LET(_xlpm.maxVal,_xlfn.MAXIFS($K:$K,$A:$A,A130),IF(AND(_xlpm.maxVal=K130,T130<>0),_xlpm.maxVal,"")) | AD130: =$K130*L130*负载统计!$K$3/60 -> 0 | AE130: =$K130*L130*负载统计!$K$4/60 -> 0 | AF130: =$K130*N130*负载统计!$K$5/60 -> 0 | AG130: =$K130*O130*负载统计!$K$6/60 -> 0 | AH130: =$K130*P130*负载统计!$K$7/60 -> 0 | AI130: =$K130*Q130*负载统计!$K$8/60 -> 0 | AJ130: =$K130*R130*负载统计!$K$9/60 -> 0 | AK130: =$K130*S130*负载统计!$K$10/60 -> 0 | AL130: =$K130*T130*负载统计!$K$11/60 -> 0
A131: 59 | B131: 3201U6105-28V-控制 | C131: EATA32 起落架系统 | D131: 左主起EHM控制器 | E131: 3231E11100G900 | F131: 3201U6105 | G131: =VLOOKUP(A131,负载电气特性!A:G,7,FALSE) -> 28 | H131: 否 | I131: 连续负载 | J131: 工作 | K131: 0.098 | L131: 1 | M131: 1 | N131: 1 | O131: 1 | P131: 1 | Q131: 1 | R131: 1 | S131: 1 | T131: 1 | U131: =_xlfn.LET(_xlpm.maxVal,_xlfn.MAXIFS($K:$K,$A:$A,A131),IF(AND(_xlpm.maxVal=K131,L131<>0),_xlpm.maxVal,"")) -> 0.098 | V131: =_xlfn.LET(_xlpm.maxVal,_xlfn.MAXIFS($K:$K,$A:$A,A131),IF(AND(_xlpm.maxVal=K131,M131<>0),_xlpm.maxVal,"")) -> 0.098 | W131: =_xlfn.LET(_xlpm.maxVal,_xlfn.MAXIFS($K:$K,$A:$A,A131),IF(AND(_xlpm.maxVal=K131,N131<>0),_xlpm.maxVal,"")) -> 0.098 | X131: =_xlfn.LET(_xlpm.maxVal,_xlfn.MAXIFS($K:$K,$A:$A,A131),IF(AND(_xlpm.maxVal=K131,O131<>0),_xlpm.maxVal,"")) -> 0.098 | Y131: =_xlfn.LET(_xlpm.maxVal,_xlfn.MAXIFS($K:$K,$A:$A,A131),IF(AND(_xlpm.maxVal=K131,P131<>0),_xlpm.maxVal,"")) -> 0.098 | Z131: =_xlfn.LET(_xlpm.maxVal,_xlfn.MAXIFS($K:$K,$A:$A,A131),IF(AND(_xlpm.maxVal=K131,Q131<>0),_xlpm.maxVal,"")) -> 0.098 | AA131: =_xlfn.LET(_xlpm.maxVal,_xlfn.MAXIFS($K:$K,$A:$A,A131),IF(AND(_xlpm.maxVal=K131,R131<>0),_xlpm.maxVal,"")) -> 0.098 | AB131: =_xlfn.LET(_xlpm.maxVal,_xlfn.MAXIFS($K:$K,$A:$A,A131),IF(AND(_xlpm.maxVal=K131,S131<>0),_xlpm.maxVal,"")) -> 0.098 | AC131: =_xlfn.LET(_xlpm.maxVal,_xlfn.MAXIFS($K:$K,$A:$A,A131),IF(AND(_xlpm.maxVal=K131,T131<>0),_xlpm.maxVal,"")) -> 0.098 | AD131: =$K131*L131*负载统计!$K$3/60 -> 0 | AE131: =$K131*L131*负载统计!$K$4/60 -> 0 | AF131: =$K131*N131*负载统计!$K$5/60 -> 0.0016333333 | AG131: =$K131*O131*负载统计!$K$6/60 -> 0.0049 | AH131: =$K131*P131*负载统计!$K$7/60 -> 0.011057667 | AI131: =$K131*Q131*负载统计!$K$8/60 -> 0.071213333 | AJ131: =$K131*R131*负载统计!$K$9/60 -> 0.022621667 | AK131: =$K131*S131*负载统计!$K$10/60 -> 0.00081666667 | AL131: =$K131*T131*负载统计!$K$11/60 -> 0.0065333333
A132: 59 | B132: 3201U6105-28V-控制 | C132: EATA32 起落架系统 | D132: 左主起EHM控制器 | E132: 3231E11100G900 | F132: 3201U6105 | G132: =VLOOKUP(A132,负载电气特性!A:G,7,FALSE) -> 28 | H132: 否 | I132: 连续负载 | J132: 待机 | K132: 0.008 | L132: 0 | M132: 0 | N132: 0 | O132: 0 | P132: 0 | Q132: 0 | R132: 0 | S132: 0 | T132: 0 | U132: =_xlfn.LET(_xlpm.maxVal,_xlfn.MAXIFS($K:$K,$A:$A,A132),IF(AND(_xlpm.maxVal=K132,L132<>0),_xlpm.maxVal,"")) | V132: =_xlfn.LET(_xlpm.maxVal,_xlfn.MAXIFS($K:$K,$A:$A,A132),IF(AND(_xlpm.maxVal=K132,M132<>0),_xlpm.maxVal,"")) | W132: =_xlfn.LET(_xlpm.maxVal,_xlfn.MAXIFS($K:$K,$A:$A,A132),IF(AND(_xlpm.maxVal=K132,N132<>0),_xlpm.maxVal,"")) | X132: =_xlfn.LET(_xlpm.maxVal,_xlfn.MAXIFS($K:$K,$A:$A,A132),IF(AND(_xlpm.maxVal=K132,O132<>0),_xlpm.maxVal,"")) | Y132: =_xlfn.LET(_xlpm.maxVal,_xlfn.MAXIFS($K:$K,$A:$A,A132),IF(AND(_xlpm.maxVal=K132,P132<>0),_xlpm.maxVal,"")) | Z132: =_xlfn.LET(_xlpm.maxVal,_xlfn.MAXIFS($K:$K,$A:$A,A132),IF(AND(_xlpm.maxVal=K132,Q132<>0),_xlpm.maxVal,"")) | AA132: =_xlfn.LET(_xlpm.maxVal,_xlfn.MAXIFS($K:$K,$A:$A,A132),IF(AND(_xlpm.maxVal=K132,R132<>0),_xlpm.maxVal,"")) | AB132: =_xlfn.LET(_xlpm.maxVal,_xlfn.MAXIFS($K:$K,$A:$A,A132),IF(AND(_xlpm.maxVal=K132,S132<>0),_xlpm.maxVal,"")) | AC132: =_xlfn.LET(_xlpm.maxVal,_xlfn.MAXIFS($K:$K,$A:$A,A132),IF(AND(_xlpm.maxVal=K132,T132<>0),_xlpm.maxVal,"")) | AD132: =$K132*L132*负载统计!$K$3/60 -> 0 | AE132: =$K132*L132*负载统计!$K$4/60 -> 0 | AF132: =$K132*N132*负载统计!$K$5/60 -> 0 | AG132: =$K132*O132*负载统计!$K$6/60 -> 0 | AH132: =$K132*P132*负载统计!$K$7/60 -> 0 | AI132: =$K132*Q132*负载统计!$K$8/60 -> 0 | AJ132: =$K132*R132*负载统计!$K$9/60 -> 0 | AK132: =$K132*S132*负载统计!$K$10/60 -> 0 | AL132: =$K132*T132*负载统计!$K$11/60 -> 0
A133: 59 | B133: 3201U6105-28V-控制 | C133: EATA32 起落架系统 | D133: 左主起EHM控制器 | E133: 3231E11100G900 | F133: 3201U6105 | G133: =VLOOKUP(A133,负载电气特性!A:G,7,FALSE) -> 28 | H133: 否 | I133: 连续负载 | J133: 关闭 | K133: 0 | L133: 0 | M133: 0 | N133: 0 | O133: 0 | P133: 0 | Q133: 0 | R133: 0 | S133: 0 | T133: 0 | U133: =_xlfn.LET(_xlpm.maxVal,_xlfn.MAXIFS($K:$K,$A:$A,A133),IF(AND(_xlpm.maxVal=K133,L133<>0),_xlpm.maxVal,"")) | V133: =_xlfn.LET(_xlpm.maxVal,_xlfn.MAXIFS($K:$K,$A:$A,A133),IF(AND(_xlpm.maxVal=K133,M133<>0),_xlpm.maxVal,"")) | W133: =_xlfn.LET(_xlpm.maxVal,_xlfn.MAXIFS($K:$K,$A:$A,A133),IF(AND(_xlpm.maxVal=K133,N133<>0),_xlpm.maxVal,"")) | X133: =_xlfn.LET(_xlpm.maxVal,_xlfn.MAXIFS($K:$K,$A:$A,A133),IF(AND(_xlpm.maxVal=K133,O133<>0),_xlpm.maxVal,"")) | Y133: =_xlfn.LET(_xlpm.maxVal,_xlfn.MAXIFS($K:$K,$A:$A,A133),IF(AND(_xlpm.maxVal=K133,P133<>0),_xlpm.maxVal,"")) | Z133: =_xlfn.LET(_xlpm.maxVal,_xlfn.MAXIFS($K:$K,$A:$A,A133),IF(AND(_xlpm.maxVal=K133,Q133<>0),_xlpm.maxVal,"")) | AA133: =_xlfn.LET(_xlpm.maxVal,_xlfn.MAXIFS($K:$K,$A:$A,A133),IF(AND(_xlpm.maxVal=K133,R133<>0),_xlpm.maxVal,"")) | AB133: =_xlfn.LET(_xlpm.maxVal,_xlfn.MAXIFS($K:$K,$A:$A,A133),IF(AND(_xlpm.maxVal=K133,S133<>0),_xlpm.maxVal,"")) | AC133: =_xlfn.LET(_xlpm.maxVal,_xlfn.MAXIFS($K:$K,$A:$A,A133),IF(AND(_xlpm.maxVal=K133,T133<>0),_xlpm.maxVal,"")) | AD133: =$K133*L133*负载统计!$K$3/60 -> 0 | AE133: =$K133*L133*负载统计!$K$4/60 -> 0 | AF133: =$K133*N133*负载统计!$K$5/60 -> 0 | AG133: =$K133*O133*负载统计!$K$6/60 -> 0 | AH133: =$K133*P133*负载统计!$K$7/60 -> 0 | AI133: =$K133*Q133*负载统计!$K$8/60 -> 0 | AJ133: =$K133*R133*负载统计!$K$9/60 -> 0 | AK133: =$K133*S133*负载统计!$K$10/60 -> 0 | AL133: =$K133*T133*负载统计!$K$11/60 -> 0
A134: 60 | B134: 3201U6107-270V-功率 | C134: EATA32 起落架系统 | D134: 右主起EHM控制器 | E134: 3231E11100G900 | F134: 3201U6107 | G134: =VLOOKUP(A134,负载电气特性!A:G,7,FALSE) -> 270 | H134: 否 | I134: 脉冲负载 | J134: 工作 | K134: 1.35 | L134: 0 | M134: 0 | N134: 0 | O134: 0 | P134: 0.074 | Q134: 0 | R134: 0.036 | S134: 0 | T134: 0 | U134: =_xlfn.LET(_xlpm.maxVal,_xlfn.MAXIFS($K:$K,$A:$A,A134),IF(AND(_xlpm.maxVal=K134,L134<>0),_xlpm.maxVal,"")) | V134: =_xlfn.LET(_xlpm.maxVal,_xlfn.MAXIFS($K:$K,$A:$A,A134),IF(AND(_xlpm.maxVal=K134,M134<>0),_xlpm.maxVal,"")) | W134: =_xlfn.LET(_xlpm.maxVal,_xlfn.MAXIFS($K:$K,$A:$A,A134),IF(AND(_xlpm.maxVal=K134,N134<>0),_xlpm.maxVal,"")) | X134: =_xlfn.LET(_xlpm.maxVal,_xlfn.MAXIFS($K:$K,$A:$A,A134),IF(AND(_xlpm.maxVal=K134,O134<>0),_xlpm.maxVal,"")) | Y134: =_xlfn.LET(_xlpm.maxVal,_xlfn.MAXIFS($K:$K,$A:$A,A134),IF(AND(_xlpm.maxVal=K134,P134<>0),_xlpm.maxVal,"")) -> 1.35 | Z134: =_xlfn.LET(_xlpm.maxVal,_xlfn.MAXIFS($K:$K,$A:$A,A134),IF(AND(_xlpm.maxVal=K134,Q134<>0),_xlpm.maxVal,"")) | AA134: =_xlfn.LET(_xlpm.maxVal,_xlfn.MAXIFS($K:$K,$A:$A,A134),IF(AND(_xlpm.maxVal=K134,R134<>0),_xlpm.maxVal,"")) -> 1.35 | AB134: =_xlfn.LET(_xlpm.maxVal,_xlfn.MAXIFS($K:$K,$A:$A,A134),IF(AND(_xlpm.maxVal=K134,S134<>0),_xlpm.maxVal,"")) | AC134: =_xlfn.LET(_xlpm.maxVal,_xlfn.MAXIFS($K:$K,$A:$A,A134),IF(AND(_xlpm.maxVal=K134,T134<>0),_xlpm.maxVal,"")) | AD134: =$K134*L134*负载统计!$K$3/60 -> 0 | AE134: =$K134*L134*负载统计!$K$4/60 -> 0 | AF134: =$K134*N134*负载统计!$K$5/60 -> 0 | AG134: =$K134*O134*负载统计!$K$6/60 -> 0 | AH134: =$K134*P134*负载统计!$K$7/60 -> 0.01127205 | AI134: =$K134*Q134*负载统计!$K$8/60 -> 0 | AJ134: =$K134*R134*负载统计!$K$9/60 -> 0.0112185 | AK134: =$K134*S134*负载统计!$K$10/60 -> 0 | AL134: =$K134*T134*负载统计!$K$11/60 -> 0
A135: 60 | B135: 3201U6107-270V-功率 | C135: EATA32 起落架系统 | D135: 右主起EHM控制器 | E135: 3231E11100G900 | F135: 3201U6107 | G135: =VLOOKUP(A135,负载电气特性!A:G,7,FALSE) -> 270 | H135: 否 | I135: 脉冲负载 | J135: 关闭 | K135: 0 | L135: 1 | M135: 1 | N135: 1 | O135: 1 | P135: =1-P134 -> 0.926 | Q135: 1 | R135: =1-R134 -> 0.964 | S135: 1 | T135: 1 | U135: =_xlfn.LET(_xlpm.maxVal,_xlfn.MAXIFS($K:$K,$A:$A,A135),IF(AND(_xlpm.maxVal=K135,L135<>0),_xlpm.maxVal,"")) | V135: =_xlfn.LET(_xlpm.maxVal,_xlfn.MAXIFS($K:$K,$A:$A,A135),IF(AND(_xlpm.maxVal=K135,M135<>0),_xlpm.maxVal,"")) | W135: =_xlfn.LET(_xlpm.maxVal,_xlfn.MAXIFS($K:$K,$A:$A,A135),IF(AND(_xlpm.maxVal=K135,N135<>0),_xlpm.maxVal,"")) | X135: =_xlfn.LET(_xlpm.maxVal,_xlfn.MAXIFS($K:$K,$A:$A,A135),IF(AND(_xlpm.maxVal=K135,O135<>0),_xlpm.maxVal,"")) | Y135: =_xlfn.LET(_xlpm.maxVal,_xlfn.MAXIFS($K:$K,$A:$A,A135),IF(AND(_xlpm.maxVal=K135,P135<>0),_xlpm.maxVal,"")) | Z135: =_xlfn.LET(_xlpm.maxVal,_xlfn.MAXIFS($K:$K,$A:$A,A135),IF(AND(_xlpm.maxVal=K135,Q135<>0),_xlpm.maxVal,"")) | AA135: =_xlfn.LET(_xlpm.maxVal,_xlfn.MAXIFS($K:$K,$A:$A,A135),IF(AND(_xlpm.maxVal=K135,R135<>0),_xlpm.maxVal,"")) | AB135: =_xlfn.LET(_xlpm.maxVal,_xlfn.MAXIFS($K:$K,$A:$A,A135),IF(AND(_xlpm.maxVal=K135,S135<>0),_xlpm.maxVal,"")) | AC135: =_xlfn.LET(_xlpm.maxVal,_xlfn.MAXIFS($K:$K,$A:$A,A135),IF(AND(_xlpm.maxVal=K135,T135<>0),_xlpm.maxVal,"")) | AD135: =$K135*L135*负载统计!$K$3/60 -> 0 | AE135: =$K135*L135*负载统计!$K$4/60 -> 0 | AF135: =$K135*N135*负载统计!$K$5/60 -> 0 | AG135: =$K135*O135*负载统计!$K$6/60 -> 0 | AH135: =$K135*P135*负载统计!$K$7/60 -> 0 | AI135: =$K135*Q135*负载统计!$K$8/60 -> 0 | AJ135: =$K135*R135*负载统计!$K$9/60 -> 0 | AK135: =$K135*S135*负载统计!$K$10/60 -> 0 | AL135: =$K135*T135*负载统计!$K$11/60 -> 0
A136: 61 | B136: 3201U6107-28V-控制 | C136: EATA32 起落架系统 | D136: 右主起EHM控制器 | E136: 3231E11100G900 | F136: 3201U6107 | G136: =VLOOKUP(A136,负载电气特性!A:G,7,FALSE) -> 28 | H136: 否 | I136: 连续负载 | J136: 工作 | K136: 0.098 | L136: 1 | M136: 1 | N136: 1 | O136: 1 | P136: 1 | Q136: 1 | R136: 1 | S136: 1 | T136: 1 | U136: =_xlfn.LET(_xlpm.maxVal,_xlfn.MAXIFS($K:$K,$A:$A,A136),IF(AND(_xlpm.maxVal=K136,L136<>0),_xlpm.maxVal,"")) -> 0.098 | V136: =_xlfn.LET(_xlpm.maxVal,_xlfn.MAXIFS($K:$K,$A:$A,A136),IF(AND(_xlpm.maxVal=K136,M136<>0),_xlpm.maxVal,"")) -> 0.098 | W136: =_xlfn.LET(_xlpm.maxVal,_xlfn.MAXIFS($K:$K,$A:$A,A136),IF(AND(_xlpm.maxVal=K136,N136<>0),_xlpm.maxVal,"")) -> 0.098 | X136: =_xlfn.LET(_xlpm.maxVal,_xlfn.MAXIFS($K:$K,$A:$A,A136),IF(AND(_xlpm.maxVal=K136,O136<>0),_xlpm.maxVal,"")) -> 0.098 | Y136: =_xlfn.LET(_xlpm.maxVal,_xlfn.MAXIFS($K:$K,$A:$A,A136),IF(AND(_xlpm.maxVal=K136,P136<>0),_xlpm.maxVal,"")) -> 0.098 | Z136: =_xlfn.LET(_xlpm.maxVal,_xlfn.MAXIFS($K:$K,$A:$A,A136),IF(AND(_xlpm.maxVal=K136,Q136<>0),_xlpm.maxVal,"")) -> 0.098 | AA136: =_xlfn.LET(_xlpm.maxVal,_xlfn.MAXIFS($K:$K,$A:$A,A136),IF(AND(_xlpm.maxVal=K136,R136<>0),_xlpm.maxVal,"")) -> 0.098 | AB136: =_xlfn.LET(_xlpm.maxVal,_xlfn.MAXIFS($K:$K,$A:$A,A136),IF(AND(_xlpm.maxVal=K136,S136<>0),_xlpm.maxVal,"")) -> 0.098 | AC136: =_xlfn.LET(_xlpm.maxVal,_xlfn.MAXIFS($K:$K,$A:$A,A136),IF(AND(_xlpm.maxVal=K136,T136<>0),_xlpm.maxVal,"")) -> 0.098 | AD136: =$K136*L136*负载统计!$K$3/60 -> 0 | AE136: =$K136*L136*负载统计!$K$4/60 -> 0 | AF136: =$K136*N136*负载统计!$K$5/60 -> 0.0016333333 | AG136: =$K136*O136*负载统计!$K$6/60 -> 0.0049 | AH136: =$K136*P136*负载统计!$K$7/60 -> 0.011057667 | AI136: =$K136*Q136*负载统计!$K$8/60 -> 0.071213333 | AJ136: =$K136*R136*负载统计!$K$9/60 -> 0.022621667 | AK136: =$K136*S136*负载统计!$K$10/60 -> 0.00081666667 | AL136: =$K136*T136*负载统计!$K$11/60 -> 0.0065333333
A137: 61 | B137: 3201U6107-28V-控制 | C137: EATA32 起落架系统 | D137: 右主起EHM控制器 | E137: 3231E11100G900 | F137: 3201U6107 | G137: =VLOOKUP(A137,负载电气特性!A:G,7,FALSE) -> 28 | H137: 否 | I137: 连续负载 | J137: 待机 | K137: 0.008 | L137: 0 | M137: 0 | N137: 0 | O137: 0 | P137: 0 | Q137: 0 | R137: 0 | S137: 0 | T137: 0 | U137: =_xlfn.LET(_xlpm.maxVal,_xlfn.MAXIFS($K:$K,$A:$A,A137),IF(AND(_xlpm.maxVal=K137,L137<>0),_xlpm.maxVal,"")) | V137: =_xlfn.LET(_xlpm.maxVal,_xlfn.MAXIFS($K:$K,$A:$A,A137),IF(AND(_xlpm.maxVal=K137,M137<>0),_xlpm.maxVal,"")) | W137: =_xlfn.LET(_xlpm.maxVal,_xlfn.MAXIFS($K:$K,$A:$A,A137),IF(AND(_xlpm.maxVal=K137,N137<>0),_xlpm.maxVal,"")) | X137: =_xlfn.LET(_xlpm.maxVal,_xlfn.MAXIFS($K:$K,$A:$A,A137),IF(AND(_xlpm.maxVal=K137,O137<>0),_xlpm.maxVal,"")) | Y137: =_xlfn.LET(_xlpm.maxVal,_xlfn.MAXIFS($K:$K,$A:$A,A137),IF(AND(_xlpm.maxVal=K137,P137<>0),_xlpm.maxVal,"")) | Z137: =_xlfn.LET(_xlpm.maxVal,_xlfn.MAXIFS($K:$K,$A:$A,A137),IF(AND(_xlpm.maxVal=K137,Q137<>0),_xlpm.maxVal,"")) | AA137: =_xlfn.LET(_xlpm.maxVal,_xlfn.MAXIFS($K:$K,$A:$A,A137),IF(AND(_xlpm.maxVal=K137,R137<>0),_xlpm.maxVal,"")) | AB137: =_xlfn.LET(_xlpm.maxVal,_xlfn.MAXIFS($K:$K,$A:$A,A137),IF(AND(_xlpm.maxVal=K137,S137<>0),_xlpm.maxVal,"")) | AC137: =_xlfn.LET(_xlpm.maxVal,_xlfn.MAXIFS($K:$K,$A:$A,A137),IF(AND(_xlpm.maxVal=K137,T137<>0),_xlpm.maxVal,"")) | AD137: =$K137*L137*负载统计!$K$3/60 -> 0 | AE137: =$K137*L137*负载统计!$K$4/60 -> 0 | AF137: =$K137*N137*负载统计!$K$5/60 -> 0 | AG137: =$K137*O137*负载统计!$K$6/60 -> 0 | AH137: =$K137*P137*负载统计!$K$7/60 -> 0 | AI137: =$K137*Q137*负载统计!$K$8/60 -> 0 | AJ137: =$K137*R137*负载统计!$K$9/60 -> 0 | AK137: =$K137*S137*负载统计!$K$10/60 -> 0 | AL137: =$K137*T137*负载统计!$K$11/60 -> 0
A138: 61 | B138: 3201U6107-28V-控制 | C138: EATA32 起落架系统 | D138: 右主起EHM控制器 | E138: 3231E11100G900 | F138: 3201U6107 | G138: =VLOOKUP(A138,负载电气特性!A:G,7,FALSE) -> 28 | H138: 否 | I138: 连续负载 | J138: 关闭 | K138: 0 | L138: 0 | M138: 0 | N138: 0 | O138: 0 | P138: 0 | Q138: 0 | R138: 0 | S138: 0 | T138: 0 | U138: =_xlfn.LET(_xlpm.maxVal,_xlfn.MAXIFS($K:$K,$A:$A,A138),IF(AND(_xlpm.maxVal=K138,L138<>0),_xlpm.maxVal,"")) | V138: =_xlfn.LET(_xlpm.maxVal,_xlfn.MAXIFS($K:$K,$A:$A,A138),IF(AND(_xlpm.maxVal=K138,M138<>0),_xlpm.maxVal,"")) | W138: =_xlfn.LET(_xlpm.maxVal,_xlfn.MAXIFS($K:$K,$A:$A,A138),IF(AND(_xlpm.maxVal=K138,N138<>0),_xlpm.maxVal,"")) | X138: =_xlfn.LET(_xlpm.maxVal,_xlfn.MAXIFS($K:$K,$A:$A,A138),IF(AND(_xlpm.maxVal=K138,O138<>0),_xlpm.maxVal,"")) | Y138: =_xlfn.LET(_xlpm.maxVal,_xlfn.MAXIFS($K:$K,$A:$A,A138),IF(AND(_xlpm.maxVal=K138,P138<>0),_xlpm.maxVal,"")) | Z138: =_xlfn.LET(_xlpm.maxVal,_xlfn.MAXIFS($K:$K,$A:$A,A138),IF(AND(_xlpm.maxVal=K138,Q138<>0),_xlpm.maxVal,"")) | AA138: =_xlfn.LET(_xlpm.maxVal,_xlfn.MAXIFS($K:$K,$A:$A,A138),IF(AND(_xlpm.maxVal=K138,R138<>0),_xlpm.maxVal,"")) | AB138: =_xlfn.LET(_xlpm.maxVal,_xlfn.MAXIFS($K:$K,$A:$A,A138),IF(AND(_xlpm.maxVal=K138,S138<>0),_xlpm.maxVal,"")) | AC138: =_xlfn.LET(_xlpm.maxVal,_xlfn.MAXIFS($K:$K,$A:$A,A138),IF(AND(_xlpm.maxVal=K138,T138<>0),_xlpm.maxVal,"")) | AD138: =$K138*L138*负载统计!$K$3/60 -> 0 | AE138: =$K138*L138*负载统计!$K$4/60 -> 0 | AF138: =$K138*N138*负载统计!$K$5/60 -> 0 | AG138: =$K138*O138*负载统计!$K$6/60 -> 0 | AH138: =$K138*P138*负载统计!$K$7/60 -> 0 | AI138: =$K138*Q138*负载统计!$K$8/60 -> 0 | AJ138: =$K138*R138*负载统计!$K$9/60 -> 0 | AK138: =$K138*S138*负载统计!$K$10/60 -> 0 | AL138: =$K138*T138*负载统计!$K$11/60 -> 0
A139: 62 | B139: 3201U4121-270V-功率 | C139: EATA32 起落架系统 | D139: 前起EHM控制器 | E139: 3231E11300G900 | F139: 3201U4121 | G139: =VLOOKUP(A139,负载电气特性!A:G,7,FALSE) -> 270 | H139: 否 | I139: 脉冲负载 | J139: 工作 | K139: 1.35 | L139: 0 | M139: 0 | N139: 0 | O139: 0 | P139: 0.074 | Q139: 0 | R139: 0.036 | S139: 0 | T139: 0 | U139: =_xlfn.LET(_xlpm.maxVal,_xlfn.MAXIFS($K:$K,$A:$A,A139),IF(AND(_xlpm.maxVal=K139,L139<>0),_xlpm.maxVal,"")) | V139: =_xlfn.LET(_xlpm.maxVal,_xlfn.MAXIFS($K:$K,$A:$A,A139),IF(AND(_xlpm.maxVal=K139,M139<>0),_xlpm.maxVal,"")) | W139: =_xlfn.LET(_xlpm.maxVal,_xlfn.MAXIFS($K:$K,$A:$A,A139),IF(AND(_xlpm.maxVal=K139,N139<>0),_xlpm.maxVal,"")) | X139: =_xlfn.LET(_xlpm.maxVal,_xlfn.MAXIFS($K:$K,$A:$A,A139),IF(AND(_xlpm.maxVal=K139,O139<>0),_xlpm.maxVal,"")) | Y139: =_xlfn.LET(_xlpm.maxVal,_xlfn.MAXIFS($K:$K,$A:$A,A139),IF(AND(_xlpm.maxVal=K139,P139<>0),_xlpm.maxVal,"")) -> 1.35 | Z139: =_xlfn.LET(_xlpm.maxVal,_xlfn.MAXIFS($K:$K,$A:$A,A139),IF(AND(_xlpm.maxVal=K139,Q139<>0),_xlpm.maxVal,"")) | AA139: =_xlfn.LET(_xlpm.maxVal,_xlfn.MAXIFS($K:$K,$A:$A,A139),IF(AND(_xlpm.maxVal=K139,R139<>0),_xlpm.maxVal,"")) -> 1.35 | AB139: =_xlfn.LET(_xlpm.maxVal,_xlfn.MAXIFS($K:$K,$A:$A,A139),IF(AND(_xlpm.maxVal=K139,S139<>0),_xlpm.maxVal,"")) | AC139: =_xlfn.LET(_xlpm.maxVal,_xlfn.MAXIFS($K:$K,$A:$A,A139),IF(AND(_xlpm.maxVal=K139,T139<>0),_xlpm.maxVal,"")) | AD139: =$K139*L139*负载统计!$K$3/60 -> 0 | AE139: =$K139*L139*负载统计!$K$4/60 -> 0 | AF139: =$K139*N139*负载统计!$K$5/60 -> 0 | AG139: =$K139*O139*负载统计!$K$6/60 -> 0 | AH139: =$K139*P139*负载统计!$K$7/60 -> 0.01127205 | AI139: =$K139*Q139*负载统计!$K$8/60 -> 0 | AJ139: =$K139*R139*负载统计!$K$9/60 -> 0.0112185 | AK139: =$K139*S139*负载统计!$K$10/60 -> 0 | AL139: =$K139*T139*负载统计!$K$11/60 -> 0
A140: 62 | B140: 3201U4121-270V-功率 | C140: EATA32 起落架系统 | D140: 前起EHM控制器 | E140: 3231E11300G900 | F140: 3201U4121 | G140: =VLOOKUP(A140,负载电气特性!A:G,7,FALSE) -> 270 | H140: 否 | I140: 脉冲负载 | J140: 关闭 | K140: 0 | L140: 1 | M140: 1 | N140: 1 | O140: 1 | P140: =1-P139 -> 0.926 | Q140: 1 | R140: =1-R139 -> 0.964 | S140: 1 | T140: 1 | U140: =_xlfn.LET(_xlpm.maxVal,_xlfn.MAXIFS($K:$K,$A:$A,A140),IF(AND(_xlpm.maxVal=K140,L140<>0),_xlpm.maxVal,"")) | V140: =_xlfn.LET(_xlpm.maxVal,_xlfn.MAXIFS($K:$K,$A:$A,A140),IF(AND(_xlpm.maxVal=K140,M140<>0),_xlpm.maxVal,"")) | W140: =_xlfn.LET(_xlpm.maxVal,_xlfn.MAXIFS($K:$K,$A:$A,A140),IF(AND(_xlpm.maxVal=K140,N140<>0),_xlpm.maxVal,"")) | X140: =_xlfn.LET(_xlpm.maxVal,_xlfn.MAXIFS($K:$K,$A:$A,A140),IF(AND(_xlpm.maxVal=K140,O140<>0),_xlpm.maxVal,"")) | Y140: =_xlfn.LET(_xlpm.maxVal,_xlfn.MAXIFS($K:$K,$A:$A,A140),IF(AND(_xlpm.maxVal=K140,P140<>0),_xlpm.maxVal,"")) | Z140: =_xlfn.LET(_xlpm.maxVal,_xlfn.MAXIFS($K:$K,$A:$A,A140),IF(AND(_xlpm.maxVal=K140,Q140<>0),_xlpm.maxVal,"")) | AA140: =_xlfn.LET(_xlpm.maxVal,_xlfn.MAXIFS($K:$K,$A:$A,A140),IF(AND(_xlpm.maxVal=K140,R140<>0),_xlpm.maxVal,"")) | AB140: =_xlfn.LET(_xlpm.maxVal,_xlfn.MAXIFS($K:$K,$A:$A,A140),IF(AND(_xlpm.maxVal=K140,S140<>0),_xlpm.maxVal,"")) | AC140: =_xlfn.LET(_xlpm.maxVal,_xlfn.MAXIFS($K:$K,$A:$A,A140),IF(AND(_xlpm.maxVal=K140,T140<>0),_xlpm.maxVal,"")) | AD140: =$K140*L140*负载统计!$K$3/60 -> 0 | AE140: =$K140*L140*负载统计!$K$4/60 -> 0 | AF140: =$K140*N140*负载统计!$K$5/60 -> 0 | AG140: =$K140*O140*负载统计!$K$6/60 -> 0 | AH140: =$K140*P140*负载统计!$K$7/60 -> 0 | AI140: =$K140*Q140*负载统计!$K$8/60 -> 0 | AJ140: =$K140*R140*负载统计!$K$9/60 -> 0 | AK140: =$K140*S140*负载统计!$K$10/60 -> 0 | AL140: =$K140*T140*负载统计!$K$11/60 -> 0
A141: 63 | B141: 3201U4121-28V-控制 | C141: EATA32 起落架系统 | D141: 前起EHM控制器 | E141: 3231E11300G900 | F141: 3201U4121 | G141: =VLOOKUP(A141,负载电气特性!A:G,7,FALSE) -> 28 | H141: 否 | I141: 连续负载 | J141: 工作 | K141: 0.098 | L141: 1 | M141: 1 | N141: 1 | O141: 1 | P141: 1 | Q141: 1 | R141: 1 | S141: 1 | T141: 1 | U141: =_xlfn.LET(_xlpm.maxVal,_xlfn.MAXIFS($K:$K,$A:$A,A141),IF(AND(_xlpm.maxVal=K141,L141<>0),_xlpm.maxVal,"")) -> 0.098 | V141: =_xlfn.LET(_xlpm.maxVal,_xlfn.MAXIFS($K:$K,$A:$A,A141),IF(AND(_xlpm.maxVal=K141,M141<>0),_xlpm.maxVal,"")) -> 0.098 | W141: =_xlfn.LET(_xlpm.maxVal,_xlfn.MAXIFS($K:$K,$A:$A,A141),IF(AND(_xlpm.maxVal=K141,N141<>0),_xlpm.maxVal,"")) -> 0.098 | X141: =_xlfn.LET(_xlpm.maxVal,_xlfn.MAXIFS($K:$K,$A:$A,A141),IF(AND(_xlpm.maxVal=K141,O141<>0),_xlpm.maxVal,"")) -> 0.098 | Y141: =_xlfn.LET(_xlpm.maxVal,_xlfn.MAXIFS($K:$K,$A:$A,A141),IF(AND(_xlpm.maxVal=K141,P141<>0),_xlpm.maxVal,"")) -> 0.098 | Z141: =_xlfn.LET(_xlpm.maxVal,_xlfn.MAXIFS($K:$K,$A:$A,A141),IF(AND(_xlpm.maxVal=K141,Q141<>0),_xlpm.maxVal,"")) -> 0.098 | AA141: =_xlfn.LET(_xlpm.maxVal,_xlfn.MAXIFS($K:$K,$A:$A,A141),IF(AND(_xlpm.maxVal=K141,R141<>0),_xlpm.maxVal,"")) -> 0.098 | AB141: =_xlfn.LET(_xlpm.maxVal,_xlfn.MAXIFS($K:$K,$A:$A,A141),IF(AND(_xlpm.maxVal=K141,S141<>0),_xlpm.maxVal,"")) -> 0.098 | AC141: =_xlfn.LET(_xlpm.maxVal,_xlfn.MAXIFS($K:$K,$A:$A,A141),IF(AND(_xlpm.maxVal=K141,T141<>0),_xlpm.maxVal,"")) -> 0.098 | AD141: =$K141*L141*负载统计!$K$3/60 -> 0 | AE141: =$K141*L141*负载统计!$K$4/60 -> 0 | AF141: =$K141*N141*负载统计!$K$5/60 -> 0.0016333333 | AG141: =$K141*O141*负载统计!$K$6/60 -> 0.0049 | AH141: =$K141*P141*负载统计!$K$7/60 -> 0.011057667 | AI141: =$K141*Q141*负载统计!$K$8/60 -> 0.071213333 | AJ141: =$K141*R141*负载统计!$K$9/60 -> 0.022621667 | AK141: =$K141*S141*负载统计!$K$10/60 -> 0.00081666667 | AL141: =$K141*T141*负载统计!$K$11/60 -> 0.0065333333
